File: mechanics_and_materials/materials_practical_data/instrondata_machine3_15sep2022_2pm/all_material_instron_data/Al_Annealed_1150_T0.csv
Time measurement,Displacement,Primary force measurement,Strain 1
(s),(mm),(N),(%)
"0.00000","0.00000","0.00625","-0.0002"
"0.22000","0.03128","208.90350","0.0075"
"0.44000","0.06818","364.12674","0.0257"
"0.66000","0.10485","430.77072","0.0503"
"0.88000","0.14153","459.54871","0.0929"
"1.10000","0.17817","479.60529","0.1436"
"1.32000","0.21485","496.74780","0.1937"
"1.54000","0.25149","512.01270","0.2413"
"1.76000","0.28816","526.74658","0.2868"
"1.98000","0.32488","540.60980","0.3305"
"2.20000","0.36151","553.13959","0.3733"
"2.42000","0.39819","565.14233","0.4155"
"2.64000","0.43486","576.58313","0.4564"
"2.86000","0.47149","586.87341","0.4971"
"3.08000","0.50819","597.20026","0.5373"
"3.30000","0.54489","606.16406","0.5766"
"3.52000","0.58155","615.98688","0.6149"
"3.74000","0.61814","624.72314","0.6538"
"3.96000","0.65486","633.53009","0.6917"
"4.18000","0.69154","641.82642","0.7296"
"4.40000","0.72819","650.48242","0.7671"
"4.62000","0.76488","658.27954","0.8054"
"4.84000","0.80153","665.64270","0.8426"
"5.06000","0.83816","673.20483","0.8796"
"5.28000","0.87483","680.42676","0.9166"
"5.50000","0.91152","687.78528","0.9530"
"5.72000","0.94823","694.62152","0.9890"
"5.94000","0.98483","701.31580","1.0250"
"6.16000","1.02154","707.42664","1.0603"
"6.38000","1.05818","713.74078","1.0950"
"6.60000","1.09476","719.67834","1.1288"
"6.82000","1.13157","725.76202","1.1631"
"7.04000","1.16822","731.65082","1.1969"
"7.26000","1.20483","737.47876","1.2308"
"7.48000","1.24152","743.04773","1.2643"
"7.70000","1.27812","748.47559","1.2983"
"7.92000","1.31486","754.13098","1.3324"
"8.14000","1.35158","758.98999","1.3664"
"8.36000","1.38821","764.51398","1.4004"
"8.58000","1.42484","769.50623","1.4341"
"8.80000","1.46151","774.73767","1.4685"
"9.02000","1.49817","780.24316","1.5027"
"9.24000","1.53487","785.35870","1.5366"
"9.46000","1.57156","790.08936","1.5706"
"9.68000","1.60820","795.20233","1.6048"
"9.90000","1.64487","799.79413","1.6390"
"10.12000","1.68152","804.61029","1.6735"
"10.34000","1.71815","809.40326","1.7078"
"10.56000","1.75488","814.03870","1.7422"
"10.78000","1.79155","818.75848","1.7767"
"11.00000","1.82817","823.64551","1.8111"
"11.22000","1.86487","827.84369","1.8450"
"11.44000","1.90144","832.18823","1.8795"
"11.66000","1.93824","836.67657","1.9142"
"11.88000","1.97491","840.94598","1.9488"
"12.10000","2.01151","845.67145","1.9831"
"12.32000","2.04821","849.77972","2.0179"
"12.54000","2.08482","854.19250","2.0521"
"12.76000","2.12147","858.50305","2.0866"
"12.98000","2.15824","862.28827","2.1215"
"13.20000","2.19491","866.41510","2.1563"
"13.42000","2.23154","870.43689","2.1910"
"13.64000","2.26815","874.33319","2.2255"
"13.86000","2.30485","878.31256","2.2602"
"14.08000","2.34150","882.17090","2.2950"
"14.30000","2.37822","886.17822","2.3294"
"14.52000","2.41488","889.96741","2.3648"
"14.74000","2.45152","893.84412","2.3997"
"14.96000","2.48816","897.23767","2.4348"
"15.18000","2.52481","900.55035","2.4697"
"15.40000","2.56156","904.76331","2.5044"
"15.62000","2.59817","908.36304","2.5394"
"15.84000","2.63488","912.00977","2.5750"
"16.06000","2.67153","915.45673","2.6095"
"16.28000","2.70812","918.96997","2.6445"
"16.50000","2.74488","922.46167","2.6797"
"16.72000","2.78155","925.72363","2.7149"
"16.94000","2.81816","929.01642","2.7499"
"17.16000","2.85489","932.54230","2.7851"
"17.38000","2.89148","935.68292","2.8206"
"17.60000","2.92818","938.90216","2.8552"
"17.82000","2.96487","941.99945","2.8909"
"18.04000","3.00155","945.59705","2.9264"
"18.26000","3.03820","948.95142","2.9623"
"18.48000","3.07484","952.05780","2.9979"
"18.70000","3.11151","955.68256","3.0334"
"18.92000","3.14818","958.44006","3.0687"
"19.14000","3.18486","961.39246","3.1038"
"19.36000","3.22155","964.19452","3.1397"
"19.58000","3.25819","967.52716","3.1754"
"19.80000","3.29480","970.29645","3.2111"
"20.02000","3.33152","973.04034","3.2466"
"20.24000","3.36821","976.64569","3.2823"
"20.46000","3.40484","979.01160","3.3182"
"20.68000","3.44154","981.86035","3.3541"
"20.90000","3.47821","984.81543","3.3900"
"21.12000","3.51482","987.86383","3.4254"
"21.34000","3.55153","990.73157","3.4609"
"21.56000","3.58824","993.28168","3.4970"
"21.78000","3.62488","996.22046","3.5329"
"22.00000","3.66153","998.92456","3.5689"
"22.22000","3.69817","1001.41699","3.6050"
"22.44000","3.73482","1004.28247","3.6413"
"22.66000","3.77150","1006.78503","3.6778"
"22.88000","3.80822","1009.35010","3.7141"
"23.10000","3.84487","1012.15485","3.7504"
"23.32000","3.88146","1014.72742","3.7868"
"23.54000","3.91822","1017.33429","3.8230"
"23.76000","3.95484","1019.66986","3.8592"
"23.98000","3.99148","1022.17554","3.8953"
"24.20000","4.02824","1024.87598","3.9316"
"24.42000","4.06484","1027.44641","3.9685"
"24.64000","4.10149","1029.57166","4.0051"
"24.86000","4.13820","1032.08740","4.0416"
"25.08000","4.17484","1034.91846","4.0781"
"25.30000","4.21154","1037.04285","4.1147"
"25.52000","4.24819","1039.19006","4.1513"
"25.74000","4.28487","1041.64355","4.1881"
"25.96000","4.32152","1044.16162","4.2247"
"26.18000","4.35815","1046.43921","4.2613"
"26.40000","4.39487","1048.79163","4.2980"
"26.62000","4.43152","1051.26831","4.3346"
"26.84000","4.46817","1053.03247","4.3718"
"27.06000","4.50485","1055.49512","4.4092"
"27.28000","4.54152","1057.57959","4.4461"
"27.50000","4.57813","1060.03625","4.4833"
"27.72000","4.61487","1062.14575","4.5199"
"27.94000","4.65159","1064.29749","4.5568"
"28.16000","4.68814","1066.42688","4.5936"
"28.38000","4.72486","1068.91248","4.6312"
"28.60000","4.76152","1070.79810","4.6684"
"28.82000","4.79815","1072.86169","4.7061"
"29.04000","4.83491","1074.97559","4.7432"
"29.26000","4.87152","1076.87671","4.7804"
"29.48000","4.90817","1079.39294","4.8175"
"29.70000","4.94485","1081.14526","4.8551"
"29.92000","4.98150","1083.34790","4.8923"
"30.14000","5.01824","1085.56287","4.9296"
"30.36000","5.05485","1087.22266","4.9670"
"30.58000","5.09156","1089.28845","5.0048"
"30.80000","5.12818","1091.49646","5.0419"
"31.02000","5.16481","1093.18018","5.0792"
"31.24000","5.20155","1094.95935","5.1160"
"31.46000","5.23821","1096.88477","5.1537"
"31.68000","5.27483","1098.99268","5.1916"
"31.90000","5.31152","1100.66711","5.2305"
"32.12000","5.34818","1102.73413","5.2694"
"32.34000","5.38482","1104.49121","5.3079"
"32.56000","5.42153","1106.29639","5.3462"
"32.78000","5.45822","1107.90503","5.3834"
"33.00000","5.49486","1109.87585","5.4201"
"33.22000","5.53154","1112.18396","5.4572"
"33.44000","5.56817","1114.01001","5.4951"
"33.66000","5.60484","1115.57910","5.5337"
"33.88000","5.64154","1117.29028","5.5727"
"34.10000","5.67821","1118.68555","5.6121"
"34.32000","5.71488","1120.90979","5.6505"
"34.54000","5.75150","1122.43335","5.6883"
"34.76000","5.78814","1124.03503","5.7254"
"34.98000","5.82487","1125.77063","5.7626"
"35.20000","5.86152","1127.43689","5.7999"
"35.42000","5.89821","1129.22632","5.8380"
"35.64000","5.93489","1130.93188","5.8766"
"35.86000","5.97146","1132.57983","5.9166"
"36.08000","6.00819","1134.25232","5.9569"
"36.30000","6.04487","1135.79529","5.9970"
"36.52000","6.08151","1137.08362","6.0353"
"36.74000","6.11824","1138.95532","6.0734"
"36.96000","6.15484","1140.56726","6.1104"
"37.18000","6.19148","1142.30115","6.1469"
"37.40000","6.22817","1144.07861","6.1840"
"37.62000","6.26490","1145.61230","6.2223"
"37.84000","6.30154","1146.87634","6.2625"
"38.06000","6.33820","1148.48218","6.3033"
"38.28000","6.37488","1150.01233","6.3442"
"38.50000","6.41148","1152.11926","6.3844"
"38.72000","6.44817","1153.26685","6.4235"
"38.94000","6.48491","1154.85327","6.4605"
"39.16000","6.52154","1156.15112","6.4972"
"39.38000","6.55817","1157.65576","6.5333"
"39.60000","6.59483","1159.28088","6.5707"
"39.82000","6.63151","1160.35925","6.6095"
"40.04000","6.66818","1161.91870","6.6504"
"40.26000","6.70490","1163.42554","6.6927"
"40.48000","6.74152","1164.99463","6.7352"
"40.70000","6.77812","1166.33362","6.7771"
"40.92000","6.81485","1167.97351","6.8168"
"41.14000","6.85151","1169.33508","6.8544"
"41.36000","6.88818","1170.49463","6.8906"
"41.58000","6.92488","1171.91406","6.9261"
"41.80000","6.96150","1173.82617","6.9617"
"42.02000","6.99818","1174.86414","6.9995"
"42.24000","7.03483","1176.21155","7.0400"
"42.46000","7.07155","1177.71350","7.0831"
"42.68000","7.10822","1178.96912","7.1276"
"42.90000","7.14485","1180.01306","7.1716"
"43.12000","7.18154","1181.47327","7.2138"
"43.34000","7.21815","1182.88232","7.2520"
"43.56000","7.25482","1184.17566","7.2881"
"43.78000","7.29155","1185.36353","7.3222"
"44.00000","7.32820","1186.63550","7.3560"
"44.22000","7.36483","1188.22546","7.3912"
"44.44000","7.40150","1189.43835","7.4297"
"44.66000","7.43820","1190.69336","7.4719"
"44.88000","7.47483","1192.28052","7.5182"
"45.10000","7.51156","1193.45386","7.5664"
"45.32000","7.54822","1194.91980","7.6143"
"45.54000","7.58482","1196.11792","7.6582"
"45.76000","7.62152","1197.24963","7.6978"
"45.98000","7.65819","1198.49231","7.7336"
"46.20000","7.69486","1199.60327","7.7658"
"46.42000","7.73154","1200.77283","7.7969"
"46.64000","7.76817","1201.91040","7.8297"
"46.86000","7.80483","1203.42810","7.8655"
"47.08000","7.84148","1204.17468","7.9063"
"47.30000","7.87820","1205.87256","7.9518"
"47.52000","7.91487","1206.72961","8.0015"
"47.74000","7.95151","1207.77258","8.0520"
"47.96000","7.98821","1209.29395","8.1001"
"48.18000","8.02485","1210.24548","8.1431"
"48.40000","8.06147","1211.36353","8.1801"
"48.62000","8.09822","1212.33777","8.2125"
"48.84000","8.13487","1213.69446","8.2416"
"49.06000","8.17150","1214.67371","8.2702"
"49.28000","8.20820","1215.97766","8.3005"
"49.50000","8.24484","1217.07166","8.3356"
"49.72000","8.28152","1218.13525","8.3776"
"49.94000","8.31823","1219.22485","8.4285"
"50.16000","8.35486","1220.40869","8.4844"
"50.38000","8.39150","1221.56543","8.5425"
"50.60000","8.42820","1222.80542","8.5968"
"50.82000","8.46486","1223.90930","8.6428"
"51.04000","8.50150","1225.01013","8.6800"
"51.26000","8.53820","1225.42334","8.7112"
"51.48000","8.57485","1226.87891","8.7383"
"51.70000","8.61153","1228.14673","8.7642"
"51.92000","8.64816","1229.13806","8.7912"
"52.14000","8.68485","1230.33508","8.8226"
"52.36000","8.72158","1231.57642","8.8609"
"52.58000","8.75815","1232.02893","8.9082"
"52.80000","8.79489","1232.98267","8.9627"
"53.02000","8.83151","1234.07385","9.0210"
"53.24000","8.86816","1235.29309","9.0791"
"53.46000","8.90488","1236.31140","9.1310"
"53.68000","8.94154","1237.18030","9.1732"
"53.90000","8.97818","1237.77881","9.2064"
"54.12000","9.01485","1238.68604","9.2350"
"54.34000","9.05154","1239.93311","9.2599"
"54.56000","9.08821","1241.15027","9.2838"
"54.78000","9.12484","1242.10974","9.3089"
"55.00000","9.16159","1243.31689","9.3378"
"55.22000","9.19817","1243.99939","9.3740"
"55.44000","9.23485","1244.80347","9.4213"
"55.66000","9.27153","1245.93250","9.4777"
"55.88000","9.30816","1246.58154","9.5407"
"56.10000","9.34486","1247.46643","9.6071"
"56.32000","9.38152","1248.84436","9.6692"
"56.54000","9.41819","1250.23682","9.7174"
"56.76000","9.45485","1250.93542","9.7536"
"56.98000","9.49152","1252.01245","9.7828"
"57.20000","9.52821","1253.01318","9.8085"
"57.42000","9.56483","1253.81348","9.8332"
"57.64000","9.60154","1254.43408","9.8593"
"57.86000","9.63819","1255.58386","9.8900"
"58.08000","9.67483","1256.51416","9.9289"
"58.30000","9.71153","1257.52649","9.9764"
"58.52000","9.74819","1258.59570","10.0307"
"58.74000","9.78487","1259.33948","10.0895"
"58.96000","9.82151","1259.97913","10.1529"
"59.18000","9.85818","1261.04285","10.2169"
"59.40000","9.89485","1261.67932","10.2713"
"59.62000","9.93151","1262.71313","10.3112"
"59.84000","9.96822","1263.47131","10.3405"
"60.06000","10.00485","1264.35779","10.3649"
"60.28000","10.04151","1264.97986","10.3869"
"60.50000","10.07820","1265.70239","10.4080"
"60.72000","10.11484","1266.84607","10.4296"
"60.94000","10.15152","1267.43445","10.4543"
"61.16000","10.18823","1267.99365","10.4872"
"61.38000","10.22487","1268.68115","10.5294"
"61.60000","10.26150","1269.19446","10.5783"
"61.82000","10.29817","1270.56079","10.6307"
"62.04000","10.33487","1271.67029","10.6893"
"62.26000","10.37154","1272.06226","10.7530"
"62.48000","10.40821","1272.60254","10.8179"
"62.70000","10.44487","1273.32629","10.8774"
"62.92000","10.48150","1274.62671","10.9211"
"63.14000","10.51818","1275.27576","10.9517"
"63.36000","10.55487","1276.09192","10.9762"
"63.58000","10.59156","1277.09778","10.9986"
"63.80000","10.62819","1277.51038","11.0199"
"64.02000","10.66486","1278.58777","11.0437"
"64.24000","10.70152","1279.53918","11.0725"
"64.46000","10.73812","1280.23047","11.1119"
"64.68000","10.77490","1280.72131","11.1634"
"64.90000","10.81155","1281.61670","11.2226"
"65.12000","10.84816","1282.67798","11.2872"
"65.34000","10.88487","1283.39990","11.3550"
"65.56000","10.92146","1284.03040","11.4240"
"65.78000","10.95819","1284.77002","11.4890"
"66.00000","10.99491","1285.74414","11.5407"
"66.22000","11.03153","1286.35999","11.5768"
"66.44000","11.06819","1287.14392","11.6050"
"66.66000","11.10483","1287.76221","11.6294"
"66.88000","11.14152","1288.80896","11.6524"
"67.10000","11.17820","1289.24524","11.6759"
"67.32000","11.21490","1289.95837","11.7033"
"67.54000","11.25155","1290.88916","11.7382"
"67.76000","11.28816","1291.39294","11.7832"
"67.98000","11.32484","1292.55042","11.8375"
"68.20000","11.36151","1293.12207","11.8976"
"68.42000","11.39821","1294.07581","11.9609"
"68.64000","11.43487","1294.11133","12.0263"
"68.86000","11.47153","1295.09619","12.0913"
"69.08000","11.50822","1295.68250","12.1510"
"69.30000","11.54479","1296.15234","12.1993"
"69.52000","11.58156","1296.66272","12.2340"
"69.74000","11.61823","1297.37036","12.2606"
"69.96000","11.65484","1297.97168","12.2831"
"70.18000","11.69156","1298.62280","12.3037"
"70.40000","11.72815","1299.32678","12.3234"
"70.62000","11.76483","1300.34766","12.3440"
"70.84000","11.80154","1300.42358","12.3664"
"71.06000","11.83822","1301.00012","12.3921"
"71.28000","11.87487","1301.40796","12.4236"
"71.50000","11.91148","1302.14099","12.4615"
"71.72000","11.94820","1302.68384","12.5067"
"71.94000","11.98485","1303.35962","12.5586"
"72.16000","12.02154","1304.06213","12.6152"
"72.38000","12.05824","1304.66870","12.6787"
"72.60000","12.09483","1305.06006","12.7479"
"72.82000","12.13150","1305.92822","12.8177"
"73.04000","12.16817","1306.34155","12.8809"
"73.26000","12.20487","1307.44238","12.9310"
"73.48000","12.24152","1307.79504","12.9681"
"73.70000","12.27820","1308.06738","12.9981"
"73.92000","12.31486","1308.74207","13.0239"
"74.14000","12.35147","1309.47498","13.0477"
"74.36000","12.38818","1310.20178","13.0721"
"74.58000","12.42487","1310.77783","13.0992"
"74.80000","12.46150","1311.40662","13.1316"
"75.02000","12.49821","1311.96448","13.1723"
"75.24000","12.53484","1312.53113","13.2216"
"75.46000","12.57152","1313.41797","13.2780"
"75.68000","12.60819","1313.82556","13.3393"
"75.90000","12.64486","1314.39600","13.4043"
"76.12000","12.68154","1314.88965","13.4719"
"76.34000","12.71817","1315.32922","13.5399"
"76.56000","12.75484","1316.18994","13.6028"
"76.78000","12.79153","1317.01184","13.6552"
"77.00000","12.82817","1317.73694","13.6973"
"77.22000","12.86489","1318.07251","13.7328"
"77.44000","12.90152","1318.62952","13.7649"
"77.66000","12.93815","1319.33643","13.7946"
"77.88000","12.97487","1319.51282","13.8243"
"78.10000","13.01152","1320.25696","13.8560"
"78.32000","13.04820","1320.90417","13.8918"
"78.54000","13.08486","1321.40759","13.9340"
"78.76000","13.12154","1322.08911","13.9826"
"78.98000","13.15818","1322.59900","14.0359"
"79.20000","13.19485","1323.36133","14.0928"
"79.42000","13.23155","1323.55017","14.1514"
"79.64000","13.26817","1324.25269","14.2110"
"79.86000","13.30484","1324.41394","14.2715"
"80.08000","13.34151","1325.05286","14.3301"
"80.30000","13.37818","1325.44995","14.3847"
"80.52000","13.41484","1325.96191","14.4320"
"80.74000","13.45153","1326.58765","14.4727"
"80.96000","13.48820","1326.91541","14.5084"
"81.18000","13.52484","1327.72827","14.5413"
"81.40000","13.56156","1328.01062","14.5727"
"81.62000","13.59817","1328.46375","14.6036"
"81.84000","13.63482","1329.13220","14.6357"
"82.06000","13.67158","1329.41235","14.6705"
"82.28000","13.70818","1329.64941","14.7093"
"82.50000","13.74483","1330.11877","14.7520"
"82.72000","13.78153","1330.30261","14.7985"
"82.94000","13.81816","1330.59119","14.8459"
"83.16000","13.85489","1330.64001","14.8899"
"83.38000","13.89152","1331.54053","14.9338"
"83.60000","13.92820","1332.46851","14.9803"
"83.82000","13.96486","1332.75793","15.0289"
"84.04000","14.00148","1333.41797","15.0855"
"84.26000","14.03821","1333.58655","15.1449"
"84.48000","14.07485","1333.87415","15.2016"
"84.70000","14.11152","1334.18774","15.2527"
"84.92000","14.14821","1334.79675","15.2967"
"85.14000","14.18486","1335.27527","15.3356"
"85.36000","14.22149","1335.59753","15.3712"
"85.58000","14.25819","1335.93225","15.4050"
"85.80000","14.29488","1336.09375","15.4363"
"86.02000","14.33148","1336.29285","15.4675"
"86.24000","14.36820","1337.10461","15.4990"
"86.46000","14.40485","1337.71509","15.5324"
"86.68000","14.44149","1338.90796","15.5672"
"86.90000","14.47824","1338.60889","15.6094"
"87.12000","14.51487","1338.81982","15.6556"
"87.34000","14.55151","1339.55859","15.7050"
"87.56000","14.58818","1339.80640","15.7577"
"87.78000","14.62483","1339.95996","15.8134"
"88.00000","14.66154","1340.54797","15.8709"
"88.22000","14.69820","1340.79077","15.9304"
"88.44000","14.73489","1341.47449","15.9897"
"88.66000","14.77151","1341.92761","16.0464"
"88.88000","14.80814","1342.63220","16.0992"
"89.10000","14.84488","1342.89233","16.1474"
"89.32000","14.88153","1343.53430","16.1917"
"89.54000","14.91818","1343.73853","16.2331"
"89.76000","14.95486","1344.13953","16.2731"
"89.98000","14.99151","1344.32349","16.3129"
"90.20000","15.02816","1345.19873","16.3528"
"90.42000","15.06487","1345.29346","16.3942"
"90.64000","15.10154","1345.82031","16.4366"
"90.86000","15.13819","1346.02942","16.4813"
"91.08000","15.17486","1346.62915","16.5280"
"91.30000","15.21151","1347.04480","16.5768"
"91.52000","15.24815","1347.69104","16.6276"
"91.74000","15.28485","1348.12769","16.6800"
"91.96000","15.32156","1348.01184","16.7339"
"92.18000","15.35820","1348.77759","16.7890"
"92.40000","15.39484","1348.83362","16.8446"
"92.62000","15.43148","1349.38037","16.9000"
"92.84000","15.46820","1349.73083","16.9539"
"93.06000","15.50488","1349.80652","17.0054"
"93.28000","15.54154","1350.31116","17.0541"
"93.50000","15.57822","1350.74023","17.1007"
"93.72000","15.61479","1351.07910","17.1451"
"93.94000","15.65153","1351.84009","17.1890"
"94.16000","15.68822","1352.03906","17.2325"
"94.38000","15.72485","1352.05774","17.2761"
"94.60000","15.76157","1352.49023","17.3200"
"94.82000","15.79815","1352.86206","17.3647"
"95.04000","15.83483","1353.37817","17.4104"
"95.26000","15.87150","1353.75647","17.4578"
"95.48000","15.90822","1353.77856","17.5064"
"95.70000","15.94488","1354.31946","17.5559"
"95.92000","15.98150","1354.42712","17.6069"
"96.14000","16.01822","1355.09521","17.6586"
"96.36000","16.05483","1355.64941","17.7111"
"96.58000","16.09151","1355.59314","17.7647"
"96.80000","16.12825","1355.98230","17.8184"
"97.02000","16.16485","1355.96912","17.8714"
"97.24000","16.20151","1356.30518","17.9238"
"97.46000","16.23815","1356.84045","17.9745"
"97.68000","16.27482","1357.13916","18.0243"
"97.90000","16.31153","1357.40576","18.0728"
"98.12000","16.34824","1357.74683","18.1203"
"98.34000","16.38487","1358.35437","18.1670"
"98.56000","16.42146","1358.45239","18.2132"
"98.78000","16.45819","1358.65967","18.2595"
"99.00000","16.49487","1359.31506","18.3060"
"99.22000","16.53152","1359.06702","18.3531"
"99.44000","16.56822","1359.38037","18.4006"
"99.66000","16.60485","1360.15723","18.4486"
"99.88000","16.64151","1360.43713","18.4972"
"100.10000","16.67816","1360.50586","18.5425"
"100.32000","16.71486","1360.52698","18.5896"
"100.54000","16.75155","1360.84729","18.6365"
"100.76000","16.78819","1361.40405","18.6839"
"100.98000","16.82487","1361.34265","18.7316"
"101.20000","16.86149","1362.06616","18.7797"
"101.42000","16.89816","1362.08936","18.8287"
"101.64000","16.93489","1362.49048","18.8785"
"101.86000","16.97154","1362.59204","18.9287"
"102.08000","17.00817","1363.08862","18.9785"
"102.30000","17.04486","1363.10974","19.0275"
"102.52000","17.08152","1363.44153","19.0754"
"102.74000","17.11819","1363.81201","19.1201"
"102.96000","17.15489","1364.30444","19.1622"
"103.18000","17.19157","1364.37012","19.2000"
"103.40000","17.22816","1364.75452","19.2337"
"103.62000","17.26484","1364.80115","19.2643"
"103.84000","17.30153","1365.31494","19.2916"
"104.06000","17.33820","1365.54834","19.3166"
"104.28000","17.37487","1365.80652","19.3403"
"104.50000","17.41151","1365.97205","19.3620"
"104.72000","17.44817","1366.18396","19.3819"
"104.94000","17.48482","1364.88074","19.3991"
"105.16000","17.52154","1365.80566","19.4124"
"105.38000","17.55821","1367.89221","19.4233"
"105.60000","17.59482","1368.51379","19.4277"
"105.82000","17.63154","1367.78235","19.4247"
"106.04000","17.66820","1367.52454","19.4104"
"106.26000","17.70481","1367.68713","19.4095"
"106.48000","17.74153","1367.80225","19.4093"
"106.70000","17.77819","1367.78564","19.4117"
"106.92000","17.81485","1367.86304","19.4131"
"107.14000","17.85154","1368.30640","19.4188"
"107.36000","17.88819","1368.73486","19.4204"
"107.58000","17.92486","1368.78003","19.4186"
"107.80000","17.96152","1369.02209","19.4196"
"108.02000","17.99821","1369.21399","19.4222"
"108.24000","18.03483","1369.59570","19.4240"
"108.46000","18.07152","1369.86609","19.4261"
"108.68000","18.10820","1370.19189","19.4285"
"108.90000","18.14484","1370.44226","19.4302"
"109.12000","18.18155","1370.50159","19.4310"
"109.34000","18.21817","1370.57263","19.4334"
"109.56000","18.25486","1370.81335","19.4364"
"109.78000","18.29150","1371.05115","19.4400"
"110.00000","18.32818","1371.66260","19.4423"
"110.22000","18.36492","1371.58337","19.4443"
"110.44000","18.40149","1371.56238","19.4492"
"110.66000","18.43821","1372.23950","19.4561"
"110.88000","18.47486","1372.27319","19.4609"
"111.10000","18.51148","1372.54993","19.4637"
"111.32000","18.54822","1372.59290","19.4613"
"111.54000","18.58486","1371.85767","19.4603"
"111.76000","18.62152","1372.76404","19.4586"
"111.98000","18.65819","1373.29590","19.4570"
"112.20000","18.69487","1373.37122","19.4565"
"112.42000","18.73153","1373.36414","19.4565"
"112.64000","18.76815","1373.20520","19.4584"
"112.86000","18.80491","1373.85303","19.4605"
"113.08000","18.84151","1373.97852","19.4624"
"113.30000","18.87819","1374.08728","19.4662"
"113.52000","18.91487","1374.33899","19.4702"
"113.74000","18.95149","1374.30334","19.4738"
"113.96000","18.98820","1374.77783","19.4794"
"114.18000","19.02486","1374.87817","19.4900"
"114.40000","19.06153","1375.24536","19.4970"
"114.62000","19.09817","1375.22180","19.5016"
"114.84000","19.13485","1375.42761","19.5060"
"115.06000","19.17153","1375.90454","19.5088"
"115.28000","19.20815","1375.51904","19.5102"
"115.50000","19.24488","1375.78516","19.5114"
"115.72000","19.28152","1376.13342","19.5134"
"115.94000","19.31817","1376.39294","19.5148"
"116.16000","19.35486","1376.71887","19.5147"
"116.38000","19.39151","1376.37537","19.5139"
"116.60000","19.42820","1376.42944","19.5135"
"116.82000","19.46485","1376.72949","19.5150"
"117.04000","19.50151","1377.12830","19.5154"
"117.26000","19.53819","1377.34534","19.5167"
"117.48000","19.57483","1377.31604","19.5202"
"117.70000","19.61155","1377.39246","19.5254"
"117.92000","19.64820","1377.65869","19.5327"
"118.14000","19.68485","1377.65894","19.5445"
"118.36000","19.72152","1377.87646","19.5534"
"118.58000","19.75817","1378.34558","19.5618"
"118.80000","19.79484","1378.14697","19.5713"
"119.02000","19.83156","1378.44604","19.5948"
"119.24000","19.86822","1378.63977","19.6415"
"119.46000","19.90483","1378.67261","19.6686"
"119.68000","19.94150","1378.91077","19.6795"
"119.90000","19.97819","1378.90344","19.6823"
"120.12000","20.01487","1379.13025","19.6819"
"120.34000","20.05155","1378.94019","19.6809"
"120.56000","20.08822","1379.18909","19.6821"
"120.78000","20.12483","1379.43958","19.6820"
"121.00000","20.16151","1379.53333","19.6815"
"121.22000","20.19819","1379.58923","19.6832"
"121.44000","20.23488","1379.56677","19.6866"
"121.66000","20.27151","1379.75330","19.6887"
"121.88000","20.30818","1379.87170","19.6911"
"122.10000","20.34485","1380.14124","19.6939"
"122.32000","20.38146","1380.21423","19.6983"
"122.54000","20.41823","1380.49402","19.7025"
"122.76000","20.45489","1380.52344","19.7058"
"122.98000","20.49148","1380.74023","19.7081"
"123.20000","20.52820","1380.79895","19.7100"
"123.42000","20.56480","1380.89404","19.7134"
"123.64000","20.60151","1380.80603","19.7153"
"123.86000","20.63825","1380.77405","19.7162"
"124.08000","20.67486","1380.90393","19.7170"
"124.30000","20.71153","1381.17883","19.7174"
"124.52000","20.74814","1381.12817","19.7170"
"124.74000","20.78484","1381.36572","19.7172"
"124.96000","20.82154","1381.45959","19.7170"
"125.18000","20.85822","1381.33545","19.7163"
"125.40000","20.89488","1381.31702","19.7173"
"125.62000","20.93149","1381.69519","19.7184"
"125.84000","20.96816","1381.83765","19.7175"
"126.06000","21.00485","1381.87646","19.7152"
"126.28000","21.04154","1381.60352","19.7142"
"126.50000","21.07820","1381.48865","19.7151"
"126.72000","21.11485","1381.79626","19.7173"
"126.94000","21.15155","1381.84766","19.7179"
"127.16000","21.18813","1381.80994","19.7186"
"127.38000","21.22487","1382.22156","19.7199"
"127.60000","21.26155","1382.15100","19.7212"
"127.82000","21.29819","1382.24524","19.7226"
"128.04000","21.33488","1382.49316","19.7243"
"128.26000","21.37149","1382.49988","19.7258"
"128.48000","21.40818","1382.52283","19.7269"
"128.70000","21.44487","1382.33765","19.7263"
"128.92000","21.48155","1382.35144","19.7264"
"129.14000","21.51820","1382.47937","19.7283"
"129.36000","21.55482","1382.46143","19.7303"
"129.58000","21.59154","1382.95837","19.7308"
"129.80000","21.62819","1382.72034","19.7296"
"130.02000","21.66486","1382.58813","19.7278"
"130.24000","21.70155","1382.96362","19.7273"
"130.46000","21.73817","1382.87561","19.7262"
"130.68000","21.77483","1382.59229","19.7224"
"130.90000","21.81151","1382.69812","19.7163"
"131.12000","21.84819","1382.82178","19.7167"
"131.34000","21.88486","1382.83276","19.7179"
"131.56000","21.92154","1382.91870","19.7201"
"131.78000","21.95818","1382.82593","19.7227"
"132.00000","21.99482","1382.87512","19.7238"
"132.22000","22.03152","1382.90784","19.7209"
"132.44000","22.06820","1382.30310","19.7012"
"132.66000","22.10484","1382.59753","19.7020"
"132.88000","22.14153","1382.78772","19.7026"
"133.10000","22.17819","1382.82263","19.7054"
"133.32000","22.21485","1383.18591","19.7088"
"133.54000","22.25151","1382.99890","19.7112"
"133.76000","22.28819","1382.84387","19.7131"
"133.98000","22.32487","1382.88489","19.7117"
"134.20000","22.36151","1382.78552","19.7085"
"134.42000","22.39820","1382.93774","19.7066"
"134.64000","22.43487","1382.81409","19.7035"
"134.86000","22.47151","1382.81152","19.7021"
"135.08000","22.50822","1382.70154","19.7026"
"135.30000","22.54487","1382.65112","19.7040"
"135.52000","22.58148","1382.83154","19.7019"
"135.74000","22.61820","1382.78247","19.6982"
"135.96000","22.65483","1382.94495","19.6977"
"136.18000","22.69154","1382.56042","19.6989"
"136.40000","22.72819","1382.61841","19.7014"
"136.62000","22.76488","1383.03821","19.7042"
"136.84000","22.80152","1382.68958","19.7075"
"137.06000","22.83816","1382.90295","19.7106"
"137.28000","22.87490","1383.06055","19.7135"
"137.50000","22.91151","1382.75342","19.7148"
"137.72000","22.94820","1382.48035","19.7149"
"137.94000","22.98488","1383.08325","19.7164"
"138.16000","23.02150","1382.94189","19.7175"
"138.38000","23.05817","1382.70740","19.7145"
"138.60000","23.09485","1382.65259","19.7091"
"138.82000","23.13153","1382.56738","19.7082"
"139.04000","23.16817","1382.56836","19.7079"
"139.26000","23.20488","1382.69507","19.7067"
"139.48000","23.24151","1382.63953","19.7059"
"139.70000","23.27815","1382.51550","19.7060"
"139.92000","23.31490","1382.64783","19.7068"
"140.14000","23.35152","1382.49976","19.7095"
"140.36000","23.38819","1382.55176","19.7105"
"140.58000","23.42487","1382.57532","19.7111"
"140.80000","23.46149","1382.14709","19.7105"
"141.02000","23.49822","1382.21179","19.7110"
"141.24000","23.53485","1382.29541","19.7122"
"141.46000","23.57154","1382.31934","19.7114"
"141.68000","23.60820","1382.40869","19.7112"
"141.90000","23.64481","1382.02026","19.7110"
"142.12000","23.68154","1382.03992","19.7116"
"142.34000","23.71819","1382.01270","19.7134"
"142.56000","23.75485","1382.00916","19.7157"
"142.78000","23.79154","1382.26807","19.7185"
"143.00000","23.82817","1381.83167","19.7202"
"143.22000","23.86482","1382.13684","19.7203"
"143.44000","23.90152","1381.92712","19.7208"
"143.66000","23.93822","1381.66724","19.7210"
"143.88000","23.97481","1381.43213","19.7174"
"144.10000","24.01153","1381.40784","19.7149"
"144.32000","24.04820","1381.57654","19.7164"
"144.54000","24.08484","1381.55371","19.7167"
"144.76000","24.12158","1381.34888","19.7173"
"144.98000","24.15821","1380.93469","19.7170"
"145.20000","24.19485","1381.53455","19.7162"
"145.42000","24.23151","1381.14026","19.7151"
"145.64000","24.26818","1381.18262","19.7146"
"145.86000","24.30486","1380.99744","19.7157"
"146.08000","24.34154","1380.76270","19.7168"
"146.30000","24.37820","1380.91553","19.7185"
"146.52000","24.41484","1380.72534","19.7202"
"146.74000","24.45147","1380.83093","19.7218"
"146.96000","24.48820","1380.66284","19.7231"
"147.18000","24.52487","1380.59460","19.7244"
"147.40000","24.56151","1380.18396","19.7227"
"147.62000","24.59822","1380.02844","19.7207"
"147.84000","24.63483","1380.51758","19.7203"
"148.06000","24.67148","1379.69873","19.7178"
"148.28000","24.70820","1379.64026","19.7105"
"148.50000","24.74487","1379.52625","19.7104"
"148.72000","24.78153","1379.43579","19.7103"
"148.94000","24.81818","1379.28528","19.7112"
"149.16000","24.85485","1379.30652","19.7135"
"149.38000","24.89149","1379.14722","19.7151"
"149.60000","24.92820","1378.57361","19.7161"
"149.82000","24.96490","1378.41760","19.7162"
"150.04000","25.00152","1378.51855","19.7168"
"150.26000","25.03819","1378.35852","19.7180"
"150.48000","25.07483","1378.24133","19.7187"
"150.70000","25.11153","1378.12952","19.7178"
"150.92000","25.14819","1377.76379","19.7135"
"151.14000","25.18488","1377.44287","19.7120"
"151.36000","25.22156","1377.74097","19.7126"
"151.58000","25.25812","1377.26978","19.7142"
"151.80000","25.29487","1377.10547","19.7159"
"152.02000","25.33154","1376.92554","19.7175"
"152.24000","25.36819","1376.56885","19.7180"
"152.46000","25.40489","1376.40027","19.7184"
"152.68000","25.44148","1376.06335","19.7182"
"152.90000","25.47817","1376.05469","19.7180"
"153.12000","25.51483","1375.33972","19.7176"
"153.34000","25.55157","1375.19507","19.7167"
"153.56000","25.58822","1374.70251","19.7164"
"153.78000","25.62483","1374.09009","19.7174"
"154.00000","25.66154","1373.81396","19.7186"
"154.22000","25.69815","1373.39270","19.7194"
"154.44000","25.73484","1373.13489","19.7204"
"154.66000","25.77157","1372.32629","19.7209"
"154.88000","25.80817","1371.67224","19.7213"
"155.10000","25.84486","1370.95215","19.7214"
"155.32000","25.88150","1369.77161","19.7210"
"155.54000","25.91818","1369.19604","19.7200"
"155.76000","25.95486","1368.24524","19.7190"
"155.98000","25.99154","1366.95557","19.7186"
"156.20000","26.02820","1365.88208","19.7179"
"156.42000","26.06480","1364.42920","19.7169"
"156.64000","26.10153","1363.38599","19.7168"
"156.86000","26.13819","1361.77832","19.7168"
"157.08000","26.17485","1360.03442","19.7167"
"157.30000","26.21156","1357.86584","19.7166"
"157.52000","26.24818","1356.16748","19.7166"
"157.74000","26.28486","1354.00916","19.7165"
"157.96000","26.32151","1351.61279","19.7166"
"158.18000","26.35821","1349.09717","19.7165"
"158.40000","26.39488","1345.87964","19.7164"
"158.62000","26.43151","1342.78967","19.7164"
"158.84000","26.46820","1339.33289","19.7165"
"159.06000","26.50484","1335.34607","19.7165"
"159.28000","26.54147","1330.86560","19.7165"
"159.50000","26.57823","1326.01050","19.7165"
"159.72000","26.61487","1320.38928","19.7164"
"159.94000","26.65150","1314.17273","19.7163"
"160.16000","26.68819","1306.81799","19.7165"
"160.38000","26.72487","1298.91553","19.7166"
"160.60000","26.76152","1289.50085","19.7165"
"160.82000","26.79821","1279.56384","19.7165"
"161.04000","26.83487","1267.74072","19.7164"
"161.26000","26.87151","1255.09082","19.7163"
"161.48000","26.90817","1240.86145","19.7162"
"161.70000","26.94487","1224.54248","19.7161"
"161.92000","26.98152","1206.74341","19.7158"
"162.14000","27.01823","1185.72681","19.7155"
"162.36000","27.05486","1162.69629","19.7152"
"162.58000","27.09152","1136.13513","19.7148"
"162.80000","27.12817","1105.49622","19.7143"
"163.02000","27.16484","1069.64319","19.7137"
"163.24000","27.20155","1027.39197","19.7128"
"163.46000","27.23818","977.62506","19.7117"
"163.68000","27.27489","918.25977","19.7106"
"163.90000","27.31154","841.99670","19.7089"
"164.12000","27.34813","753.12817","19.7071"
"164.34000","27.38489","642.38599","19.7049"
"164.56000","27.42155","526.09735","19.7023"
"164.78000","27.45819","430.70483","19.7004"
"165.00000","27.49489","356.92227","19.6992"
"165.22000","27.53152","283.10229","19.6980"
"165.44000","27.56820","217.38200","19.6966"
"165.66000","27.60487","159.39687","19.6953"
"165.88000","27.64156","96.36377","19.6931"
"166.10000","27.67817","13.68403","19.6900"
"166.32000","27.71487","-170.78394","19.6792"
"166.54000","27.75152","-229.83083","19.6741"
"166.76000","27.78816","-242.63719","19.6718"
"166.98000","27.82489","-249.28328","19.6437"
"167.20000","27.86151","-249.59663","19.6560"
"167.42000","27.89822","-249.53215","19.6626"
"167.64000","27.93482","-249.59943","19.6673"
"167.86000","27.97150","-249.54271","19.6702"
"168.08000","28.00824","-249.24979","19.6708"
"168.30000","28.04483","-249.43315","19.6698"
"168.52000","28.08158","-249.35512","19.6681"
"168.74000","28.11821","-249.80804","19.6680"
"168.96000","28.15480","-249.36006","19.6678"
"169.18000","28.19155","-249.48071","19.6679"
"169.40000","28.22821","-249.61890","19.6679"
"169.62000","28.26486","-249.49551","19.6678"
"169.84000","28.30152","-249.73512","19.6678"
"170.06000","28.33819","-249.61261","19.6677"
"170.28000","28.37486","-249.39624","19.6676"
"170.50000","28.41147","-249.50542","19.6677"
"170.72000","28.44823","-249.42094","19.6675"
"170.94000","28.48485","-249.30486","19.6675"
"171.16000","28.52151","-249.53677","19.6675"
"171.38000","28.55819","-249.50661","19.6673"
"171.60000","28.59483","-249.44136","19.6674"
"171.82000","28.63152","-249.52773","19.6672"
"172.04000","28.66818","-249.52441","19.6672"
"172.26000","28.70489","-249.58109","19.6672"
"172.48000","28.74150","-249.57964","19.6672"
"172.70000","28.77819","-249.59659","19.6672"
"172.92000","28.81488","-249.41394","19.6671"
"173.14000","28.85150","-249.50046","19.6670"
"173.36000","28.88821","-249.50426","19.6670"
"173.58000","28.92484","-249.32532","19.6670"
"173.80000","28.96149","-249.47589","19.6670"
"174.02000","28.99820","-249.62900","19.6668"
"174.24000","29.03487","-249.37083","19.6669"
"174.46000","29.07155","-249.51295","19.6668"
"174.68000","29.10817","-249.49466","19.6668"
"174.90000","29.14484","-249.33749","19.6668"
"175.12000","29.18152","-249.27914","19.6667"
"175.34000","29.21816","-249.39938","19.6667"
"175.56000","29.25489","-249.49142","19.6668"
"175.78000","29.29154","-249.48558","19.6667"
"176.00000","29.32817","-249.61424","19.6667"
"176.22000","29.36486","-249.39627","19.6666"
"176.44000","29.40149","-249.41635","19.6667"
"176.66000","29.43817","-249.83527","19.6664"
"176.88000","29.47491","-249.74101","19.6666"
"177.10000","29.51154","-249.45815","19.6664"
"177.32000","29.54816","-249.57475","19.6664"
"177.54000","29.58483","-249.50278","19.6664"
"177.76000","29.62152","-249.56430","19.6664"
"177.98000","29.65823","-249.71732","19.6663"
"178.20000","29.69488","-249.67000","19.6663"
"178.42000","29.73154","-249.46118","19.6663"
"178.64000","29.76817","-249.78726","19.6664"
"178.86000","29.80484","-249.60158","19.6663"
"179.08000","29.84154","-249.72391","19.6663"
"179.30000","29.87821","-249.55444","19.6662"
"179.52000","29.91485","-249.25655","19.6662"
"179.74000","29.95150","-249.50366","19.6663"
"179.96000","29.98817","-249.67654","19.6662"
"180.18000","30.02479","-249.24637","19.6662"
"180.40000","30.06157","-249.61641","19.6662"
"180.62000","30.09823","-249.42502","19.6662"
"180.84000","30.13480","-249.59329","19.6663"
"181.06000","30.17155","-249.43184","19.6662"
"181.28000","30.20813","-249.80896","19.6662"
"181.50000","30.24485","-249.41345","19.6662"
"181.72000","30.28158","-249.53078","19.6662"
"181.94000","30.31817","-249.62996","19.6661"
"182.16000","30.35486","-249.73131","19.6661"
"182.38000","30.39148","-249.65526","19.6661"
"182.60000","30.42817","-249.46425","19.6660"
"182.82000","30.46488","-249.51265","19.6660"
"183.04000","30.50155","-249.31575","19.6659"
"183.26000","30.53821","-249.72702","19.6660"
"183.48000","30.57483","-249.48572","19.6660"
"183.70000","30.61148","-249.72568","19.6659"
"183.92000","30.64820","-249.74393","19.6660"
"184.14000","30.68488","-249.21461","19.6659"
"184.36000","30.72152","-249.62491","19.6660"
"184.58000","30.75819","-249.32300","19.6659"
"184.80000","30.79486","-249.44737","19.6659"
"185.02000","30.83147","-249.53256","19.6659"
"185.24000","30.86823","-249.41394","19.6659"
"185.46000","30.90491","-249.47331","19.6659"
"185.68000","30.94150","-249.73250","19.6658"
"185.90000","30.97820","-249.57846","19.6658"
"186.12000","31.01483","-249.41191","19.6658"
"186.34000","31.05151","-249.47740","19.6659"
"186.56000","31.08821","-249.53520","19.6658"
"186.78000","31.12489","-249.53482","19.6658"
"187.00000","31.16152","-249.38106","19.6657"
"187.22000","31.19815","-249.51981","19.6657"
"187.44000","31.23487","-249.68385","19.6657"
"187.66000","31.27150","-249.49661","19.6657"
"187.88000","31.30820","-249.51590","19.6656"
"188.10000","31.34489","-249.58211","19.6656"
"188.32000","31.38151","-249.75069","19.6656"
"188.54000","31.41816","-249.88751","19.6655"
"188.76000","31.45484","-249.60796","19.6655"
"188.98000","31.49153","-249.79935","19.6654"
"189.20000","31.52820","-249.69395","19.6654"
"189.42000","31.56488","-249.62125","19.6654"
"189.64000","31.60152","-249.51001","19.6651"
"189.86000","31.63815","-249.40491","19.6653"
"190.08000","31.67485","-249.61470","19.6652"
"190.30000","31.71156","-249.50995","19.6652"
"190.52000","31.74818","-249.32364","19.6652"
"190.74000","31.78487","-249.72842","19.6652"
"190.96000","31.82150","-249.57466","19.6652"
"191.18000","31.85818","-249.69971","19.6652"
"191.40000","31.89487","-249.67690","19.6651"
"191.62000","31.93153","-249.95706","19.6652"
"191.84000","31.96821","-249.45552","19.6653"
"192.06000","32.00483","-249.84232","19.6651"
"192.28000","32.04152","-249.59137","19.6651"
"192.50000","32.07819","-249.71103","19.6651"
"192.72000","32.11484","-249.36513","19.6651"
"192.94000","32.15155","-249.62997","19.6652"
"193.16000","32.18820","-249.56161","19.6651"
"193.38000","32.22483","-249.64595","19.6650"
"193.60000","32.26153","-249.42010","19.6650"
"193.82000","32.29817","-249.56316","19.6649"
"194.04000","32.33486","-249.45694","19.6650"
"194.26000","32.37152","-249.58028","19.6651"
"194.48000","32.40821","-249.51746","19.6648"
"194.70000","32.44482","-249.63680","19.6649"
"194.92000","32.48148","-249.64053","19.6649"
"195.14000","32.51825","-249.65543","19.6648"
"195.36000","32.55486","-249.65941","19.6650"
"195.58000","32.59152","-249.44255","19.6648"
"195.80000","32.62820","-249.47829","19.6649"
"196.02000","32.66481","-249.63098","19.6650"
"196.24000","32.70150","-249.59650","19.6648"
"196.46000","32.73820","-249.86937","19.6649"
"196.68000","32.77487","-249.69841","19.6648"
"196.90000","32.81150","-249.70355","19.6647"
"197.12000","32.84821","-249.52499","19.6649"
"197.34000","32.88484","-249.64067","19.6648"
"197.56000","32.92147","-249.48770","19.6647"
"197.78000","32.95826","-249.66609","19.6648"
"198.00000","32.99484","-249.54605","19.6648"
"198.22000","33.03150","-249.59778","19.6648"
"198.44000","33.06820","-249.60406","19.6648"
"198.66000","33.10482","-249.78098","19.6647"
"198.88000","33.14155","-249.28036","19.6647"
"199.10000","33.17819","-249.43347","19.6647"
"199.32000","33.21488","-249.72241","19.6646"
"199.54000","33.25154","-249.42671","19.6647"
"199.76000","33.28815","-249.50595","19.6647"
"199.98000","33.32488","-249.90926","19.6647"
"200.20000","33.36155","-249.70488","19.6647"
"200.42000","33.39818","-249.47121","19.6647"
"200.64000","33.43487","-249.44803","19.6647"
"200.86000","33.47151","-249.51042","19.6647"
"201.08000","33.50813","-249.48271","19.6646"
"201.30000","33.54487","-249.38792","19.6647"
"201.52000","33.58159","-249.80853","19.6646"
"201.74000","33.61815","-249.81743","19.6646"
"201.96000","33.65485","-249.74397","19.6645"
"202.18000","33.69153","-249.73988","19.6644"
"202.40000","33.72817","-249.39023","19.6644"
"202.62000","33.76489","-249.40877","19.6644"
"202.84000","33.80155","-249.53429","19.6643"
"203.06000","33.83817","-249.64502","19.6644"
"203.28000","33.87484","-249.75620","19.6644"
"203.50000","33.91149","-249.69391","19.6644"
"203.72000","33.94818","-249.57620","19.6644"
"203.94000","33.98486","-249.17421","19.6644"
"204.16000","34.02154","-249.64500","19.6643"
"204.38000","34.05819","-249.96858","19.6643"
"204.60000","34.09478","-249.63785","19.6643"
"204.82000","34.13153","-249.54968","19.6643"
"205.04000","34.16822","-249.48143","19.6644"
"205.26000","34.20485","-249.53903","19.6643"
"205.48000","34.24152","-249.62756","19.6643"
"205.70000","34.27814","-249.67673","19.6643"
"205.92000","34.31482","-249.68256","19.6643"
"206.14000","34.35154","-249.35156","19.6643"
"206.36000","34.38823","-249.51901","19.6643"
"206.58000","34.42485","-249.63396","19.6642"
"206.80000","34.46151","-249.63776","19.6642"
"207.02000","34.49818","-249.78108","19.6642"
"207.24000","34.53482","-249.42032","19.6642"
"207.46000","34.57152","-249.70316","19.6642"
"207.68000","34.60823","-249.70001","19.6640"
"207.90000","34.64485","-249.54970","19.6640"
"208.12000","34.68149","-249.64064","19.6641"
"208.34000","34.71815","-249.53137","19.6640"
"208.56000","34.75490","-249.67500","19.6640"
"208.78000","34.79153","-249.90071","19.6639"
"209.00000","34.82821","-249.53136","19.6640"
"209.22000","34.86491","-249.51703","19.6640"
"209.44000","34.90143","-249.60429","19.6639"
"209.66000","34.93819","-249.77280","19.6640"
"209.88000","34.97490","-249.83119","19.6639"
"210.10000","35.01153","-249.59352","19.6639"
"210.32000","35.04823","-249.57745","19.6638"
"210.54000","35.08482","-249.47664","19.6638"
"210.76000","35.12148","-249.47917","19.6639"
"210.98000","35.15818","-249.51300","19.6638"
"211.20000","35.19493","-249.56868","19.6638"
"211.42000","35.23156","-249.61920","19.6638"
"211.64000","35.26816","-249.47610","19.6638"
"211.86000","35.30488","-249.69313","19.6638"
"212.08000","35.34149","-249.83199","19.6638"
"212.30000","35.37819","-249.62801","19.6638"
"212.52000","35.41491","-249.54349","19.6638"
"212.74000","35.45153","-249.61208","19.6637"
"212.96000","35.48817","-249.85440","19.6637"
"213.18000","35.52483","-249.59843","19.6638"
"213.40000","35.56151","-249.61668","19.6638"
"213.62000","35.59820","-249.78412","19.6637"
"213.84000","35.63489","-249.68629","19.6637"
"214.06000","35.67152","-249.67500","19.6637"
"214.28000","35.70813","-249.71748","19.6637"
"214.50000","35.74485","-249.80887","19.6638"
"214.72000","35.78151","-249.72458","19.6637"
"214.94000","35.81818","-249.59712","19.6637"
"215.16000","35.85490","-249.52020","19.6637"
"215.38000","35.89152","-249.55014","19.6636"
"215.60000","35.92818","-249.52100","19.6637"
"215.82000","35.96484","-249.50076","19.6637"
"216.04000","36.00154","-249.65433","19.6637"
"216.26000","36.03823","-249.62642","19.6636"
"216.48000","36.07483","-249.79291","19.6636"
"216.70000","36.11153","-249.69621","19.6636"
"216.92000","36.14817","-249.56055","19.6636"
"217.14000","36.18482","-249.62283","19.6636"
"217.36000","36.22156","-249.49266","19.6636"
"217.58000","36.25821","-249.64523","19.6635"
"217.80000","36.29482","-249.60919","19.6636"
"218.02000","36.33155","-249.65703","19.6636"
"218.24000","36.36819","-249.71320","19.6636"
"218.46000","36.40482","-249.43250","19.6635"
"218.68000","36.44155","-249.71107","19.6636"
"218.90000","36.47823","-249.82300","19.6635"
"219.12000","36.51484","-249.76553","19.6635"
"219.34000","36.55151","-249.67653","19.6635"
"219.56000","36.58819","-249.49586","19.6636"
"219.78000","36.62484","-249.51517","19.6635"
"220.00000","36.66154","-249.69417","19.6635"
"220.22000","36.69820","-249.68269","19.6635"
"220.44000","36.73485","-249.68007","19.6635"
"220.66000","36.77150","-249.68381","19.6635"
"220.88000","36.80817","-249.94868","19.6634"
"221.10000","36.84489","-249.80490","19.6634"
"221.32000","36.88151","-249.64027","19.6635"
"221.54000","36.91821","-249.74281","19.6635"
"221.76000","36.95486","-249.41321","19.6634"
"221.98000","36.99146","-249.47337","19.6634"
"222.20000","37.02821","-249.55788","19.6634"
"222.42000","37.06487","-249.66055","19.6634"
"222.64000","37.10150","-249.71559","19.6634"
"222.86000","37.13821","-249.80981","19.6633"
"223.08000","37.17483","-249.62483","19.6634"
"223.30000","37.21152","-249.47803","19.6634"
"223.52000","37.24819","-249.32372","19.6633"
"223.74000","37.28487","-249.72870","19.6633"
"223.96000","37.32153","-249.46841","19.6633"
"224.18000","37.35819","-249.84842","19.6633"
"224.40000","37.39487","-249.65768","19.6633"
"224.62000","37.43149","-249.80370","19.6633"
"224.84000","37.46821","-249.69231","19.6633"
"225.06000","37.50487","-249.67372","19.6633"
"225.28000","37.54156","-249.72954","19.6630"
"225.50000","37.57814","-249.65639","19.6630"
"225.72000","37.61483","-249.65103","19.6630"
"225.94000","37.65156","-249.49945","19.6631"
"226.16000","37.68816","-249.76384","19.6629"
"226.38000","37.72490","-249.75110","19.6631"
"226.60000","37.76153","-249.61902","19.6631"
"226.82000","37.79812","-249.62402","19.6630"
"227.04000","37.83488","-249.60414","19.6406"
"227.26000","37.87153","-249.69196","19.5912"
"227.48000","37.90820","-249.43123","19.5874"
"227.70000","37.94485","-249.69077","19.6206"
"227.92000","37.98153","-249.58525","19.5575"
"228.14000","38.01818","-249.70638","19.5011"
"228.36000","38.05482","-249.48083","19.3212"
"228.58000","38.09158","-249.74933","19.3608"
"228.80000","38.12821","-249.99217","19.3625"
"229.02000","38.16483","-249.60655","19.2492"
"229.24000","38.20153","-249.60274","19.2485"
"229.46000","38.23815","-249.95198","19.2497"
"229.68000","38.27486","-249.71941","19.2495"
"229.90000","38.31155","-249.54271","19.2498"
"230.12000","38.34819","-249.73148","19.2499"
"230.34000","38.38482","-249.70177","19.2500"
"230.56000","38.42152","-249.95091","19.2500"
"230.78000","38.45821","-249.72060","19.2501"
"231.00000","38.49484","-249.63231","19.2502"
"231.22000","38.53154","-249.71754","19.2501"
"231.25000","38.53654","-249.44725","19.2502"