File: mechanics_and_materials/materials_practical_data/instrondata_machine3_15sep2022_2pm/all_material_instron_data/Al_Work_hardened_5005_H34.csv
Time measurement,Displacement,Primary force measurement,Strain 1
(s),(mm),(N),(%)
"0.00000","0.00000","-0.13355","0.0007"
"0.04000","0.00209","1.73332","0.0008"
"0.08000","0.00729","32.18935","0.0027"
"0.12000","0.01301","74.70996","0.0052"
"0.16000","0.02100","133.40547","0.0090"
"0.20000","0.02828","193.58536","0.0127"
"0.24000","0.03504","239.47733","0.0156"
"0.28000","0.04180","278.63095","0.0181"
"0.32000","0.04856","315.38217","0.0205"
"0.36000","0.05525","351.43796","0.0228"
"0.40000","0.06188","386.89157","0.0251"
"0.44000","0.06855","422.24097","0.0275"
"0.48000","0.07522","457.10333","0.0299"
"0.52000","0.08186","491.50363","0.0323"
"0.56000","0.08856","525.35040","0.0346"
"0.60000","0.09527","559.00647","0.0368"
"0.64000","0.10194","592.43262","0.0392"
"0.68000","0.10859","625.61810","0.0414"
"0.72000","0.11525","658.45300","0.0437"
"0.76000","0.12194","691.05890","0.0459"
"0.80000","0.12858","723.27350","0.0482"
"0.84000","0.13520","754.87054","0.0504"
"0.88000","0.14189","786.08289","0.0526"
"0.92000","0.14860","817.66748","0.0551"
"0.96000","0.15521","849.12787","0.0573"
"1.00000","0.16187","879.87817","0.0595"
"1.04000","0.16858","910.24597","0.0618"
"1.08000","0.17523","940.81030","0.0640"
"1.12000","0.18191","970.08844","0.0664"
"1.16000","0.18858","999.48535","0.0686"
"1.20000","0.19519","1029.26245","0.0708"
"1.24000","0.20189","1058.67883","0.0731"
"1.28000","0.20858","1087.37439","0.0753"
"1.32000","0.21521","1116.12317","0.0779"
"1.36000","0.22192","1144.40979","0.0802"
"1.40000","0.22860","1171.70276","0.0825"
"1.44000","0.23523","1199.19128","0.0849"
"1.48000","0.24189","1227.24878","0.0873"
"1.52000","0.24852","1254.55237","0.0897"
"1.56000","0.25523","1281.41467","0.0922"
"1.60000","0.26192","1307.76221","0.0946"
"1.64000","0.26858","1333.04102","0.0971"
"1.68000","0.27526","1358.58240","0.0995"
"1.72000","0.28194","1383.42249","0.1021"
"1.76000","0.28855","1408.08472","0.1045"
"1.80000","0.29521","1431.77979","0.1070"
"1.84000","0.30188","1455.04321","0.1094"
"1.88000","0.30858","1477.61255","0.1117"
"1.92000","0.31530","1499.90771","0.1142"
"1.96000","0.32198","1522.23901","0.1167"
"2.00000","0.32858","1543.69543","0.1193"
"2.04000","0.33525","1565.23608","0.1218"
"2.08000","0.34191","1586.06433","0.1244"
"2.12000","0.34853","1606.67542","0.1271"
"2.16000","0.35523","1626.27795","0.1297"
"2.20000","0.36196","1645.69373","0.1324"
"2.24000","0.36858","1664.80505","0.1351"
"2.28000","0.37523","1683.31323","0.1378"
"2.32000","0.38189","1701.08228","0.1406"
"2.36000","0.38855","1718.99683","0.1436"
"2.40000","0.39526","1735.58313","0.1464"
"2.44000","0.40193","1751.31274","0.1495"
"2.48000","0.40857","1767.31018","0.1525"
"2.52000","0.41528","1782.70374","0.1556"
"2.56000","0.42192","1797.36633","0.1587"
"2.60000","0.42855","1811.80798","0.1620"
"2.64000","0.43528","1825.86072","0.1654"
"2.68000","0.44193","1838.56750","0.1688"
"2.72000","0.44859","1851.26843","0.1724"
"2.76000","0.45527","1863.75244","0.1761"
"2.80000","0.46188","1875.81531","0.1797"
"2.84000","0.46854","1887.54980","0.1838"
"2.88000","0.47524","1898.99426","0.1878"
"2.92000","0.48192","1909.51941","0.1920"
"2.96000","0.48862","1920.01184","0.1965"
"3.00000","0.49530","1930.01965","0.2009"
"3.04000","0.50193","1939.85327","0.2056"
"3.08000","0.50854","1949.29370","0.2103"
"3.12000","0.51522","1958.06104","0.2153"
"3.16000","0.52191","1967.05981","0.2207"
"3.20000","0.52861","1975.42383","0.2260"
"3.24000","0.53529","1983.11060","0.2315"
"3.28000","0.54195","1990.52319","0.2370"
"3.32000","0.54863","1998.65405","0.2428"
"3.36000","0.55526","2005.63245","0.2488"
"3.40000","0.56185","2012.52332","0.2549"
"3.44000","0.56854","2019.61377","0.2610"
"3.48000","0.57528","2026.06091","0.2675"
"3.52000","0.58192","2032.14514","0.2739"
"3.56000","0.58862","2038.15088","0.2804"
"3.60000","0.59528","2044.12842","0.2871"
"3.64000","0.60189","2049.75708","0.2939"
"3.68000","0.60859","2055.19824","0.3008"
"3.72000","0.61522","2059.91479","0.3077"
"3.76000","0.62188","2064.88159","0.3147"
"3.80000","0.62861","2070.27246","0.3218"
"3.84000","0.63527","2075.32764","0.3289"
"3.88000","0.64194","2079.73071","0.3360"
"3.92000","0.64860","2084.08789","0.3434"
"3.96000","0.65524","2088.68335","0.3507"
"4.00000","0.66194","2092.73242","0.3582"
"4.04000","0.66860","2096.67676","0.3655"
"4.08000","0.67521","2100.79614","0.3727"
"4.12000","0.68194","2104.97192","0.3802"
"4.16000","0.68859","2108.87183","0.3877"
"4.20000","0.69520","2112.39966","0.3951"
"4.24000","0.70191","2116.15894","0.4027"
"4.28000","0.70861","2119.51123","0.4102"
"4.32000","0.71527","2123.19751","0.4176"
"4.36000","0.72193","2126.65039","0.4249"
"4.40000","0.72859","2129.97632","0.4324"
"4.44000","0.73523","2133.69775","0.4397"
"4.48000","0.74191","2136.86035","0.4471"
"4.52000","0.74860","2139.98486","0.4546"
"4.56000","0.75525","2142.90942","0.4620"
"4.60000","0.76195","2146.26465","0.4689"
"4.64000","0.76864","2149.12329","0.4762"
"4.68000","0.77523","2152.43628","0.4834"
"4.72000","0.78187","2155.31787","0.4904"
"4.76000","0.78858","2158.55127","0.4976"
"4.80000","0.79526","2161.54883","0.5048"
"4.84000","0.80195","2164.39136","0.5116"
"4.88000","0.80862","2167.04126","0.5188"
"4.92000","0.81529","2170.28833","0.5258"
"4.96000","0.82194","2172.79688","0.5331"
"5.00000","0.82854","2175.63306","0.5399"
"5.04000","0.83523","2178.17676","0.5470"
"5.08000","0.84195","2181.03296","0.5543"
"5.12000","0.84859","2183.82861","0.5612"
"5.16000","0.85530","2186.36084","0.5685"
"5.20000","0.86196","2188.85474","0.5756"
"5.24000","0.86856","2191.47021","0.5828"
"5.28000","0.87526","2194.06860","0.5900"
"5.32000","0.88192","2196.38745","0.5973"
"5.36000","0.88854","2198.86255","0.6044"
"5.40000","0.89526","2201.41870","0.6116"
"5.44000","0.90195","2204.37891","0.6189"
"5.48000","0.90857","2206.69409","0.6261"
"5.52000","0.91524","2209.12891","0.6333"
"5.56000","0.92191","2211.73413","0.6407"
"5.60000","0.92859","2214.16064","0.6478"
"5.64000","0.93526","2216.60742","0.6548"
"5.68000","0.94193","2218.74707","0.6619"
"5.72000","0.94858","2221.47974","0.6690"
"5.76000","0.95524","2223.75220","0.6758"
"5.80000","0.96189","2225.91187","0.6828"
"5.84000","0.96860","2228.38232","0.6897"
"5.88000","0.97529","2230.82520","0.6964"
"5.92000","0.98195","2233.31348","0.7031"
"5.96000","0.98862","2235.52075","0.7098"
"6.00000","0.99525","2237.70483","0.7162"
"6.04000","1.00189","2239.94043","0.7226"
"6.08000","1.00859","2242.01392","0.7292"
"6.12000","1.01525","2244.22339","0.7358"
"6.16000","1.02191","2246.49561","0.7422"
"6.20000","1.02861","2248.97705","0.7485"
"6.24000","1.03531","2250.95142","0.7553"
"6.28000","1.04190","2253.28027","0.7617"
"6.32000","1.04855","2254.99634","0.7690"
"6.36000","1.05523","2257.53760","0.7753"
"6.40000","1.06191","2259.53784","0.7825"
"6.44000","1.06863","2261.81030","0.7897"
"6.48000","1.07530","2263.78394","0.7969"
"6.52000","1.08192","2265.76562","0.8045"
"6.56000","1.08860","2268.19043","0.8117"
"6.60000","1.09523","2270.25366","0.8193"
"6.64000","1.10189","2272.06567","0.8271"
"6.68000","1.10858","2274.02319","0.8349"
"6.72000","1.11527","2276.29956","0.8427"
"6.76000","1.12195","2278.28076","0.8506"
"6.80000","1.12861","2280.40796","0.8584"
"6.84000","1.13523","2282.29639","0.8662"
"6.88000","1.14192","2284.03125","0.8742"
"6.92000","1.14858","2285.85767","0.8820"
"6.96000","1.15521","2287.92773","0.8898"
"7.00000","1.16191","2289.77539","0.8975"
"7.04000","1.16861","2292.11938","0.9050"
"7.08000","1.17524","2294.08765","0.9125"
"7.12000","1.18191","2296.07251","0.9198"
"7.16000","1.18858","2297.81543","0.9269"
"7.20000","1.19527","2299.89673","0.9334"
"7.24000","1.20195","2301.57764","0.9399"
"7.28000","1.20861","2302.95630","0.9458"
"7.32000","1.21525","2305.14258","0.9512"
"7.36000","1.22192","2307.33838","0.9563"
"7.40000","1.22859","2308.56006","0.9613"
"7.44000","1.23521","2310.54077","0.9659"
"7.48000","1.24192","2312.33789","0.9702"
"7.52000","1.24864","2313.80884","0.9741"
"7.56000","1.25526","2315.72314","0.9779"
"7.60000","1.26193","2317.77832","0.9817"
"7.64000","1.26856","2319.51318","0.9854"
"7.68000","1.27521","2321.64868","0.9892"
"7.72000","1.28194","2323.23169","0.9929"
"7.76000","1.28859","2324.93799","0.9964"
"7.80000","1.29528","2326.83960","1.0003"
"7.84000","1.30198","2328.69824","1.0040"
"7.88000","1.30859","2330.44604","1.0082"
"7.92000","1.31524","2332.10303","1.0128"
"7.96000","1.32188","2333.30884","1.0176"
"8.00000","1.32856","2334.58325","1.0233"
"8.04000","1.33527","2335.70605","1.0299"
"8.08000","1.34193","2336.28638","1.0387"
"8.12000","1.34858","2337.54907","1.0491"
"8.16000","1.35529","2339.11548","1.0611"
"8.20000","1.36191","2341.20898","1.0735"
"8.24000","1.36852","2342.84448","1.0861"
"8.28000","1.37522","2344.54468","1.0987"
"8.32000","1.38194","2346.32812","1.1117"
"8.36000","1.38862","2347.43506","1.1249"
"8.40000","1.39529","2349.47998","1.1381"
"8.44000","1.40196","2350.68481","1.1511"
"8.48000","1.40859","2351.92017","1.1640"
"8.52000","1.41524","2353.12891","1.1766"
"8.56000","1.42190","2354.45898","1.1892"
"8.60000","1.42856","2355.52148","1.2017"
"8.64000","1.43528","2356.72705","1.2144"
"8.68000","1.44195","2357.09131","1.2275"
"8.72000","1.44859","2357.64136","1.2411"
"8.76000","1.45526","2359.80200","1.2534"
"8.80000","1.46193","2362.99243","1.2634"
"8.84000","1.46860","2365.12988","1.2712"
"8.88000","1.47526","2366.08130","1.2766"
"8.92000","1.48190","2367.42676","1.2806"
"8.96000","1.48859","2368.72388","1.2832"
"9.00000","1.49527","2370.06445","1.2853"
"9.04000","1.50189","2371.66016","1.2871"
"9.08000","1.50860","2373.21655","1.2886"
"9.12000","1.51527","2374.56030","1.2899"
"9.16000","1.52192","2376.37842","1.2910"
"9.20000","1.52860","2378.14722","1.2922"
"9.24000","1.53521","2379.60327","1.2931"
"9.28000","1.54187","2381.47144","1.2940"
"9.32000","1.54859","2383.23657","1.2948"
"9.36000","1.55527","2384.67871","1.2955"
"9.40000","1.56194","2386.37085","1.2963"
"9.44000","1.56864","2388.00146","1.2972"
"9.48000","1.57525","2389.93604","1.2981"
"9.52000","1.58187","2392.01636","1.2990"
"9.56000","1.58856","2393.49048","1.2997"
"9.60000","1.59527","2395.07837","1.3005"
"9.64000","1.60195","2396.58252","1.3014"
"9.68000","1.60862","2397.75586","1.3022"
"9.72000","1.61530","2399.10693","1.3029"
"9.76000","1.62195","2399.97754","1.3037"
"9.80000","1.62859","2400.31543","1.3045"
"9.84000","1.63522","2400.68579","1.3053"
"9.88000","1.64192","2401.61743","1.3061"
"9.92000","1.64861","2402.50146","1.3068"
"9.96000","1.65527","2402.71436","1.3075"
"10.00000","1.66195","2405.21338","1.3085"
"10.04000","1.66861","2409.51074","1.3095"
"10.08000","1.67526","2412.21606","1.3106"
"10.12000","1.68194","2412.83447","1.3116"
"10.16000","1.68858","2414.19043","1.3127"
"10.20000","1.69522","2416.94336","1.3139"
"10.24000","1.70195","2419.16504","1.3150"
"10.28000","1.70863","2420.42822","1.3162"
"10.32000","1.71523","2421.97632","1.3177"
"10.36000","1.72194","2423.57007","1.3191"
"10.40000","1.72860","2425.44312","1.3207"
"10.44000","1.73524","2428.06177","1.3228"
"10.48000","1.74193","2429.86670","1.3257"
"10.52000","1.74858","2413.60522","1.3418"
"10.56000","1.75524","2406.89844","1.3675"
"10.60000","1.76190","2412.74243","1.3901"
"10.64000","1.76856","2414.19067","1.4147"
"10.68000","1.77526","2416.42725","1.4392"
"10.72000","1.78196","2418.85059","1.4640"
"10.76000","1.78862","2421.26318","1.4885"
"10.80000","1.79526","2423.61450","1.5128"
"10.84000","1.80189","2425.28027","1.5378"
"10.88000","1.80856","2426.46460","1.5633"
"10.92000","1.81527","2427.76953","1.5888"
"10.96000","1.82194","2427.61230","1.6148"
"11.00000","1.82860","2427.34033","1.6410"
"11.04000","1.83531","2429.26587","1.6658"
"11.08000","1.84196","2433.06152","1.6872"
"11.12000","1.84853","2435.49023","1.7046"
"11.16000","1.85519","2436.95728","1.7207"
"11.20000","1.86194","2437.54614","1.7357"
"11.24000","1.86861","2438.81763","1.7485"
"11.28000","1.87529","2440.71655","1.7589"
"11.32000","1.88196","2442.52954","1.7661"
"11.36000","1.88860","2444.15967","1.7699"
"11.40000","1.89527","2445.33228","1.7720"
"11.44000","1.90192","2446.80835","1.7734"
"11.48000","1.90854","2448.93188","1.7746"
"11.52000","1.91528","2452.24658","1.7759"
"11.56000","1.92197","2454.06470","1.7769"
"11.60000","1.92859","2452.65186","1.7776"
"11.64000","1.93528","2443.90747","1.7778"
"11.68000","1.94191","2442.88159","1.7782"
"11.72000","1.94859","2446.74731","1.7787"
"11.76000","1.95525","2449.09619","1.7792"
"11.80000","1.96188","2452.27417","1.7799"
"11.84000","1.96860","2456.06738","1.7806"
"11.88000","1.97528","2459.33374","1.7813"
"11.92000","1.98191","2461.80493","1.7821"
"11.96000","1.98860","2463.67871","1.7827"
"12.00000","1.99524","2463.82812","1.7834"
"12.04000","2.00189","2463.55518","1.7841"
"12.08000","2.00858","2463.51318","1.7846"
"12.12000","2.01525","2464.57275","1.7854"
"12.16000","2.02191","2465.61255","1.7861"
"12.20000","2.02858","2467.44116","1.7867"
"12.24000","2.03526","2468.54395","1.7874"
"12.28000","2.04193","2462.16260","1.7875"
"12.32000","2.04863","2455.62378","1.7877"
"12.36000","2.05531","2460.85376","1.7885"
"12.40000","2.06192","2464.40918","1.7892"
"12.44000","2.06856","2466.14746","1.7899"
"12.48000","2.07525","2467.49561","1.7905"
"12.52000","2.08188","2468.90088","1.7911"
"12.56000","2.08859","2469.99780","1.7917"
"12.60000","2.09529","2470.78149","1.7923"
"12.64000","2.10194","2472.25977","1.7930"
"12.68000","2.10863","2473.99438","1.7937"
"12.72000","2.11522","2473.83228","1.7946"
"12.76000","2.12185","2473.02515","1.7953"
"12.80000","2.12858","2473.45630","1.7959"
"12.84000","2.13527","2475.56299","1.7964"
"12.88000","2.14196","2479.54688","1.7972"
"12.92000","2.14865","2482.75049","1.7978"
"12.96000","2.15527","2482.82471","1.7981"
"13.00000","2.16194","2483.84619","1.7987"
"13.04000","2.16856","2487.38989","1.7995"
"13.08000","2.17520","2480.33838","1.7996"
"13.12000","2.18193","2474.33423","1.7996"
"13.16000","2.18862","2486.26367","1.8010"
"13.20000","2.19526","2494.46509","1.8023"
"13.24000","2.20193","2498.50659","1.8033"
"13.28000","2.20859","2493.03784","1.8037"
"13.32000","2.21523","2482.98413","1.8036"
"13.36000","2.22191","2486.57910","1.8042"
"13.40000","2.22856","2488.63818","1.8048"
"13.44000","2.23525","2489.59058","1.8053"
"13.48000","2.24196","2491.18555","1.8059"
"13.52000","2.24862","2492.18018","1.8064"
"13.56000","2.25525","2487.16382","1.8063"
"13.60000","2.26194","2489.24829","1.8069"
"13.64000","2.26862","2495.67627","1.8077"
"13.68000","2.27525","2500.59839","1.8084"
"13.72000","2.28191","2504.44458","1.8092"
"13.76000","2.28861","2507.45068","1.8100"
"13.80000","2.29525","2509.24121","1.8107"
"13.84000","2.30191","2509.53882","1.8114"
"13.88000","2.30857","2509.26904","1.8120"
"13.92000","2.31526","2509.03491","1.8126"
"13.96000","2.32196","2508.21240","1.8132"
"14.00000","2.32857","2505.41821","1.8138"
"14.04000","2.33524","2502.12158","1.8145"
"14.08000","2.34193","2504.09424","1.8158"
"14.12000","2.34857","2505.71924","1.8187"
"14.16000","2.35528","2482.09888","1.8407"
"14.20000","2.36194","2477.30981","1.8664"
"14.24000","2.36858","2483.46973","1.8885"
"14.28000","2.37529","2484.07397","1.9131"
"14.32000","2.38192","2483.90015","1.9389"
"14.36000","2.38850","2485.26587","1.9644"
"14.40000","2.39520","2487.25562","1.9897"
"14.44000","2.40191","2488.94556","2.0157"
"14.48000","2.40859","2490.11230","2.0418"
"14.52000","2.41530","2491.23413","2.0678"
"14.56000","2.42198","2492.22339","2.0940"
"14.60000","2.42859","2493.22656","2.1204"
"14.64000","2.43522","2493.82397","2.1471"
"14.68000","2.44188","2494.43140","2.1740"
"14.72000","2.44858","2495.34546","2.2008"
"14.76000","2.45529","2496.38916","2.2273"
"14.80000","2.46197","2497.37427","2.2537"
"14.84000","2.46862","2498.18115","2.2801"
"14.88000","2.47526","2498.57202","2.3065"
"14.92000","2.48193","2499.05298","2.3327"
"14.96000","2.48859","2498.81274","2.3573"
"15.00000","2.49524","2497.20874","2.3768"
"15.04000","2.50191","2495.84033","2.3892"
"15.08000","2.50862","2495.67896","2.3966"
"15.12000","2.51528","2497.96167","2.4026"
"15.16000","2.52190","2500.56567","2.4081"
"15.20000","2.52858","2503.40967","2.4132"
"15.24000","2.53528","2505.26245","2.4192"
"15.28000","2.54191","2504.91675","2.4264"
"15.32000","2.54859","2504.53735","2.4339"
"15.36000","2.55527","2506.15210","2.4407"
"15.40000","2.56189","2508.20752","2.4459"
"15.44000","2.56859","2507.91821","2.4496"
"15.48000","2.57526","2504.23486","2.4518"
"15.52000","2.58192","2505.82373","2.4535"
"15.56000","2.58862","2512.55249","2.4556"
"15.60000","2.59527","2517.77930","2.4576"
"15.64000","2.60191","2520.21997","2.4600"
"15.68000","2.60857","2516.51318","2.4623"
"15.72000","2.61524","2512.61890","2.4644"
"15.76000","2.62192","2513.20581","2.4667"
"15.80000","2.62860","2515.44531","2.4689"
"15.84000","2.63526","2518.88306","2.4715"
"15.88000","2.64197","2522.07129","2.4748"
"15.92000","2.64859","2524.79224","2.4793"
"15.96000","2.65521","2524.59375","2.4876"
"16.00000","2.66192","2520.41064","2.5022"
"16.04000","2.66860","2520.21411","2.5188"
"16.08000","2.67525","2522.73242","2.5339"
"16.12000","2.68196","2524.19849","2.5469"
"16.16000","2.68863","2525.15283","2.5573"
"16.20000","2.69526","2525.85083","2.5651"
"16.24000","2.70191","2526.18506","2.5712"
"16.28000","2.70857","2526.61304","2.5761"
"16.32000","2.71520","2527.08423","2.5799"
"16.36000","2.72193","2526.85205","2.5830"
"16.40000","2.72864","2527.02490","2.5854"
"16.44000","2.73525","2527.73413","2.5875"
"16.48000","2.74192","2528.72876","2.5895"
"16.52000","2.74862","2529.10718","2.5912"
"16.56000","2.75524","2529.33472","2.5926"
"16.60000","2.76191","2529.13354","2.5938"
"16.64000","2.76858","2529.43579","2.5949"
"16.68000","2.77526","2529.40039","2.5958"
"16.72000","2.78197","2528.95679","2.5966"
"16.76000","2.78857","2528.22827","2.5972"
"16.80000","2.79525","2528.25244","2.5978"
"16.84000","2.80194","2528.35376","2.5983"
"16.88000","2.80858","2529.17993","2.5988"
"16.92000","2.81527","2530.05249","2.5994"
"16.96000","2.82193","2531.49292","2.5999"
"17.00000","2.82855","2533.59204","2.6004"
"17.04000","2.83524","2535.06104","2.6011"
"17.08000","2.84190","2535.68433","2.6015"
"17.12000","2.84858","2533.56836","2.6019"
"17.16000","2.85530","2526.62720","2.6021"
"17.20000","2.86196","2522.96973","2.6023"
"17.24000","2.86858","2524.95923","2.6031"
"17.28000","2.87522","2525.64282","2.6035"
"17.32000","2.88191","2525.76685","2.6040"
"17.36000","2.88859","2525.54663","2.6045"
"17.40000","2.89528","2525.04980","2.6050"
"17.44000","2.90196","2525.36792","2.6053"
"17.48000","2.90863","2525.89185","2.6058"
"17.52000","2.91527","2527.31152","2.6063"
"17.56000","2.92188","2528.78784","2.6068"
"17.60000","2.92853","2530.73877","2.6073"
"17.64000","2.93526","2532.99878","2.6077"
"17.68000","2.94195","2535.21216","2.6084"
"17.72000","2.94861","2537.77832","2.6089"
"17.76000","2.95528","2540.55054","2.6097"
"17.80000","2.96193","2541.59741","2.6101"
"17.84000","2.96857","2542.52612","2.6108"
"17.88000","2.97523","2541.23267","2.6111"
"17.92000","2.98188","2536.67651","2.6111"
"17.96000","2.98860","2537.09448","2.6113"
"18.00000","2.99529","2539.83691","2.6117"
"18.04000","3.00191","2542.18726","2.6123"
"18.08000","3.00862","2543.59912","2.6126"
"18.12000","3.01526","2543.41772","2.6129"
"18.16000","3.02189","2541.12964","2.6130"
"18.20000","3.02860","2536.66382","2.6130"
"18.24000","3.03525","2534.20776","2.6133"
"18.28000","3.04193","2534.94092","2.6135"
"18.32000","3.04862","2534.62598","2.6140"
"18.36000","3.05524","2534.37109","2.6142"
"18.40000","3.06188","2534.54468","2.6145"
"18.44000","3.06861","2534.20483","2.6149"
"18.48000","3.07529","2533.71484","2.6152"
"18.52000","3.08193","2533.70996","2.6156"
"18.56000","3.08860","2533.79346","2.6159"
"18.60000","3.09527","2533.23584","2.6162"
"18.64000","3.10191","2532.47534","2.6165"
"18.68000","3.10857","2531.78979","2.6168"
"18.72000","3.11525","2530.63452","2.6169"
"18.76000","3.12194","2529.19751","2.6172"
"18.80000","3.12863","2525.30103","2.6171"
"18.84000","3.13525","2521.51685","2.6170"
"18.88000","3.14188","2521.16895","2.6171"
"18.92000","3.14857","2521.27319","2.6170"
"18.96000","3.15522","2521.06738","2.6173"
"19.00000","3.16193","2521.29932","2.6173"
"19.04000","3.16863","2520.96216","2.6175"
"19.08000","3.17529","2520.88965","2.6174"
"19.12000","3.18197","2521.19238","2.6174"
"19.16000","3.18856","2520.41895","2.6177"
"19.20000","3.19516","2520.44043","2.6175"
"19.24000","3.20193","2520.51050","2.6177"
"19.28000","3.20863","2519.61865","2.6174"
"19.32000","3.21526","2518.78564","2.6175"
"19.36000","3.22198","2516.28760","2.6173"
"19.40000","3.22861","2507.77588","2.6169"
"19.44000","3.23522","2504.61719","2.6169"
"19.48000","3.24190","2504.48706","2.6167"
"19.52000","3.24855","2503.03979","2.6171"
"19.56000","3.25524","2502.77124","2.6171"
"19.60000","3.26195","2501.88721","2.6171"
"19.64000","3.26860","2501.35962","2.6173"
"19.68000","3.27526","2500.58154","2.6174"
"19.72000","3.28194","2499.34985","2.6176"
"19.76000","3.28859","2498.22559","2.6175"
"19.80000","3.29524","2497.52148","2.6176"
"19.84000","3.30192","2496.42480","2.6177"
"19.88000","3.30860","2495.31958","2.6178"
"19.92000","3.31530","2494.51245","2.6179"
"19.96000","3.32193","2493.01465","2.6181"
"20.00000","3.32858","2491.78784","2.6180"
"20.04000","3.33529","2490.66602","2.6182"
"20.08000","3.34196","2489.24854","2.6181"
"20.12000","3.34858","2487.89966","2.6183"
"20.16000","3.35526","2487.06812","2.6184"
"20.20000","3.36196","2485.80811","2.6183"
"20.24000","3.36855","2484.11719","2.6184"
"20.28000","3.37523","2483.14502","2.6185"
"20.32000","3.38194","2481.55298","2.6186"
"20.36000","3.38860","2480.13916","2.6186"
"20.40000","3.39530","2479.22290","2.6186"
"20.44000","3.40193","2477.39355","2.6185"
"20.48000","3.40853","2475.78687","2.6186"
"20.52000","3.41523","2474.41650","2.6188"
"20.56000","3.42194","2472.78247","2.6187"
"20.60000","3.42858","2471.36084","2.6188"
"20.64000","3.43529","2469.39307","2.6189"
"20.68000","3.44194","2467.64087","2.6187"
"20.72000","3.44861","2466.14941","2.6188"
"20.76000","3.45523","2464.21313","2.6189"
"20.80000","3.46184","2462.92773","2.6187"
"20.84000","3.46858","2460.95703","2.6189"
"20.88000","3.47528","2459.15186","2.6187"
"20.92000","3.48193","2457.27051","2.6187"
"20.96000","3.48865","2455.35547","2.6188"
"21.00000","3.49529","2453.85156","2.6186"
"21.04000","3.50190","2451.73804","2.6187"
"21.08000","3.50856","2449.87842","2.6187"
"21.12000","3.51523","2448.05688","2.6186"
"21.16000","3.52193","2445.87158","2.6187"
"21.20000","3.52864","2443.81299","2.6184"
"21.24000","3.53530","2441.13062","2.6184"
"21.28000","3.54191","2438.51270","2.6182"
"21.32000","3.54858","2434.82178","2.6180"
"21.36000","3.55526","2430.40967","2.6178"
"21.40000","3.56189","2428.06860","2.6177"
"21.44000","3.56856","2427.28076","2.6176"
"21.48000","3.57529","2426.10938","2.6174"
"21.52000","3.58193","2424.72876","2.6173"
"21.56000","3.58857","2422.52612","2.6172"
"21.60000","3.59524","2420.06836","2.6172"
"21.64000","3.60191","2418.13574","2.6169"
"21.68000","3.60861","2415.82471","2.6169"
"21.72000","3.61525","2413.94678","2.6165"
"21.76000","3.62192","2411.34155","2.6169"
"21.80000","3.62862","2409.64673","2.6167"
"21.84000","3.63525","2407.53662","2.6164"
"21.88000","3.64192","2405.66309","2.6166"
"21.92000","3.64861","2403.51953","2.6163"
"21.96000","3.65526","2401.24829","2.6165"
"22.00000","3.66197","2399.08521","2.6163"
"22.04000","3.66862","2396.65552","2.6162"
"22.08000","3.67523","2394.27954","2.6163"
"22.12000","3.68191","2391.51855","2.6162"
"22.16000","3.68856","2389.27856","2.6160"
"22.20000","3.69523","2386.74536","2.6159"
"22.24000","3.70195","2383.96460","2.6158"
"22.28000","3.70862","2381.02295","2.6158"
"22.32000","3.71525","2378.57202","2.6157"
"22.36000","3.72188","2375.92017","2.6155"
"22.40000","3.72855","2372.79053","2.6154"
"22.44000","3.73524","2370.25244","2.6153"
"22.48000","3.74195","2367.23755","2.6152"
"22.52000","3.74862","2363.83008","2.6151"
"22.56000","3.75529","2360.93726","2.6149"
"22.60000","3.76196","2358.15430","2.6148"
"22.64000","3.76859","2354.76636","2.6148"
"22.68000","3.77521","2351.62842","2.6146"
"22.72000","3.78188","2348.78052","2.6145"
"22.76000","3.78859","2345.30957","2.6143"
"22.80000","3.79528","2342.05664","2.6142"
"22.84000","3.80197","2338.82617","2.6140"
"22.88000","3.80859","2335.39429","2.6138"
"22.92000","3.81526","2332.03394","2.6137"
"22.96000","3.82194","2328.61646","2.6136"
"23.00000","3.82855","2324.77466","2.6134"
"23.04000","3.83523","2321.22827","2.6133"
"23.08000","3.84194","2317.48047","2.6131"
"23.12000","3.84861","2313.68726","2.6130"
"23.16000","3.85529","2309.94214","2.6128"
"23.20000","3.86192","2306.36157","2.6126"
"23.24000","3.86854","2302.54541","2.6124"
"23.28000","3.87528","2298.32983","2.6122"
"23.32000","3.88194","2293.92920","2.6121"
"23.36000","3.88858","2290.33301","2.6120"
"23.40000","3.89527","2286.16479","2.6116"
"23.44000","3.90193","2281.97974","2.6115"
"23.48000","3.90855","2277.48926","2.6112"
"23.52000","3.91525","2273.48682","2.6110"
"23.56000","3.92196","2269.11377","2.6108"
"23.60000","3.92861","2264.64282","2.6106"
"23.64000","3.93527","2259.86694","2.6105"
"23.68000","3.94193","2255.57202","2.6101"
"23.72000","3.94859","2250.51172","2.6099"
"23.76000","3.95527","2245.80273","2.6099"
"23.80000","3.96193","2241.28613","2.6095"
"23.84000","3.96860","2236.47583","2.6093"
"23.88000","3.97529","2231.52563","2.6090"
"23.92000","3.98197","2226.58765","2.6088"
"23.96000","3.98859","2221.35327","2.6085"
"24.00000","3.99520","2216.14062","2.6082"
"24.04000","4.00189","2211.03931","2.6080"
"24.08000","4.00861","2205.56885","2.6077"
"24.12000","4.01530","2200.30371","2.6075"
"24.16000","4.02194","2194.53638","2.6072"
"24.20000","4.02862","2189.60522","2.6070"
"24.24000","4.03529","2184.01465","2.6066"
"24.28000","4.04187","2178.14917","2.6064"
"24.32000","4.04856","2172.36523","2.6060"
"24.36000","4.05526","2166.78296","2.6058"
"24.40000","4.06192","2160.36450","2.6054"
"24.44000","4.06865","2154.72437","2.6051"
"24.48000","4.07530","2148.43408","2.6048"
"24.52000","4.08191","2142.48169","2.6044"
"24.56000","4.08860","2136.01514","2.6040"
"24.60000","4.09525","2129.40112","2.6037"
"24.64000","4.10190","2122.84985","2.6033"
"24.68000","4.10859","2116.70850","2.6030"
"24.72000","4.11528","2110.31519","2.6026"
"24.76000","4.12194","2103.73315","2.6022"
"24.80000","4.12859","2096.54102","2.6018"
"24.84000","4.13523","2089.58545","2.6014"
"24.88000","4.14193","2082.50464","2.6009"
"24.92000","4.14859","2075.34424","2.6005"
"24.96000","4.15525","2068.09277","2.6000"
"25.00000","4.16194","2060.99976","2.5996"
"25.04000","4.16860","2053.51270","2.5992"
"25.08000","4.17524","2045.77112","2.5986"
"25.12000","4.18192","2037.68445","2.5982"
"25.16000","4.18861","2029.92004","2.5977"
"25.20000","4.19528","2022.12915","2.5972"
"25.24000","4.20196","2013.90161","2.5967"
"25.28000","4.20860","2006.06421","2.5963"
"25.32000","4.21523","1997.35242","2.5957"
"25.36000","4.22191","1988.95898","2.5952"
"25.40000","4.22860","1980.27869","2.5946"
"25.44000","4.23525","1971.84924","2.5941"
"25.48000","4.24195","1962.94238","2.5936"
"25.52000","4.24865","1953.76721","2.5931"
"25.56000","4.25524","1944.64526","2.5924"
"25.60000","4.26187","1935.28162","2.5919"
"25.64000","4.26857","1926.01758","2.5913"
"25.68000","4.27527","1916.37134","2.5907"
"25.72000","4.28199","1906.44360","2.5902"
"25.76000","4.28862","1895.97327","2.5895"
"25.80000","4.29530","1886.55273","2.5890"
"25.84000","4.30194","1876.11426","2.5882"
"25.88000","4.30856","1865.08228","2.5876"
"25.92000","4.31524","1854.28784","2.5869"
"25.96000","4.32189","1843.33069","2.5862"
"26.00000","4.32859","1832.45667","2.5856"
"26.04000","4.33531","1820.80176","2.5848"
"26.08000","4.34194","1809.26379","2.5842"
"26.12000","4.34857","1797.31824","2.5835"
"26.16000","4.35527","1785.13770","2.5828"
"26.20000","4.36192","1772.67236","2.5819"
"26.24000","4.36857","1760.01868","2.5811"
"26.28000","4.37527","1746.71899","2.5802"
"26.32000","4.38197","1733.27795","2.5794"
"26.36000","4.38860","1719.98572","2.5786"
"26.40000","4.39527","1706.03564","2.5776"
"26.44000","4.40193","1691.29504","2.5767"
"26.48000","4.40859","1676.80444","2.5756"
"26.52000","4.41528","1661.40906","2.5746"
"26.56000","4.42194","1646.08118","2.5735"
"26.60000","4.42859","1630.09387","2.5725"
"26.64000","4.43529","1613.55627","2.5715"
"26.68000","4.44192","1595.64917","2.5702"
"26.72000","4.44857","1576.33496","2.5690"
"26.76000","4.45528","1554.32751","2.5675"
"26.80000","4.46197","1526.05872","2.5657"
"26.84000","4.46865","1486.50818","2.5632"
"26.88000","4.47530","1427.34863","2.5596"
"26.92000","4.48193","1261.03149","2.5507"
"26.93200","4.48405","967.69116","2.5321"
"26.93500","4.48458","874.88611","2.5270"