File: mechanics_and_materials/materials_practical_data/instrondata_machine3_15sep2022_2pm/all_material_instron_data/Copper_Annealed.csv
Time measurement,Displacement,Primary force measurement,Strain 1
(s),(mm),(N),(%)
"0.00000","0.00000","-1.11002","0.0006"
"0.12000","0.01267","73.05355","0.0043"
"0.24000","0.03482","242.39642","0.0146"
"0.36000","0.05490","367.48749","0.0236"
"0.48000","0.07493","483.37827","0.0322"
"0.60000","0.09491","594.00342","0.0411"
"0.72000","0.11493","700.79803","0.0508"
"0.84000","0.13491","803.00970","0.0634"
"0.96000","0.15485","900.90259","0.0722"
"1.08000","0.17494","995.09302","0.0815"
"1.20000","0.19494","1085.15393","0.0917"
"1.32000","0.21494","1170.44202","0.1015"
"1.44000","0.23493","1251.13757","0.1111"
"1.56000","0.25494","1326.05518","0.1202"
"1.68000","0.27491","1394.78784","0.1295"
"1.80000","0.29494","1458.28296","0.1388"
"1.92000","0.31490","1514.85681","0.1470"
"2.04000","0.33497","1567.35315","0.1553"
"2.16000","0.35497","1613.12683","0.1638"
"2.28000","0.37492","1654.05212","0.1714"
"2.40000","0.39495","1690.50903","0.1785"
"2.52000","0.41493","1723.31689","0.1859"
"2.64000","0.43499","1752.82288","0.1952"
"2.76000","0.45495","1779.52722","0.2028"
"2.88000","0.47497","1803.20032","0.2112"
"3.00000","0.49494","1825.79370","0.2192"
"3.12000","0.51500","1846.56396","0.2280"
"3.24000","0.53492","1865.20520","0.2380"
"3.36000","0.55492","1883.60754","0.2487"
"3.48000","0.57493","1900.29895","0.2593"
"3.60000","0.59490","1916.71790","0.2725"
"3.72000","0.61496","1931.09570","0.2853"
"3.84000","0.63489","1945.51196","0.3003"
"3.96000","0.65497","1958.19287","0.3169"
"4.08000","0.67497","1970.27454","0.3355"
"4.20000","0.69491","1980.81824","0.3561"
"4.32000","0.71493","1990.87183","0.3780"
"4.44000","0.73497","1999.63208","0.4017"
"4.56000","0.75497","2007.85291","0.4284"
"4.68000","0.77498","2014.65112","0.4571"
"4.80000","0.79495","2020.39148","0.4870"
"4.92000","0.81493","2026.74475","0.5187"
"5.04000","0.83498","2031.34619","0.5514"
"5.16000","0.85491","2036.01575","0.5845"
"5.28000","0.87499","2039.86316","0.6177"
"5.40000","0.89496","2044.03320","0.6508"
"5.52000","0.91498","2047.83472","0.6836"
"5.64000","0.93497","2051.64160","0.7161"
"5.76000","0.95493","2055.08618","0.7482"
"5.88000","0.97499","2058.16577","0.7799"
"6.00000","0.99494","2062.06567","0.8111"
"6.12000","1.01495","2065.27319","0.8421"
"6.24000","1.03491","2068.74341","0.8726"
"6.36000","1.05497","2072.20996","0.9030"
"6.48000","1.07493","2075.22241","0.9331"
"6.60000","1.09497","2078.64111","0.9626"
"6.72000","1.11492","2081.68018","0.9914"
"6.84000","1.13493","2084.62988","1.0205"
"6.96000","1.15496","2087.38647","1.0494"
"7.08000","1.17490","2090.23145","1.0778"
"7.20000","1.19498","2093.37549","1.1061"
"7.32000","1.21494","2096.16577","1.1341"
"7.44000","1.23497","2098.74683","1.1619"
"7.56000","1.25495","2101.89624","1.1895"
"7.68000","1.27496","2104.89111","1.2172"
"7.80000","1.29493","2107.78662","1.2448"
"7.92000","1.31498","2110.60181","1.2721"
"8.04000","1.33492","2113.07788","1.2993"
"8.16000","1.35495","2115.80664","1.3262"
"8.28000","1.37502","2118.35791","1.3530"
"8.40000","1.39494","2120.44653","1.3797"
"8.52000","1.41499","2123.31592","1.4065"
"8.64000","1.43493","2126.06885","1.4331"
"8.76000","1.45494","2128.27783","1.4594"
"8.88000","1.47496","2131.02466","1.4860"
"9.00000","1.49493","2133.30566","1.5124"
"9.12000","1.51497","2135.87451","1.5387"
"9.24000","1.53498","2138.14404","1.5649"
"9.36000","1.55495","2140.47485","1.5910"
"9.48000","1.57492","2142.95435","1.6172"
"9.60000","1.59496","2145.17261","1.6430"
"9.72000","1.61489","2147.79004","1.6689"
"9.84000","1.63496","2150.05347","1.6949"
"9.96000","1.65487","2152.32568","1.7206"
"10.08000","1.67496","2154.88867","1.7468"
"10.20000","1.69497","2157.19092","1.7729"
"10.32000","1.71494","2159.35010","1.7988"
"10.44000","1.73500","2162.05542","1.8247"
"10.56000","1.75496","2164.22534","1.8503"
"10.68000","1.77498","2166.49731","1.8761"
"10.80000","1.79493","2168.29492","1.9020"
"10.92000","1.81495","2170.79517","1.9274"
"11.04000","1.83497","2173.17700","1.9530"
"11.16000","1.85500","2174.47144","1.9791"
"11.28000","1.87494","2177.02661","2.0046"
"11.40000","1.89495","2179.19116","2.0303"
"11.52000","1.91495","2181.70166","2.0559"
"11.64000","1.93496","2183.44214","2.0817"
"11.76000","1.95502","2185.56567","2.1075"
"11.88000","1.97492","2187.47925","2.1331"
"12.00000","1.99499","2189.36938","2.1586"
"12.12000","2.01495","2191.66284","2.1841"
"12.24000","2.03492","2193.71460","2.2096"
"12.36000","2.05494","2195.87402","2.2352"
"12.48000","2.07494","2197.63208","2.2605"
"12.60000","2.09494","2200.23218","2.2859"
"12.72000","2.11495","2201.98633","2.3117"
"12.84000","2.13493","2203.99878","2.3370"
"12.96000","2.15492","2206.04736","2.3625"
"13.08000","2.17497","2207.67798","2.3880"
"13.20000","2.19490","2209.77441","2.4133"
"13.32000","2.21496","2211.52368","2.4386"
"13.44000","2.23495","2213.85059","2.4638"
"13.56000","2.25495","2215.61108","2.4888"
"13.68000","2.27498","2217.77563","2.5143"
"13.80000","2.29494","2219.85449","2.5397"
"13.92000","2.31497","2221.66602","2.5647"
"14.04000","2.33496","2223.51587","2.5905"
"14.16000","2.35494","2225.35181","2.6160"
"14.28000","2.37494","2227.20850","2.6413"
"14.40000","2.39499","2228.82153","2.6664"
"14.52000","2.41496","2230.98877","2.6918"
"14.64000","2.43497","2232.40405","2.7172"
"14.76000","2.45492","2234.25439","2.7424"
"14.88000","2.47498","2236.45435","2.7676"
"15.00000","2.49497","2238.23560","2.7927"
"15.12000","2.51489","2240.40015","2.8181"
"15.24000","2.53498","2241.86719","2.8434"
"15.36000","2.55493","2244.18970","2.8684"
"15.48000","2.57494","2245.30713","2.8937"
"15.60000","2.59492","2247.44458","2.9191"
"15.72000","2.61494","2248.72021","2.9441"
"15.84000","2.63493","2250.63965","2.9692"
"15.96000","2.65495","2252.47168","2.9944"
"16.08000","2.67491","2253.97632","3.0192"
"16.20000","2.69496","2256.18188","3.0446"
"16.32000","2.71500","2257.15356","3.0696"
"16.44000","2.73492","2259.45386","3.0947"
"16.56000","2.75497","2260.79980","3.1199"
"16.68000","2.77491","2262.57446","3.1449"
"16.80000","2.79497","2264.29785","3.1701"
"16.92000","2.81497","2265.81445","3.1951"
"17.04000","2.83495","2267.49536","3.2203"
"17.16000","2.85496","2269.50244","3.2453"
"17.28000","2.87499","2271.13843","3.2702"
"17.40000","2.89496","2272.26196","3.2951"
"17.52000","2.91496","2274.43433","3.3200"
"17.64000","2.93496","2276.05029","3.3451"
"17.76000","2.95492","2277.37964","3.3701"
"17.88000","2.97498","2278.96411","3.3951"
"18.00000","2.99491","2280.65137","3.4202"
"18.12000","3.01499","2282.22266","3.4456"
"18.24000","3.03498","2283.85962","3.4702"
"18.36000","3.05494","2285.49048","3.4950"
"18.48000","3.07496","2287.00586","3.5198"
"18.60000","3.09493","2288.53442","3.5450"
"18.72000","3.11495","2290.31470","3.5696"
"18.84000","3.13494","2291.82031","3.5949"
"18.96000","3.15491","2293.18018","3.6196"
"19.08000","3.17491","2294.94531","3.6446"
"19.20000","3.19499","2296.16797","3.6699"
"19.32000","3.21493","2297.97485","3.6945"
"19.44000","3.23496","2299.54932","3.7199"
"19.56000","3.25496","2300.91650","3.7448"
"19.68000","3.27496","2302.60107","3.7695"
"19.80000","3.29499","2304.06934","3.7943"
"19.92000","3.31491","2305.06055","3.8192"
"20.04000","3.33502","2306.82764","3.8439"
"20.16000","3.35496","2308.21802","3.8689"
"20.28000","3.37494","2309.50586","3.8938"
"20.40000","3.39494","2311.14697","3.9188"
"20.52000","3.41493","2312.55396","3.9437"
"20.64000","3.43495","2313.96924","3.9685"
"20.76000","3.45497","2315.35645","3.9935"
"20.88000","3.47495","2316.69678","4.0183"
"21.00000","3.49495","2318.00732","4.0432"
"21.12000","3.51499","2319.58594","4.0678"
"21.24000","3.53490","2321.04785","4.0927"
"21.36000","3.55495","2322.32520","4.1179"
"21.48000","3.57490","2324.08496","4.1425"
"21.60000","3.59493","2325.58032","4.1671"
"21.72000","3.61492","2327.22241","4.1919"
"21.84000","3.63490","2328.39966","4.2169"
"21.96000","3.65497","2329.91162","4.2419"
"22.08000","3.67496","2331.43213","4.2666"
"22.20000","3.69496","2332.16162","4.2913"
"22.32000","3.71493","2333.92676","4.3161"
"22.44000","3.73498","2335.06592","4.3408"
"22.56000","3.75495","2336.66626","4.3654"
"22.68000","3.77495","2337.78638","4.3902"
"22.80000","3.79491","2339.41016","4.4146"
"22.92000","3.81496","2340.77271","4.4395"
"23.04000","3.83498","2342.14038","4.4643"
"23.16000","3.85494","2343.52124","4.4891"
"23.28000","3.87500","2344.46753","4.5139"
"23.40000","3.89498","2345.83252","4.5388"
"23.52000","3.91498","2347.26660","4.5635"
"23.64000","3.93495","2348.57397","4.5883"
"23.76000","3.95495","2349.60181","4.6129"
"23.88000","3.97497","2350.91772","4.6378"
"24.00000","3.99497","2352.36987","4.6625"
"24.12000","4.01491","2353.74780","4.6870"
"24.24000","4.03493","2354.78564","4.7122"
"24.36000","4.05497","2356.26953","4.7366"
"24.48000","4.07495","2357.81738","4.7614"
"24.60000","4.09497","2358.97241","4.7862"
"24.72000","4.11493","2359.93433","4.8109"
"24.84000","4.13495","2361.37427","4.8357"
"24.96000","4.15494","2362.80298","4.8604"
"25.08000","4.17491","2363.83447","4.8846"
"25.20000","4.19494","2365.29932","4.9095"
"25.32000","4.21496","2366.71851","4.9344"
"25.44000","4.23496","2367.97656","4.9589"
"25.56000","4.25495","2369.34790","4.9836"
"25.68000","4.27498","2370.08984","5.0083"
"25.80000","4.29494","2371.70825","5.0330"
"25.92000","4.31500","2372.82568","5.0577"
"26.04000","4.33490","2374.09326","5.0825"
"26.16000","4.35495","2374.91382","5.1070"
"26.28000","4.37497","2376.31738","5.1315"
"26.40000","4.39496","2377.29224","5.1562"
"26.52000","4.41499","2378.49756","5.1808"
"26.64000","4.43493","2379.90820","5.2054"
"26.76000","4.45496","2380.82275","5.2298"
"26.88000","4.47495","2382.36401","5.2545"
"27.00000","4.49495","2383.08667","5.2791"
"27.12000","4.51494","2384.33521","5.3040"
"27.24000","4.53497","2385.44727","5.3285"
"27.36000","4.55493","2386.53979","5.3528"
"27.48000","4.57496","2387.77393","5.3774"
"27.60000","4.59491","2389.12012","5.4018"
"27.72000","4.61494","2390.25439","5.4266"
"27.84000","4.63495","2391.20703","5.4514"
"27.96000","4.65489","2392.72803","5.4755"
"28.08000","4.67497","2393.42139","5.5002"
"28.20000","4.69496","2394.77222","5.5252"
"28.32000","4.71494","2395.90991","5.5494"
"28.44000","4.73497","2396.85449","5.5742"
"28.56000","4.75496","2398.17334","5.5989"
"28.68000","4.77495","2399.63452","5.6232"
"28.80000","4.79496","2400.56226","5.6483"
"28.92000","4.81495","2401.61133","5.6730"
"29.04000","4.83496","2402.69092","5.6972"
"29.16000","4.85500","2403.97925","5.7216"
"29.28000","4.87492","2404.83203","5.7462"
"29.40000","4.89497","2406.21851","5.7710"
"29.52000","4.91494","2406.96631","5.7952"
"29.64000","4.93499","2407.94189","5.8199"
"29.76000","4.95496","2409.22314","5.8449"
"29.88000","4.97495","2410.24170","5.8695"
"30.00000","4.99497","2411.27246","5.8941"
"30.12000","5.01498","2412.43066","5.9185"
"30.24000","5.03494","2413.20386","5.9427"
"30.36000","5.05492","2414.50806","5.9675"
"30.48000","5.07496","2415.65063","5.9918"
"30.60000","5.09490","2417.04346","6.0166"
"30.72000","5.11495","2417.89844","6.0416"
"30.84000","5.13488","2419.03564","6.0657"
"30.96000","5.15498","2419.85645","6.0900"
"31.08000","5.17496","2421.04883","6.1142"
"31.20000","5.19491","2421.96997","6.1392"
"31.32000","5.21497","2423.10962","6.1636"
"31.44000","5.23494","2424.12183","6.1881"
"31.56000","5.25497","2425.28833","6.2125"
"31.68000","5.27495","2426.39087","6.2372"
"31.80000","5.29496","2426.92798","6.2616"
"31.92000","5.31495","2428.21704","6.2860"
"32.04000","5.33498","2428.73340","6.3106"
"32.16000","5.35493","2430.06836","6.3355"
"32.28000","5.37496","2431.20825","6.3602"
"32.40000","5.39497","2432.19409","6.3846"
"32.52000","5.41496","2432.96948","6.4089"
"32.64000","5.43500","2433.80054","6.4340"
"32.76000","5.45492","2434.86157","6.4584"
"32.88000","5.47501","2435.55566","6.4826"
"33.00000","5.49495","2436.94849","6.5069"
"33.12000","5.51491","2437.62329","6.5315"
"33.24000","5.53492","2438.62646","6.5566"
"33.36000","5.55495","2439.82031","6.5810"
"33.48000","5.57494","2441.04541","6.6054"
"33.60000","5.59495","2441.64136","6.6300"
"33.72000","5.61495","2442.56250","6.6542"
"33.84000","5.63492","2443.74585","6.6788"
"33.96000","5.65497","2444.50195","6.7032"
"34.08000","5.67488","2445.37378","6.7276"
"34.20000","5.69497","2446.70728","6.7521"
"34.32000","5.71496","2447.62012","6.7763"
"34.44000","5.73496","2448.63330","6.8009"
"34.56000","5.75496","2449.55835","6.8253"
"34.68000","5.77494","2450.44043","6.8500"
"34.80000","5.79495","2451.38501","6.8743"
"34.92000","5.81495","2452.47607","6.8988"
"35.04000","5.83496","2453.03247","6.9233"
"35.16000","5.85493","2454.33813","6.9477"
"35.28000","5.87501","2455.09473","6.9723"
"35.40000","5.89493","2456.00586","6.9966"
"35.52000","5.91497","2456.81787","7.0209"
"35.64000","5.93496","2457.77759","7.0453"
"35.76000","5.95495","2458.77466","7.0699"
"35.88000","5.97497","2459.62378","7.0942"
"36.00000","5.99491","2460.34033","7.1185"
"36.12000","6.01500","2461.23169","7.1432"
"36.24000","6.03495","2462.22632","7.1680"
"36.36000","6.05497","2463.04590","7.1923"
"36.48000","6.07492","2463.76221","7.2166"
"36.60000","6.09494","2464.54028","7.2408"
"36.72000","6.11491","2465.59058","7.2651"
"36.84000","6.13494","2466.63867","7.2898"
"36.96000","6.15492","2467.45361","7.3140"
"37.08000","6.17494","2468.39233","7.3386"
"37.20000","6.19498","2469.12231","7.3632"
"37.32000","6.21493","2470.12036","7.3877"
"37.44000","6.23500","2470.90991","7.4124"
"37.56000","6.25493","2471.50098","7.4370"
"37.68000","6.27496","2472.55908","7.4616"
"37.80000","6.29495","2473.56348","7.4855"
"37.92000","6.31493","2474.34497","7.5097"
"38.04000","6.33498","2475.08984","7.5341"
"38.16000","6.35498","2475.75049","7.5593"
"38.28000","6.37494","2476.82886","7.5836"
"38.40000","6.39492","2477.77393","7.6082"
"38.52000","6.41498","2478.20923","7.6327"
"38.64000","6.43493","2479.25562","7.6571"
"38.76000","6.45499","2479.77539","7.6816"
"38.88000","6.47491","2480.73071","7.7059"
"39.00000","6.49496","2481.48535","7.7304"
"39.12000","6.51500","2482.60693","7.7548"
"39.24000","6.53491","2483.19458","7.7790"
"39.36000","6.55495","2483.98584","7.8033"
"39.48000","6.57490","2484.88916","7.8278"
"39.60000","6.59495","2485.65234","7.8521"
"39.72000","6.61492","2486.62378","7.8765"
"39.84000","6.63492","2487.22070","7.9009"
"39.96000","6.65494","2488.01318","7.9254"
"40.08000","6.67499","2488.78442","7.9500"
"40.20000","6.69492","2489.40869","7.9743"
"40.32000","6.71494","2490.67896","7.9988"
"40.44000","6.73496","2491.19189","8.0230"
"40.56000","6.75495","2492.24048","8.0475"
"40.68000","6.77502","2493.02563","8.0716"
"40.80000","6.79491","2493.69849","8.0961"
"40.92000","6.81497","2494.46802","8.1205"
"41.04000","6.83495","2495.53711","8.1450"
"41.16000","6.85491","2496.18506","8.1693"
"41.28000","6.87497","2496.90430","8.1937"
"41.40000","6.89498","2497.44287","8.2183"
"41.52000","6.91502","2498.33447","8.2425"
"41.64000","6.93495","2498.93384","8.2669"
"41.76000","6.95496","2499.43799","8.2913"
"41.88000","6.97495","2500.61377","8.3158"
"42.00000","6.99497","2501.19849","8.3401"
"42.12000","7.01487","2501.96143","8.3642"
"42.24000","7.03495","2502.44092","8.3886"
"42.36000","7.05494","2503.60303","8.4131"
"42.48000","7.07494","2504.13037","8.4373"
"42.60000","7.09495","2504.98706","8.4620"
"42.72000","7.11493","2505.59424","8.4866"
"42.84000","7.13494","2506.24072","8.5107"
"42.96000","7.15493","2507.30518","8.5351"
"43.08000","7.17494","2507.69214","8.5594"
"43.20000","7.19493","2508.71191","8.5837"
"43.32000","7.21499","2509.00659","8.6081"
"43.44000","7.23494","2509.89673","8.6324"
"43.56000","7.25496","2510.80688","8.6568"
"43.68000","7.27493","2511.49146","8.6812"
"43.80000","7.29499","2512.36865","8.7056"
"43.92000","7.31498","2512.71606","8.7298"
"44.04000","7.33491","2513.42920","8.7543"
"44.16000","7.35499","2514.02588","8.7787"
"44.28000","7.37498","2514.81616","8.8030"
"44.40000","7.39496","2515.21509","8.8271"
"44.52000","7.41495","2516.12427","8.8516"
"44.64000","7.43496","2517.04297","8.8760"
"44.76000","7.45494","2517.69385","8.9004"
"44.88000","7.47496","2518.56201","8.9249"
"45.00000","7.49497","2518.85156","8.9491"
"45.12000","7.51497","2519.97681","8.9739"
"45.24000","7.53500","2520.18726","8.9983"
"45.36000","7.55491","2521.24707","9.0223"
"45.48000","7.57494","2521.49121","9.0467"
"45.60000","7.59489","2522.15991","9.0710"
"45.72000","7.61494","2522.78662","9.0955"
"45.84000","7.63493","2523.82446","9.1197"
"45.96000","7.65492","2524.40576","9.1439"
"46.08000","7.67495","2524.93945","9.1683"
"46.20000","7.69497","2525.94751","9.1926"
"46.32000","7.71495","2526.24414","9.2171"
"46.44000","7.73494","2527.06787","9.2417"
"46.56000","7.75496","2527.57153","9.2661"
"46.68000","7.77493","2528.35376","9.2905"
"46.80000","7.79497","2528.74463","9.3147"
"46.92000","7.81489","2529.63281","9.3387"
"47.04000","7.83499","2529.96509","9.3634"
"47.16000","7.85498","2530.92456","9.3876"
"47.28000","7.87493","2531.37622","9.4117"
"47.40000","7.89496","2531.91821","9.4365"
"47.52000","7.91495","2532.75391","9.4610"
"47.64000","7.93498","2533.36084","9.4853"
"47.76000","7.95497","2534.14062","9.5099"
"47.88000","7.97496","2534.49072","9.5342"
"48.00000","7.99493","2535.12891","9.5586"
"48.12000","8.01501","2535.65283","9.5830"
"48.24000","8.03491","2536.18750","9.6071"
"48.36000","8.05493","2537.17529","9.6315"
"48.48000","8.07493","2537.71265","9.6559"
"48.60000","8.09492","2538.39233","9.6802"
"48.72000","8.11497","2538.62378","9.7047"
"48.84000","8.13491","2539.29932","9.7292"
"48.96000","8.15497","2539.99316","9.7536"
"49.08000","8.17495","2540.83374","9.7781"
"49.20000","8.19494","2541.41382","9.8023"
"49.32000","8.21493","2541.88257","9.8265"
"49.44000","8.23496","2542.50269","9.8509"
"49.56000","8.25495","2543.21387","9.8752"
"49.68000","8.27497","2543.72070","9.8996"
"49.80000","8.29495","2544.21680","9.9237"
"49.92000","8.31496","2544.88599","9.9482"
"50.04000","8.33498","2545.36865","9.9726"
"50.16000","8.35490","2546.34155","9.9970"
"50.28000","8.37499","2546.43848","10.0216"
"50.40000","8.39494","2547.06470","10.0460"
"50.52000","8.41497","2547.80249","10.0704"
"50.64000","8.43497","2548.32129","10.0948"
"50.76000","8.45494","2548.85425","10.1190"
"50.88000","8.47500","2549.40039","10.1433"
"51.00000","8.49496","2549.65942","10.1679"
"51.12000","8.51493","2550.33008","10.1920"
"51.24000","8.53490","2551.09326","10.2164"
"51.36000","8.55497","2551.59521","10.2410"
"51.48000","8.57493","2552.39478","10.2653"
"51.60000","8.59493","2552.74243","10.2898"
"51.72000","8.61490","2553.10498","10.3142"
"51.84000","8.63495","2553.96411","10.3387"
"51.96000","8.65496","2554.20850","10.3630"
"52.08000","8.67491","2555.04932","10.3874"
"52.20000","8.69498","2555.42236","10.4117"
"52.32000","8.71496","2556.18750","10.4360"
"52.44000","8.73497","2556.51929","10.4604"
"52.56000","8.75494","2557.23853","10.4849"
"52.68000","8.77496","2557.89526","10.5094"
"52.80000","8.79493","2558.65967","10.5338"
"52.92000","8.81498","2558.81470","10.5585"
"53.04000","8.83493","2559.40527","10.5826"
"53.16000","8.85495","2559.84668","10.6071"
"53.28000","8.87501","2560.11890","10.6315"
"53.40000","8.89495","2560.82153","10.6557"
"53.52000","8.91501","2561.30371","10.6800"
"53.64000","8.93493","2562.39868","10.7045"
"53.76000","8.95499","2562.37476","10.7290"
"53.88000","8.97496","2562.97168","10.7535"
"54.00000","8.99493","2563.27417","10.7780"
"54.12000","9.01496","2564.20850","10.8023"
"54.24000","9.03498","2564.48999","10.8269"
"54.36000","9.05495","2564.77661","10.8511"
"54.48000","9.07492","2565.40186","10.8756"
"54.60000","9.09495","2565.77002","10.8999"
"54.72000","9.11492","2566.49634","10.9243"
"54.84000","9.13496","2566.75439","10.9485"
"54.96000","9.15489","2567.25293","10.9729"
"55.08000","9.17495","2568.17236","10.9974"
"55.20000","9.19497","2568.39551","11.0218"
"55.32000","9.21493","2568.92700","11.0463"
"55.44000","9.23498","2569.37598","11.0707"
"55.56000","9.25497","2569.98901","11.0952"
"55.68000","9.27497","2570.27954","11.1196"
"55.80000","9.29495","2570.99634","11.1438"
"55.92000","9.31494","2571.42163","11.1681"
"56.04000","9.33495","2571.90161","11.1925"
"56.16000","9.35498","2572.44629","11.2171"
"56.28000","9.37490","2572.63379","11.2412"
"56.40000","9.39497","2573.33325","11.2657"
"56.52000","9.41495","2573.61670","11.2902"
"56.64000","9.43497","2574.45264","11.3149"
"56.76000","9.45499","2574.61377","11.3393"
"56.88000","9.47493","2575.36108","11.3639"
"57.00000","9.49500","2575.59595","11.3884"
"57.12000","9.51497","2576.25000","11.4128"
"57.24000","9.53494","2576.18628","11.4372"
"57.36000","9.55491","2576.96924","11.4614"
"57.48000","9.57495","2577.61914","11.4861"
"57.60000","9.59494","2578.05444","11.5104"
"57.72000","9.61493","2578.26123","11.5348"
"57.84000","9.63494","2578.88354","11.5594"
"57.96000","9.65492","2579.21240","11.5840"
"58.08000","9.67500","2579.73999","11.6085"
"58.20000","9.69490","2580.15894","11.6329"
"58.32000","9.71498","2580.63721","11.6574"
"58.44000","9.73495","2581.16357","11.6817"
"58.56000","9.75496","2581.58154","11.7062"
"58.68000","9.77498","2581.98926","11.7305"
"58.80000","9.79493","2582.85938","11.7550"
"58.92000","9.81497","2583.31812","11.7797"
"59.04000","9.83496","2583.35278","11.8044"
"59.16000","9.85495","2583.95215","11.8288"
"59.28000","9.87497","2584.43164","11.8534"
"59.40000","9.89499","2584.70898","11.8780"
"59.52000","9.91497","2585.40723","11.9025"
"59.64000","9.93499","2585.57349","11.9271"
"59.76000","9.95490","2586.07153","11.9513"
"59.88000","9.97499","2586.37134","11.9759"
"60.00000","9.99497","2586.83057","12.0004"
"60.12000","10.01490","2587.10547","12.0248"
"60.24000","10.03496","2587.82983","12.0491"
"60.36000","10.05490","2588.21094","12.0737"
"60.48000","10.07496","2588.51978","12.0983"
"60.60000","10.09492","2589.08228","12.1228"
"60.72000","10.11494","2589.42261","12.1474"
"60.84000","10.13492","2589.84204","12.1719"
"60.96000","10.15496","2590.24756","12.1964"
"61.08000","10.17493","2590.67212","12.2206"
"61.20000","10.19493","2590.93188","12.2451"
"61.32000","10.21498","2591.49585","12.2694"
"61.44000","10.23494","2591.73096","12.2941"
"61.56000","10.25500","2592.22119","12.3186"
"61.68000","10.27490","2592.82153","12.3429"
"61.80000","10.29497","2593.19238","12.3676"
"61.92000","10.31497","2593.77441","12.3923"
"62.04000","10.33494","2593.56616","12.4168"
"62.16000","10.35495","2594.12427","12.4411"
"62.28000","10.37497","2594.30493","12.4655"
"62.40000","10.39498","2594.67358","12.4901"
"62.52000","10.41497","2595.26465","12.5146"
"62.64000","10.43499","2595.39233","12.5389"
"62.76000","10.45494","2596.07227","12.5635"
"62.88000","10.47498","2596.12378","12.5881"
"63.00000","10.49489","2596.93896","12.6127"
"63.12000","10.51499","2597.08740","12.6373"
"63.24000","10.53496","2597.87793","12.6618"
"63.36000","10.55493","2597.89795","12.6864"
"63.48000","10.57497","2598.29150","12.7109"
"63.60000","10.59491","2598.71558","12.7353"
"63.72000","10.61495","2598.98022","12.7598"
"63.84000","10.63491","2599.46509","12.7845"
"63.96000","10.65492","2599.58081","12.8087"
"64.08000","10.67491","2600.42725","12.8335"
"64.20000","10.69499","2600.69824","12.8581"
"64.32000","10.71492","2600.81787","12.8828"
"64.44000","10.73499","2601.23584","12.9074"
"64.56000","10.75497","2602.08521","12.9317"
"64.68000","10.77494","2602.04126","12.9566"
"64.80000","10.79498","2602.11792","12.9810"
"64.92000","10.81491","2602.61133","13.0056"
"65.04000","10.83500","2602.64233","13.0299"
"65.16000","10.85495","2603.09888","13.0546"
"65.28000","10.87496","2603.57007","13.0791"
"65.40000","10.89494","2604.23584","13.1038"
"65.52000","10.91496","2604.42505","13.1284"
"65.64000","10.93494","2604.90015","13.1529"
"65.76000","10.95496","2605.02148","13.1776"
"65.88000","10.97495","2605.27441","13.2021"
"66.00000","10.99494","2605.61914","13.2266"
"66.12000","11.01501","2606.19238","13.2514"
"66.24000","11.03490","2606.28760","13.2761"
"66.36000","11.05496","2606.74878","13.3007"
"66.48000","11.07493","2607.13892","13.3252"
"66.60000","11.09493","2607.48877","13.3499"
"66.72000","11.11494","2607.71729","13.3742"
"66.84000","11.13491","2608.14062","13.3990"
"66.96000","11.15496","2608.52515","13.4236"
"67.08000","11.17499","2609.16772","13.4482"
"67.20000","11.19494","2609.01025","13.4728"
"67.32000","11.21493","2609.46240","13.4973"
"67.44000","11.23498","2609.58472","13.5219"
"67.56000","11.25495","2610.08008","13.5465"
"67.68000","11.27499","2609.99341","13.5710"
"67.80000","11.29492","2610.75146","13.5954"
"67.92000","11.31498","2611.29004","13.6201"
"68.04000","11.33498","2611.51147","13.6448"
"68.16000","11.35493","2611.75049","13.6694"
"68.28000","11.37501","2611.92798","13.6940"
"68.40000","11.39495","2612.20776","13.7188"
"68.52000","11.41498","2612.41724","13.7432"
"68.64000","11.43495","2612.78687","13.7678"
"68.76000","11.45495","2612.73584","13.7924"
"68.88000","11.47496","2613.47681","13.8172"
"69.00000","11.49498","2613.76587","13.8417"
"69.12000","11.51490","2613.85400","13.8663"
"69.24000","11.53496","2614.24707","13.8910"
"69.36000","11.55494","2614.61743","13.9157"
"69.48000","11.57493","2614.86719","13.9404"
"69.60000","11.59498","2615.12012","13.9650"
"69.72000","11.61489","2615.49487","13.9896"
"69.84000","11.63496","2615.93286","14.0144"
"69.96000","11.65491","2616.06030","14.0390"
"70.08000","11.67491","2616.13452","14.0637"
"70.20000","11.69497","2616.77271","14.0882"
"70.32000","11.71496","2617.16138","14.1127"
"70.44000","11.73498","2617.38379","14.1372"
"70.56000","11.75495","2617.43506","14.1617"
"70.68000","11.77496","2617.87744","14.1863"
"70.80000","11.79494","2618.09863","14.2109"
"70.92000","11.81497","2618.45972","14.2355"
"71.04000","11.83490","2618.77148","14.2611"
"71.16000","11.85496","2618.91992","14.2856"
"71.28000","11.87498","2619.19385","14.3103"
"71.40000","11.89496","2619.21387","14.3351"
"71.52000","11.91499","2619.73022","14.3599"
"71.64000","11.93494","2620.06177","14.3846"
"71.76000","11.95497","2620.48267","14.4091"
"71.88000","11.97492","2620.55688","14.4340"
"72.00000","11.99494","2620.57886","14.4589"
"72.12000","12.01493","2621.14062","14.4835"
"72.24000","12.03499","2621.34839","14.5083"
"72.36000","12.05492","2621.63574","14.5333"
"72.48000","12.07493","2621.70557","14.5580"
"72.60000","12.09492","2621.97290","14.5826"
"72.72000","12.11494","2622.52734","14.6075"
"72.84000","12.13496","2622.59595","14.6321"
"72.96000","12.15488","2622.89771","14.6567"
"73.08000","12.17498","2623.20337","14.6815"
"73.20000","12.19495","2623.75635","14.7062"
"73.32000","12.21494","2623.51831","14.7310"
"73.44000","12.23495","2624.11255","14.7556"
"73.56000","12.25497","2624.13477","14.7804"
"73.68000","12.27496","2624.66797","14.8053"
"73.80000","12.29496","2624.88989","14.8304"
"73.92000","12.31495","2624.83179","14.8548"
"74.04000","12.33497","2625.50122","14.8795"
"74.16000","12.35500","2625.38940","14.9041"
"74.28000","12.37490","2625.91870","14.9290"
"74.40000","12.39497","2625.37476","14.9539"
"74.52000","12.41491","2626.02295","14.9786"
"74.64000","12.43497","2626.64502","15.0035"
"74.76000","12.45497","2626.72998","15.0282"
"74.88000","12.47497","2626.75317","15.0533"
"75.00000","12.49498","2627.04858","15.0777"
"75.12000","12.51498","2627.31982","15.1026"
"75.24000","12.53494","2627.26978","15.1272"
"75.36000","12.55491","2627.73120","15.1521"
"75.48000","12.57495","2627.75415","15.1766"
"75.60000","12.59489","2628.42578","15.2013"
"75.72000","12.61496","2628.69824","15.2262"
"75.84000","12.63487","2628.57202","15.2510"
"75.96000","12.65497","2629.19800","15.2758"
"76.08000","12.67497","2629.13208","15.3005"
"76.20000","12.69492","2629.58716","15.3254"
"76.32000","12.71497","2629.48901","15.3501"
"76.44000","12.73497","2630.12036","15.3750"
"76.56000","12.75497","2629.97046","15.3995"
"76.68000","12.77496","2630.29932","15.4243"
"76.80000","12.79494","2630.37500","15.4490"
"76.92000","12.81492","2630.75732","15.4738"
"77.04000","12.83499","2630.88159","15.4986"
"77.16000","12.85492","2630.89233","15.5232"
"77.28000","12.87496","2631.51587","15.5483"
"77.40000","12.89500","2631.70312","15.5731"
"77.52000","12.91495","2631.82251","15.5976"
"77.64000","12.93501","2631.69482","15.6222"
"77.76000","12.95494","2631.81323","15.6470"
"77.88000","12.97500","2632.17480","15.6717"
"78.00000","12.99493","2632.38330","15.6963"
"78.12000","13.01492","2632.40039","15.7212"
"78.24000","13.03493","2632.79712","15.7459"
"78.36000","13.05493","2633.23486","15.7708"
"78.48000","13.07494","2633.70972","15.7955"
"78.60000","13.09494","2633.84595","15.8203"
"78.72000","13.11495","2633.58960","15.8451"
"78.84000","13.13491","2633.91016","15.8698"
"78.96000","13.15497","2634.08838","15.8945"
"79.08000","13.17488","2634.19116","15.9191"
"79.20000","13.19498","2634.55981","15.9441"
"79.32000","13.21495","2634.60278","15.9686"
"79.44000","13.23497","2635.02344","15.9932"
"79.56000","13.25496","2635.13989","16.0179"
"79.68000","13.27493","2635.25928","16.0426"
"79.80000","13.29499","2635.67310","16.0673"
"79.92000","13.31496","2635.66284","16.0924"
"80.04000","13.33496","2635.20508","16.1171"
"80.16000","13.35494","2635.70068","16.1419"
"80.28000","13.37500","2635.89575","16.1666"
"80.40000","13.39495","2636.19604","16.1912"
"80.52000","13.41497","2636.52222","16.2158"
"80.64000","13.43495","2636.34961","16.2404"
"80.76000","13.45495","2636.66016","16.2653"
"80.88000","13.47499","2636.66333","16.2900"
"81.00000","13.49492","2637.09619","16.3148"
"81.12000","13.51500","2637.22046","16.3396"
"81.24000","13.53496","2637.40112","16.3644"
"81.36000","13.55495","2637.40186","16.3890"
"81.48000","13.57491","2637.77222","16.4136"
"81.60000","13.59493","2637.78149","16.4382"
"81.72000","13.61492","2638.04614","16.4627"
"81.84000","13.63495","2638.23853","16.4873"
"81.96000","13.65493","2638.25342","16.5118"
"82.08000","13.67494","2638.79810","16.5366"
"82.20000","13.69500","2638.94922","16.5613"
"82.32000","13.71491","2638.99805","16.5859"
"82.44000","13.73502","2638.88330","16.6105"
"82.56000","13.75493","2638.96387","16.6351"
"82.68000","13.77497","2639.17456","16.6596"
"82.80000","13.79495","2639.50781","16.6841"
"82.92000","13.81492","2639.45239","16.7085"
"83.04000","13.83499","2639.66724","16.7329"
"83.16000","13.85496","2639.79883","16.7575"
"83.28000","13.87496","2639.65430","16.7817"
"83.40000","13.89493","2639.95312","16.8064"
"83.52000","13.91498","2640.11035","16.8310"
"83.64000","13.93493","2640.36377","16.8553"
"83.76000","13.95499","2640.36475","16.8797"
"83.88000","13.97492","2640.48975","16.9039"
"84.00000","13.99495","2640.42700","16.9279"
"84.12000","14.01497","2640.85986","16.9516"
"84.24000","14.03491","2640.92578","16.9760"
"84.36000","14.05496","2640.88501","17.0003"
"84.48000","14.07492","2641.22461","17.0244"
"84.60000","14.09496","2641.18774","17.0482"
"84.72000","14.11491","2641.71875","17.0722"
"84.84000","14.13493","2641.26855","17.0959"
"84.96000","14.15492","2642.04248","17.1196"
"85.08000","14.17497","2642.23901","17.1432"
"85.20000","14.19491","2642.05078","17.1665"
"85.32000","14.21496","2641.98755","17.1896"
"85.44000","14.23498","2642.16992","17.2119"
"85.56000","14.25495","2642.45361","17.2339"
"85.68000","14.27499","2642.24512","17.2554"
"85.80000","14.29492","2642.59741","17.2755"
"85.92000","14.31498","2642.68286","17.2934"
"86.04000","14.33496","2642.76660","17.3089"
"86.16000","14.35495","2642.79370","17.3187"
"86.28000","14.37496","2642.95630","17.2554"
"86.40000","14.39496","2642.92725","17.2540"
"86.52000","14.41497","2643.25854","17.2726"
"86.64000","14.43495","2643.24585","17.2945"
"86.76000","14.45498","2642.97510","17.3176"
"86.88000","14.47495","2643.53442","17.3408"
"87.00000","14.49498","2643.32715","17.3644"
"87.12000","14.51488","2643.80249","17.3883"
"87.24000","14.53494","2643.82373","17.4122"
"87.36000","14.55493","2644.01782","17.4357"
"87.48000","14.57494","2644.39526","17.4597"
"87.60000","14.59495","2644.00122","17.4840"
"87.72000","14.61491","2644.43970","17.5083"
"87.84000","14.63495","2644.59546","17.5321"
"87.96000","14.65494","2644.55664","17.5564"
"88.08000","14.67491","2644.59131","17.5804"
"88.20000","14.69495","2644.76782","17.6048"
"88.32000","14.71499","2644.92822","17.6287"
"88.44000","14.73493","2644.93066","17.6527"
"88.56000","14.75498","2645.14209","17.6768"
"88.68000","14.77490","2644.99048","17.7006"
"88.80000","14.79498","2645.33057","17.7242"
"88.92000","14.81500","2645.15845","17.7479"
"89.04000","14.83490","2645.12646","17.7712"
"89.16000","14.85498","2645.60767","17.7944"
"89.28000","14.87496","2645.53906","17.8176"
"89.40000","14.89496","2645.54614","17.8400"
"89.52000","14.91495","2645.41870","17.8622"
"89.64000","14.93496","2645.94580","17.8862"
"89.76000","14.95496","2645.71948","17.9085"
"89.88000","14.97497","2645.85278","17.9302"
"90.00000","14.99497","2646.04663","17.9512"
"90.12000","15.01495","2645.66943","17.9714"
"90.24000","15.03500","2646.10547","17.9886"
"90.36000","15.05490","2645.95752","18.0021"
"90.48000","15.07497","2646.23901","18.0176"
"90.60000","15.09490","2646.38916","18.0374"
"90.72000","15.11493","2646.57910","18.0595"
"90.84000","15.13494","2647.04077","18.0824"
"90.96000","15.15491","2646.58887","18.1057"
"91.08000","15.17496","2646.97070","18.1295"
"91.20000","15.19495","2647.03467","18.1531"
"91.32000","15.21498","2647.22241","18.1768"
"91.44000","15.23495","2647.01660","18.2015"
"91.56000","15.25500","2647.05566","18.2255"
"91.68000","15.27493","2647.09521","18.2494"
"91.80000","15.29497","2647.04736","18.2737"
"91.92000","15.31490","2647.20850","18.2977"
"92.04000","15.33500","2647.09253","18.3218"
"92.16000","15.35499","2647.42114","18.3460"
"92.28000","15.37492","2646.71069","18.3704"
"92.40000","15.39496","2647.68481","18.3946"
"92.52000","15.41495","2647.31006","18.4189"
"92.64000","15.43498","2647.53467","18.4395"
"92.76000","15.45494","2647.64648","18.4637"
"92.88000","15.47495","2647.36426","18.4872"
"93.00000","15.49493","2647.80225","18.5108"
"93.12000","15.51499","2647.78125","18.5339"
"93.24000","15.53492","2647.79932","18.5572"
"93.36000","15.55496","2647.93457","18.5807"
"93.48000","15.57495","2647.75513","18.6037"
"93.60000","15.59490","2647.91724","18.6267"
"93.72000","15.61495","2647.91333","18.6501"
"93.84000","15.63488","2648.21655","18.6735"
"93.96000","15.65498","2648.03906","18.6965"
"94.08000","15.67496","2648.31714","18.7191"
"94.20000","15.69495","2648.33398","18.7415"
"94.32000","15.71495","2648.35693","18.7634"
"94.44000","15.73497","2648.38599","18.7845"
"94.56000","15.75495","2648.12012","18.8023"
"94.68000","15.77496","2648.67334","18.8115"
"94.80000","15.79496","2648.28735","18.8110"
"94.92000","15.81493","2648.61230","18.8109"
"95.04000","15.83500","2648.45093","18.8186"
"95.16000","15.85489","2648.53271","18.8362"
"95.28000","15.87500","2648.56128","18.8570"
"95.40000","15.89495","2648.66895","18.8790"
"95.52000","15.91498","2648.68726","18.9009"
"95.64000","15.93498","2648.97827","18.9233"
"95.76000","15.95494","2648.62231","18.9462"
"95.88000","15.97498","2648.42651","18.9692"
"96.00000","15.99497","2648.74365","18.9923"
"96.12000","16.01494","2648.45068","19.0156"
"96.24000","16.03489","2648.48975","19.0391"
"96.36000","16.05495","2648.60962","19.0627"
"96.48000","16.07490","2648.85205","19.0862"
"96.60000","16.09496","2649.11865","19.1101"
"96.72000","16.11489","2648.92480","19.1337"
"96.84000","16.13494","2649.21265","19.1574"
"96.96000","16.15495","2648.74023","19.1810"
"97.08000","16.17491","2649.12915","19.2044"
"97.20000","16.19501","2649.27417","19.2279"
"97.32000","16.21494","2649.05591","19.2512"
"97.44000","16.23495","2648.87964","19.2743"
"97.56000","16.25493","2649.29224","19.2974"
"97.68000","16.27495","2649.01562","19.3201"
"97.80000","16.29495","2649.14087","19.3422"
"97.92000","16.31497","2649.26636","19.3645"
"98.04000","16.33492","2649.09692","19.3858"
"98.16000","16.35497","2649.10327","19.4050"
"98.28000","16.37498","2649.29614","19.4195"
"98.40000","16.39496","2649.16846","19.4203"
"98.52000","16.41500","2649.03760","19.4201"
"98.64000","16.43493","2648.95972","19.4209"
"98.76000","16.45497","2649.07837","19.4233"
"98.88000","16.47495","2649.31055","19.4364"
"99.00000","16.49493","2649.12231","19.4505"
"99.12000","16.51498","2649.36499","19.4635"
"99.24000","16.53498","2649.37646","19.4748"
"99.36000","16.55496","2649.29126","19.4856"
"99.48000","16.57492","2649.07007","19.4975"
"99.60000","16.59494","2648.96069","19.5070"
"99.72000","16.61491","2649.18066","19.5169"
"99.84000","16.63494","2649.37891","19.5305"
"99.96000","16.65487","2649.30322","19.5441"
"100.08000","16.67495","2649.54614","19.5563"
"100.20000","16.69496","2649.56201","19.5678"
"100.32000","16.71494","2649.28760","19.5767"
"100.44000","16.73500","2649.71289","19.5845"
"100.56000","16.75496","2649.12573","19.5905"
"100.68000","16.77498","2649.38770","19.5954"
"100.80000","16.79495","2649.75903","19.6009"
"100.92000","16.81494","2649.00708","19.6091"
"101.04000","16.83495","2649.39575","19.6182"
"101.16000","16.85500","2649.54932","19.6247"
"101.28000","16.87492","2649.45801","19.6306"
"101.40000","16.89495","2649.24097","19.6358"
"101.52000","16.91495","2649.28760","19.6384"
"101.64000","16.93497","2649.38257","19.6387"
"101.76000","16.95500","2649.48633","19.6377"
"101.88000","16.97491","2649.15723","19.6369"
"102.00000","16.99501","2649.27100","19.6363"
"102.12000","17.01496","2648.98071","19.6358"
"102.24000","17.03493","2648.92358","19.6347"
"102.36000","17.05492","2649.09082","19.6338"
"102.48000","17.07495","2648.89429","19.6313"
"102.60000","17.09492","2649.15723","19.6286"
"102.72000","17.11495","2649.32373","19.6271"
"102.84000","17.13495","2648.82690","19.6269"
"102.96000","17.15495","2649.18359","19.6270"
"103.08000","17.17499","2648.71021","19.6257"
"103.20000","17.19491","2648.86255","19.6255"
"103.32000","17.21495","2648.50171","19.6250"
"103.44000","17.23495","2648.88037","19.6252"
"103.56000","17.25496","2648.66919","19.6248"
"103.68000","17.27498","2648.97729","19.6248"
"103.80000","17.29492","2648.49536","19.6235"
"103.92000","17.31498","2648.60791","19.6227"
"104.04000","17.33496","2648.71167","19.6239"
"104.16000","17.35496","2648.45923","19.6251"
"104.28000","17.37494","2648.67041","19.6266"
"104.40000","17.39500","2648.41968","19.6276"
"104.52000","17.41493","2648.61401","19.6282"
"104.64000","17.43498","2648.36523","19.6275"
"104.76000","17.45492","2648.12891","19.6274"
"104.88000","17.47500","2648.43896","19.6278"
"105.00000","17.49496","2648.14038","19.6280"
"105.12000","17.51490","2647.96997","19.6288"
"105.24000","17.53496","2648.35962","19.6287"
"105.36000","17.55493","2648.27905","19.6296"
"105.48000","17.57495","2648.10938","19.6310"
"105.60000","17.59494","2648.31812","19.6324"
"105.72000","17.61494","2647.83740","19.6343"
"105.84000","17.63492","2647.93408","19.6361"
"105.96000","17.65495","2648.01953","19.6384"
"106.08000","17.67490","2647.69067","19.6405"
"106.20000","17.69495","2648.06860","19.6404"
"106.32000","17.71498","2647.60522","19.6396"
"106.44000","17.73491","2647.92236","19.6397"
"106.56000","17.75500","2647.68579","19.6402"
"106.68000","17.77492","2647.53931","19.6398"
"106.80000","17.79498","2647.63696","19.6393"
"106.92000","17.81494","2647.47729","19.6394"
"107.04000","17.83492","2647.31055","19.6395"
"107.16000","17.85495","2647.30737","19.6397"
"107.28000","17.87497","2647.42017","19.6396"
"107.40000","17.89498","2647.29468","19.6392"
"107.52000","17.91497","2647.08667","19.6383"
"107.64000","17.93496","2646.95435","19.6374"
"107.76000","17.95493","2647.34717","19.6369"
"107.88000","17.97500","2646.75513","19.6365"
"108.00000","17.99489","2646.69385","19.6372"
"108.12000","18.01499","2646.86963","19.6380"
"108.24000","18.03496","2646.27588","19.6390"
"108.36000","18.05495","2646.77637","19.6399"
"108.48000","18.07495","2646.43774","19.6404"
"108.60000","18.09491","2646.48901","19.6409"
"108.72000","18.11495","2646.34619","19.6420"
"108.84000","18.13494","2646.34082","19.6431"
"108.96000","18.15492","2646.27637","19.6441"
"109.08000","18.17494","2646.23486","19.6455"
"109.20000","18.19497","2646.20874","19.6477"
"109.32000","18.21495","2646.41626","19.6497"
"109.44000","18.23496","2646.09009","19.6521"
"109.56000","18.25496","2646.03149","19.6653"
"109.68000","18.27495","2646.11938","19.6745"
"109.80000","18.29499","2645.99438","19.6794"
"109.92000","18.31490","2645.55469","19.6828"
"110.04000","18.33502","2645.61108","19.6848"
"110.16000","18.35492","2645.29150","19.6857"
"110.28000","18.37493","2645.60474","19.6851"
"110.40000","18.39493","2645.43921","19.6846"
"110.52000","18.41496","2645.42944","19.6848"
"110.64000","18.43498","2645.22168","19.6853"
"110.76000","18.45498","2644.99170","19.6849"
"110.88000","18.47496","2644.91357","19.6845"
"111.00000","18.49493","2644.67627","19.6853"
"111.12000","18.51500","2644.38965","19.6860"
"111.24000","18.53490","2644.57568","19.6865"
"111.36000","18.55496","2644.24805","19.6869"
"111.48000","18.57491","2644.20557","19.6877"
"111.60000","18.59494","2644.33472","19.6887"
"111.72000","18.61493","2644.52246","19.6899"
"111.84000","18.63491","2643.78442","19.6912"
"111.96000","18.65495","2643.91675","19.6933"
"112.08000","18.67496","2644.25586","19.6963"
"112.20000","18.69497","2643.90942","19.7092"
"112.32000","18.71494","2643.44263","19.7172"
"112.44000","18.73499","2643.29565","19.7218"
"112.56000","18.75494","2643.67114","19.7244"
"112.68000","18.77498","2643.30127","19.7253"
"112.80000","18.79494","2643.25391","19.7263"
"112.92000","18.81496","2643.12036","19.7268"
"113.04000","18.83498","2643.00293","19.7271"
"113.16000","18.85491","2643.20117","19.7271"
"113.28000","18.87500","2643.06177","19.7271"
"113.40000","18.89497","2642.86890","19.7266"
"113.52000","18.91502","2642.30664","19.7259"
"113.64000","18.93494","2642.37866","19.7258"
"113.76000","18.95495","2642.20337","19.7260"
"113.88000","18.97495","2642.25708","19.7262"
"114.00000","18.99495","2641.95117","19.7267"
"114.12000","19.01491","2641.85254","19.7273"
"114.24000","19.03493","2641.96606","19.7280"
"114.36000","19.05499","2641.60840","19.7289"
"114.48000","19.07492","2641.61328","19.7301"
"114.60000","19.09500","2641.40820","19.7315"
"114.72000","19.11492","2641.09399","19.7327"
"114.84000","19.13495","2641.11279","19.7337"
"114.96000","19.15493","2641.15308","19.7347"
"115.08000","19.17494","2640.78613","19.7359"
"115.20000","19.19494","2640.63013","19.7374"
"115.32000","19.21498","2640.87524","19.7412"
"115.44000","19.23495","2640.06372","19.7497"
"115.56000","19.25496","2640.50317","19.7551"
"115.68000","19.27497","2640.12915","19.7581"
"115.80000","19.29495","2640.33594","19.7602"
"115.92000","19.31499","2639.79663","19.7606"
"116.04000","19.33490","2639.82983","19.7601"
"116.16000","19.35497","2639.75830","19.7603"
"116.28000","19.37498","2639.60791","19.7610"
"116.40000","19.39497","2639.39185","19.7618"
"116.52000","19.41499","2639.05322","19.7625"
"116.64000","19.43493","2639.09033","19.7631"
"116.76000","19.45499","2638.74658","19.7637"
"116.88000","19.47493","2638.58594","19.7641"
"117.00000","19.49495","2638.33569","19.7646"
"117.12000","19.51494","2638.13232","19.7653"
"117.24000","19.53499","2637.92090","19.7661"
"117.36000","19.55492","2637.70996","19.7662"
"117.48000","19.57495","2637.57446","19.7658"
"117.60000","19.59491","2637.40039","19.7658"
"117.72000","19.61494","2637.38208","19.7663"
"117.84000","19.63495","2637.22827","19.7670"
"117.96000","19.65487","2636.99341","19.7674"
"118.08000","19.67498","2636.94312","19.7676"
"118.20000","19.69494","2636.55347","19.7678"
"118.32000","19.71494","2636.14673","19.7676"
"118.44000","19.73495","2636.14331","19.7674"
"118.56000","19.75498","2636.01758","19.7676"
"118.68000","19.77497","2635.46362","19.7678"
"118.80000","19.79496","2635.58350","19.7674"
"118.92000","19.81494","2635.16821","19.7662"
"119.04000","19.83496","2634.98657","19.7658"
"119.16000","19.85499","2634.44702","19.7655"
"119.28000","19.87489","2634.55640","19.7649"
"119.40000","19.89498","2634.10815","19.7647"
"119.52000","19.91492","2633.81543","19.7645"
"119.64000","19.93498","2633.69336","19.7645"
"119.76000","19.95496","2633.46265","19.7644"
"119.88000","19.97494","2632.94995","19.7644"
"120.00000","19.99498","2632.81714","19.7647"
"120.12000","20.01497","2632.29492","19.7652"
"120.24000","20.03494","2632.07617","19.7656"
"120.36000","20.05491","2631.60400","19.7658"
"120.48000","20.07496","2631.28979","19.7665"
"120.60000","20.09491","2631.21338","19.7673"
"120.72000","20.11495","2631.02051","19.7680"
"120.84000","20.13489","2630.61182","19.7688"
"120.96000","20.15498","2630.13379","19.7698"
"121.08000","20.17496","2629.63037","19.7707"
"121.20000","20.19492","2629.01196","19.7717"
"121.32000","20.21497","2629.10205","19.7728"
"121.44000","20.23495","2628.89966","19.7740"
"121.56000","20.25497","2627.77417","19.7749"
"121.68000","20.27495","2627.75024","19.7758"
"121.80000","20.29495","2627.15576","19.7765"
"121.92000","20.31494","2626.96021","19.7781"
"122.04000","20.33498","2625.83569","19.7823"
"122.16000","20.35493","2625.72363","19.7887"
"122.28000","20.37497","2625.26660","19.7929"
"122.40000","20.39499","2624.54370","19.7956"
"122.52000","20.41496","2623.95386","19.7974"
"122.64000","20.43498","2623.19604","19.7988"
"122.76000","20.45491","2622.62988","19.7996"
"122.88000","20.47498","2621.79346","19.8002"
"123.00000","20.49495","2621.28418","19.8006"
"123.12000","20.51492","2619.95508","19.8010"
"123.24000","20.53494","2619.64307","19.8010"
"123.36000","20.55495","2618.64673","19.8009"
"123.48000","20.57492","2617.69897","19.8008"
"123.60000","20.59494","2616.77368","19.8005"
"123.72000","20.61493","2615.76343","19.8002"
"123.84000","20.63490","2614.64038","19.8002"
"123.96000","20.65497","2613.40698","19.7998"
"124.08000","20.67488","2612.27612","19.7997"
"124.20000","20.69498","2611.11670","19.7994"
"124.32000","20.71496","2609.66260","19.7992"
"124.44000","20.73496","2608.44702","19.7992"
"124.56000","20.75498","2606.84497","19.7990"
"124.68000","20.77493","2605.47925","19.7990"
"124.80000","20.79499","2603.59521","19.7989"
"124.92000","20.81498","2601.79980","19.7989"
"125.04000","20.83496","2599.32031","19.7989"
"125.16000","20.85493","2596.99756","19.7989"
"125.28000","20.87500","2594.67407","19.7989"
"125.40000","20.89495","2592.28003","19.7989"
"125.52000","20.91498","2588.92578","19.7989"
"125.64000","20.93494","2585.43237","19.7989"
"125.76000","20.95497","2581.97266","19.7990"
"125.88000","20.97499","2577.10620","19.7989"
"126.00000","20.99492","2571.95142","19.7989"
"126.12000","21.01500","2566.03540","19.7990"
"126.24000","21.03496","2559.09790","19.7990"
"126.36000","21.05496","2550.39746","19.7991"
"126.48000","21.07493","2540.57349","19.7991"
"126.60000","21.09491","2528.65259","19.7991"
"126.72000","21.11493","2514.76904","19.7993"
"126.84000","21.13494","2497.94507","19.7994"
"126.96000","21.15492","2477.71362","19.7994"
"127.08000","21.17493","2454.71533","19.7994"
"127.20000","21.19500","2427.29688","19.7994"
"127.32000","21.21494","2395.13062","19.7993"
"127.44000","21.23502","2356.89429","19.7992"
"127.56000","21.25495","2312.72827","19.7989"
"127.68000","21.27497","2259.77344","19.7985"
"127.80000","21.29496","2194.55371","19.7979"
"127.92000","21.31496","2111.62183","19.7971"
"128.04000","21.33503","1999.58569","19.7956"
"128.16000","21.35501","1817.06665","19.7934"
"128.22100","21.36534","1124.89856","19.8155"