File: mechanics_and_materials/materials_practical_data/instrondata_machine3_15sep2022_2pm/all_material_instron_data/LDPE_cold_down.csv
Time measurement,Displacement,Primary force measurement,Strain 1
(s),(mm),(N),(%)
"0.00000","0.00000","-0.58207","-0.0015"
"0.12000","0.01249","-0.46095","0.0030"
"0.24000","0.03465","0.23654","0.0170"
"0.36000","0.05474","1.49744","0.0283"
"0.48000","0.07478","2.19000","0.0401"
"0.60000","0.09483","3.22296","0.0545"
"0.72000","0.11479","3.71403","0.0667"
"0.84000","0.13482","4.66733","0.0789"
"0.96000","0.15473","5.28686","0.0925"
"1.08000","0.17477","6.04533","0.1064"
"1.20000","0.19477","7.05266","0.1190"
"1.32000","0.21474","7.69146","0.1325"
"1.44000","0.23476","8.82585","0.1478"
"1.56000","0.25478","9.32083","0.1591"
"1.68000","0.27478","10.48444","0.1743"
"1.80000","0.29477","10.92374","0.1876"
"1.92000","0.31479","11.68833","0.2012"
"2.04000","0.33479","12.81851","0.2157"
"2.16000","0.35482","13.43865","0.2302"
"2.28000","0.37472","14.14232","0.2437"
"2.40000","0.39479","14.79263","0.2585"
"2.52000","0.41480","15.84775","0.2724"
"2.64000","0.43478","16.69124","0.2865"
"2.76000","0.45483","17.61647","0.3013"
"2.88000","0.47477","18.05661","0.3149"
"3.00000","0.49481","19.03679","0.3301"
"3.12000","0.51477","19.69178","0.3439"
"3.24000","0.53477","20.56311","0.3588"
"3.36000","0.55479","21.57282","0.3729"
"3.48000","0.57481","22.27993","0.3877"
"3.60000","0.59478","23.05199","0.4017"
"3.72000","0.61479","24.03682","0.4170"
"3.84000","0.63474","24.71271","0.4307"
"3.96000","0.65477","25.43062","0.4458"
"4.08000","0.67480","25.92466","0.4597"
"4.20000","0.69471","26.99012","0.4749"
"4.32000","0.71477","28.05636","0.4887"
"4.44000","0.73475","28.61630","0.5043"
"4.56000","0.75475","29.13620","0.5178"
"4.68000","0.77476","30.02422","0.5335"
"4.80000","0.79479","30.87658","0.5473"
"4.92000","0.81479","31.73118","0.5620"
"5.04000","0.83478","32.45726","0.5772"
"5.16000","0.85478","33.39159","0.5911"
"5.28000","0.87477","34.06325","0.6062"
"5.40000","0.89481","34.86576","0.6204"
"5.52000","0.91474","35.48125","0.6352"
"5.64000","0.93480","36.36951","0.6500"
"5.76000","0.95475","37.04553","0.6641"
"5.88000","0.97480","38.24871","0.6790"
"6.00000","0.99480","38.61856","0.6937"
"6.12000","1.01475","39.58937","0.7084"
"6.24000","1.03482","40.21642","0.7228"
"6.36000","1.05479","41.12294","0.7372"
"6.48000","1.07480","42.07370","0.7523"
"6.60000","1.09477","42.67719","0.7665"
"6.72000","1.11479","43.46521","0.7809"
"6.84000","1.13473","43.86911","0.7958"
"6.96000","1.15476","45.14140","0.8102"
"7.08000","1.17472","45.57395","0.8253"
"7.20000","1.19477","46.55827","0.8400"
"7.32000","1.21480","47.16105","0.8545"
"7.44000","1.23473","48.17451","0.8684"
"7.56000","1.25480","48.99237","0.8833"
"7.68000","1.27477","49.46318","0.8975"
"7.80000","1.29479","50.35970","0.9125"
"7.92000","1.31477","51.04973","0.9267"
"8.04000","1.33479","52.02243","0.9419"
"8.16000","1.35476","52.45842","0.9557"
"8.28000","1.37481","53.45044","0.9709"
"8.40000","1.39476","53.92787","0.9847"
"8.52000","1.41478","54.71301","0.9998"
"8.64000","1.43481","55.35564","1.0138"
"8.76000","1.45477","56.38503","1.0285"
"8.88000","1.47481","56.87381","1.0425"
"9.00000","1.49475","57.81759","1.0571"
"9.12000","1.51483","58.03024","1.0716"
"9.24000","1.53478","59.26780","1.0861"
"9.36000","1.55475","59.76068","1.1007"
"9.48000","1.57478","60.51925","1.1151"
"9.60000","1.59479","61.20677","1.1296"
"9.72000","1.61478","62.27300","1.1440"
"9.84000","1.63476","62.84305","1.1585"
"9.96000","1.65478","63.37810","1.1727"
"10.08000","1.67473","64.32549","1.1871"
"10.20000","1.69480","64.96382","1.2013"
"10.32000","1.71468","65.53596","1.2159"
"10.44000","1.73479","66.25754","1.2299"
"10.56000","1.75477","66.99837","1.2443"
"10.68000","1.77477","67.37778","1.2583"
"10.80000","1.79479","68.47882","1.2727"
"10.92000","1.81476","69.17573","1.2869"
"11.04000","1.83482","69.73644","1.3014"
"11.16000","1.85479","70.57941","1.3158"
"11.28000","1.87478","71.19074","1.3302"
"11.40000","1.89475","71.84860","1.3443"
"11.52000","1.91482","72.12019","1.3583"
"11.64000","1.93477","73.15522","1.3727"
"11.76000","1.95481","73.84740","1.3864"
"11.88000","1.97478","74.31918","1.4007"
"12.00000","1.99478","75.12595","1.4144"
"12.12000","2.01481","75.89185","1.4294"
"12.24000","2.03475","76.72301","1.4430"
"12.36000","2.05483","77.31894","1.4575"
"12.48000","2.07478","78.12952","1.4712"
"12.60000","2.09479","78.52517","1.4855"
"12.72000","2.11477","79.25278","1.4995"
"12.84000","2.13475","79.81977","1.5135"
"12.96000","2.15476","80.54481","1.5274"
"13.08000","2.17477","81.29485","1.5415"
"13.20000","2.19476","81.84943","1.5555"
"13.32000","2.21475","82.46185","1.5701"
"13.44000","2.23481","82.92258","1.5833"
"13.56000","2.25474","83.98991","1.5974"
"13.68000","2.27481","84.05538","1.6113"
"13.80000","2.29475","85.18155","1.6257"
"13.92000","2.31479","86.08276","1.6395"
"14.04000","2.33479","86.83090","1.6533"
"14.16000","2.35474","86.99429","1.6673"
"14.28000","2.37483","87.35076","1.6811"
"14.40000","2.39478","88.48113","1.6952"
"14.52000","2.41478","89.06712","1.7089"
"14.64000","2.43478","89.76945","1.7231"
"14.76000","2.45479","90.31459","1.7364"
"14.88000","2.47477","91.00929","1.7507"
"15.00000","2.49479","91.45797","1.7647"
"15.12000","2.51472","92.38287","1.7782"
"15.24000","2.53480","92.79855","1.7918"
"15.36000","2.55481","93.42886","1.8058"
"15.48000","2.57477","94.01049","1.8198"
"15.60000","2.59482","94.60992","1.8332"
"15.72000","2.61475","95.41990","1.8472"
"15.84000","2.63478","96.25700","1.8607"
"15.96000","2.65471","96.53681","1.8748"
"16.08000","2.67475","97.32655","1.8885"
"16.20000","2.69476","97.85124","1.9021"
"16.32000","2.71479","98.57357","1.9160"
"16.44000","2.73476","99.16251","1.9297"
"16.56000","2.75476","99.87153","1.9432"
"16.68000","2.77478","100.39535","1.9568"
"16.80000","2.79479","101.28792","1.9706"
"16.92000","2.81484","101.71584","1.9841"
"17.04000","2.83474","102.33508","1.9976"
"17.16000","2.85483","103.12672","2.0113"
"17.28000","2.87479","103.47318","2.0249"
"17.40000","2.89475","104.34120","2.0386"
"17.52000","2.91477","104.64915","2.0523"
"17.64000","2.93478","105.34896","2.0657"
"17.76000","2.95480","105.85368","2.0794"
"17.88000","2.97478","106.51435","2.0926"
"18.00000","2.99481","107.23807","2.1062"
"18.12000","3.01479","107.53683","2.1197"
"18.24000","3.03482","108.22085","2.1332"
"18.36000","3.05471","108.87615","2.1466"
"18.48000","3.07480","109.42591","2.1603"
"18.60000","3.09479","110.06750","2.1737"
"18.72000","3.11477","110.66324","2.1873"
"18.84000","3.13481","111.19460","2.2010"
"18.96000","3.15475","111.71467","2.2144"
"19.08000","3.17480","112.33115","2.2279"
"19.20000","3.19475","112.96204","2.2411"
"19.32000","3.21475","113.45466","2.2544"
"19.44000","3.23475","114.00912","2.2677"
"19.56000","3.25478","114.71368","2.2813"
"19.68000","3.27475","115.37889","2.2943"
"19.80000","3.29480","115.41525","2.3080"
"19.92000","3.31476","116.62926","2.3210"
"20.04000","3.33481","116.96900","2.3346"
"20.16000","3.35484","117.46684","2.3478"
"20.28000","3.37473","118.07673","2.3611"
"20.40000","3.39482","118.58287","2.3744"
"20.52000","3.41478","119.08596","2.3876"
"20.64000","3.43480","119.73208","2.4010"
"20.76000","3.45479","120.21449","2.4140"
"20.88000","3.47479","120.66296","2.4275"
"21.00000","3.49477","121.18484","2.4404"
"21.12000","3.51481","121.72982","2.4539"
"21.24000","3.53477","122.39610","2.4670"
"21.36000","3.55479","122.83069","2.4803"
"21.48000","3.57483","123.51922","2.4936"
"21.60000","3.59476","124.06608","2.5067"
"21.72000","3.61480","124.48029","2.5199"
"21.84000","3.63474","125.16185","2.5329"
"21.96000","3.65479","125.77647","2.5462"
"22.08000","3.67474","126.17387","2.5593"
"22.20000","3.69471","126.67498","2.5725"
"22.32000","3.71478","127.22113","2.5856"
"22.44000","3.73476","127.74138","2.5986"
"22.56000","3.75477","128.40652","2.6117"
"22.68000","3.77476","129.08018","2.6247"
"22.80000","3.79480","129.44040","2.6378"
"22.92000","3.81477","130.35310","2.6508"
"23.04000","3.83480","130.63667","2.6638"
"23.16000","3.85471","131.44788","2.6765"
"23.28000","3.87481","131.64171","2.6900"
"23.40000","3.89480","132.36401","2.7027"
"23.52000","3.91476","132.68170","2.7157"
"23.64000","3.93480","133.27650","2.7288"
"23.76000","3.95475","133.79846","2.7418"
"23.88000","3.97484","134.11835","2.7546"
"24.00000","3.99479","134.94827","2.7676"
"24.12000","4.01477","135.62981","2.7807"
"24.24000","4.03476","135.92830","2.7935"
"24.36000","4.05484","136.50941","2.8064"
"24.48000","4.07478","136.87512","2.8192"
"24.60000","4.09478","137.40775","2.8321"
"24.72000","4.11478","138.10159","2.8449"
"24.84000","4.13475","138.62158","2.8579"
"24.96000","4.15480","139.18138","2.8707"
"25.08000","4.17472","139.74617","2.8834"
"25.20000","4.19481","140.60912","2.8963"
"25.32000","4.21477","140.84474","2.9093"
"25.44000","4.23474","141.40848","2.9219"
"25.56000","4.25475","141.95039","2.9350"
"25.68000","4.27476","142.47156","2.9476"
"25.80000","4.29479","142.56445","2.9603"
"25.92000","4.31480","143.39627","2.9732"
"26.04000","4.33480","143.98412","2.9861"
"26.16000","4.35479","144.45668","2.9986"
"26.28000","4.37482","144.92128","3.0116"
"26.40000","4.39474","145.61247","3.0242"
"26.52000","4.41481","146.14763","3.0369"
"26.64000","4.43476","146.46497","3.0494"
"26.76000","4.45480","146.93156","3.0623"
"26.88000","4.47479","147.68188","3.0750"
"27.00000","4.49476","147.99934","3.0875"
"27.12000","4.51483","148.87524","3.1001"
"27.24000","4.53476","148.98610","3.1126"
"27.36000","4.55477","149.83287","3.1254"
"27.48000","4.57475","150.20197","3.1381"
"27.60000","4.59480","150.69763","3.1508"
"27.72000","4.61476","150.95567","3.1632"
"27.84000","4.63478","151.80087","3.1759"
"27.96000","4.65477","152.03477","3.1884"
"28.08000","4.67475","152.50281","3.2008"
"28.20000","4.69478","153.28006","3.2132"
"28.32000","4.71472","153.48289","3.2256"
"28.44000","4.73478","154.18974","3.2383"
"28.56000","4.75475","154.67863","3.2507"
"28.68000","4.77478","155.08299","3.2634"
"28.80000","4.79477","155.56772","3.2756"
"28.92000","4.81478","156.25453","3.2884"
"29.04000","4.83478","156.54527","3.3006"
"29.16000","4.85479","156.72353","3.3133"
"29.28000","4.87476","157.50491","3.3254"
"29.40000","4.89477","157.81642","3.3381"
"29.52000","4.91483","158.68980","3.3505"
"29.64000","4.93478","158.98001","3.3629"
"29.76000","4.95483","159.48402","3.3751"
"29.88000","4.97476","159.74956","3.3877"
"30.00000","4.99478","160.30496","3.4000"
"30.12000","5.01478","160.92972","3.4124"
"30.24000","5.03477","161.37489","3.4249"
"30.36000","5.05481","161.92303","3.4375"
"30.48000","5.07482","162.14169","3.4500"
"30.60000","5.09480","162.67427","3.4622"
"30.72000","5.11477","163.44151","3.4746"
"30.84000","5.13478","163.86649","3.4869"
"30.96000","5.15474","164.05827","3.4993"
"31.08000","5.17478","164.66711","3.5115"
"31.20000","5.19471","165.03427","3.5239"
"31.32000","5.21478","165.86337","3.5362"
"31.44000","5.23477","165.81885","3.5488"
"31.56000","5.25477","166.67795","3.5609"
"31.68000","5.27481","167.14410","3.5734"
"31.80000","5.29477","167.52823","3.5857"
"31.92000","5.31482","168.32112","3.5979"
"32.04000","5.33477","168.78073","3.6102"
"32.16000","5.35477","168.83687","3.6225"
"32.28000","5.37479","169.47026","3.6346"
"32.40000","5.39481","169.90898","3.6470"
"32.52000","5.41477","170.74855","3.6593"
"32.64000","5.43478","170.91963","3.6716"
"32.76000","5.45477","171.46326","3.6840"
"32.88000","5.47480","171.88153","3.6963"
"33.00000","5.49483","172.33043","3.7084"
"33.12000","5.51473","173.10500","3.7208"
"33.24000","5.53482","173.08829","3.7330"
"33.36000","5.55479","173.77130","3.7452"
"33.48000","5.57477","174.13760","3.7574"
"33.60000","5.59478","174.62848","3.7697"
"33.72000","5.61478","175.08775","3.7820"
"33.84000","5.63478","175.62086","3.7941"
"33.96000","5.65478","176.40154","3.8064"
"34.08000","5.67475","176.40688","3.8185"
"34.20000","5.69477","177.20461","3.8308"
"34.32000","5.71480","177.82611","3.8432"
"34.44000","5.73472","178.23186","3.8553"
"34.56000","5.75478","178.58070","3.8678"
"34.68000","5.77475","178.99184","3.8798"
"34.80000","5.79477","179.86505","3.8920"
"34.92000","5.81479","179.71375","3.9041"
"35.04000","5.83476","180.74998","3.9163"
"35.16000","5.85481","180.88708","3.9284"
"35.28000","5.87479","181.58698","3.9408"
"35.40000","5.89477","181.87663","3.9529"
"35.52000","5.91476","182.36018","3.9653"
"35.64000","5.93480","182.62381","3.9775"
"35.76000","5.95479","183.04185","3.9896"
"35.88000","5.97480","183.73254","4.0017"
"36.00000","5.99475","184.15033","4.0137"
"36.12000","6.01481","184.67892","4.0259"
"36.24000","6.03479","185.49878","4.0378"
"36.36000","6.05473","185.52733","4.0502"
"36.48000","6.07482","185.91017","4.0623"
"36.60000","6.09477","186.56638","4.0747"
"36.72000","6.11478","186.96204","4.0868"
"36.84000","6.13477","187.65610","4.0990"
"36.96000","6.15477","188.12108","4.1113"
"37.08000","6.17475","188.52000","4.1234"
"37.20000","6.19478","188.94789","4.1353"
"37.32000","6.21475","189.43225","4.1477"
"37.44000","6.23476","190.03058","4.1598"
"37.56000","6.25481","190.38603","4.1719"
"37.68000","6.27477","190.61606","4.1841"
"37.80000","6.29478","191.42888","4.1963"
"37.92000","6.31476","191.51311","4.2083"
"38.04000","6.33479","192.29033","4.2207"
"38.16000","6.35481","192.34685","4.2329"
"38.28000","6.37476","192.98317","4.2451"
"38.40000","6.39479","193.40833","4.2569"
"38.52000","6.41480","194.39476","4.2692"
"38.64000","6.43478","194.58344","4.2811"
"38.76000","6.45479","195.12679","4.2933"
"38.88000","6.47479","195.55934","4.3055"
"39.00000","6.49474","196.02931","4.3176"
"39.12000","6.51479","196.59293","4.3296"
"39.24000","6.53472","197.23892","4.3419"
"39.36000","6.55482","197.37640","4.3541"
"39.48000","6.57481","197.87077","4.3662"
"39.60000","6.59477","197.87138","4.3782"
"39.72000","6.61482","198.89539","4.3902"
"39.84000","6.63475","199.49391","4.4024"
"39.96000","6.65478","199.68715","4.4144"
"40.08000","6.67475","200.34546","4.4266"
"40.20000","6.69474","200.92307","4.4385"
"40.32000","6.71472","200.74879","4.4513"
"40.44000","6.73480","201.58670","4.4627"
"40.56000","6.75476","201.80418","4.4748"
"40.68000","6.77478","202.40497","4.4870"
"40.80000","6.79478","203.20784","4.4993"
"40.92000","6.81480","203.11572","4.5112"
"41.04000","6.83482","203.89964","4.5234"
"41.16000","6.85475","204.33569","4.5353"
"41.28000","6.87483","204.82289","4.5475"
"41.40000","6.89476","205.23222","4.5595"
"41.52000","6.91479","205.43344","4.5716"
"41.64000","6.93475","206.13605","4.5836"
"41.76000","6.95477","206.34360","4.5958"
"41.88000","6.97479","207.07396","4.6078"
"42.00000","6.99482","207.50758","4.6200"
"42.12000","7.01478","208.03600","4.6320"
"42.24000","7.03478","208.59599","4.6440"
"42.36000","7.05484","208.88991","4.6561"
"42.48000","7.07476","209.23933","4.6681"
"42.60000","7.09479","209.93370","4.6802"
"42.72000","7.11474","210.15930","4.6921"
"42.84000","7.13478","210.85678","4.7041"
"42.96000","7.15477","210.97858","4.7163"
"43.08000","7.17473","211.37791","4.7286"
"43.20000","7.19482","212.07689","4.7404"
"43.32000","7.21479","212.63724","4.7523"
"43.44000","7.23478","212.47263","4.7645"
"43.56000","7.25476","213.13280","4.7766"
"43.68000","7.27478","213.81764","4.7885"
"43.80000","7.29477","214.29802","4.8004"
"43.92000","7.31480","214.87601","4.8125"
"44.04000","7.33476","215.20874","4.8245"
"44.16000","7.35481","215.78819","4.8365"
"44.28000","7.37479","216.14542","4.8486"
"44.40000","7.39476","216.39224","4.8607"
"44.52000","7.41482","216.71558","4.8727"
"44.64000","7.43479","217.60497","4.8846"
"44.76000","7.45481","217.70963","4.8967"
"44.88000","7.47478","218.45686","4.9088"
"45.00000","7.49477","218.91385","4.9207"
"45.12000","7.51478","219.10915","4.9324"
"45.24000","7.53478","219.58736","4.9447"
"45.36000","7.55477","220.00438","4.9566"
"45.48000","7.57478","220.49872","4.9688"
"45.60000","7.59482","220.82793","4.9803"
"45.72000","7.61477","221.48254","4.9925"
"45.84000","7.63483","221.82625","5.0047"
"45.96000","7.65475","222.33974","5.0163"
"46.08000","7.67479","223.09998","5.0282"
"46.20000","7.69476","223.19521","5.0399"
"46.32000","7.71474","223.85268","5.0521"
"46.44000","7.73477","224.00070","5.0640"
"46.56000","7.75476","224.57329","5.0755"
"46.68000","7.77479","225.00793","5.0873"
"46.80000","7.79476","225.37054","5.0995"
"46.92000","7.81481","226.04834","5.1115"
"47.04000","7.83479","226.19574","5.1231"
"47.16000","7.85482","227.11462","5.1351"
"47.28000","7.87473","227.10725","5.1467"
"47.40000","7.89477","227.89601","5.1590"
"47.52000","7.91479","228.06750","5.1707"
"47.64000","7.93479","228.84381","5.1826"
"47.76000","7.95481","229.13211","5.1943"
"47.88000","7.97477","229.74655","5.2064"
"48.00000","7.99481","230.37402","5.2182"
"48.12000","8.01476","230.74921","5.2301"
"48.24000","8.03475","230.99741","5.2419"
"48.36000","8.05476","231.62729","5.2539"
"48.48000","8.07482","231.74637","5.2659"
"48.60000","8.09477","232.40742","5.2776"
"48.72000","8.11479","232.81059","5.2894"
"48.84000","8.13475","233.54236","5.3010"
"48.96000","8.15476","233.80870","5.3129"
"49.08000","8.17480","234.43115","5.3247"
"49.20000","8.19471","234.63359","5.3363"
"49.32000","8.21480","235.31679","5.3480"
"49.44000","8.23476","235.70547","5.3600"
"49.56000","8.25477","236.34404","5.3720"
"49.68000","8.27477","236.84015","5.3839"
"49.80000","8.29480","237.07787","5.3956"
"49.92000","8.31479","237.58427","5.4074"
"50.04000","8.33479","238.10263","5.4191"
"50.16000","8.35479","238.43182","5.4309"
"50.28000","8.37479","238.96152","5.4425"
"50.40000","8.39482","239.36893","5.4543"
"50.52000","8.41474","239.84665","5.4663"
"50.64000","8.43480","240.42746","5.4780"
"50.76000","8.45477","240.94847","5.4898"
"50.88000","8.47480","241.01378","5.5014"
"51.00000","8.49479","241.37361","5.5133"
"51.12000","8.51476","242.02731","5.5252"
"51.24000","8.53480","242.53146","5.5368"
"51.36000","8.55480","243.14877","5.5487"
"51.48000","8.57480","243.30525","5.5604"
"51.60000","8.59475","243.74617","5.5723"
"51.72000","8.61478","244.06898","5.5841"
"51.84000","8.63473","244.90099","5.5958"
"51.96000","8.65478","245.05557","5.6076"
"52.08000","8.67472","245.64482","5.6195"
"52.20000","8.69479","246.47009","5.6314"
"52.32000","8.71482","246.94019","5.6432"
"52.44000","8.73472","247.21925","5.6547"
"52.56000","8.75480","247.83862","5.6666"
"52.68000","8.77474","248.14412","5.6785"
"52.80000","8.79482","248.37996","5.6902"
"52.92000","8.81475","248.96701","5.7019"
"53.04000","8.83477","249.24756","5.7138"
"53.16000","8.85479","250.17194","5.7256"
"53.28000","8.87480","250.60127","5.7376"
"53.40000","8.89477","250.93089","5.7493"
"53.52000","8.91478","251.39465","5.7612"
"53.64000","8.93482","251.22676","5.7729"
"53.76000","8.95478","252.25656","5.7847"
"53.88000","8.97485","252.34511","5.7964"
"54.00000","8.99472","252.92177","5.8082"
"54.12000","9.01483","253.22476","5.8199"
"54.24000","9.03477","254.04428","5.8317"
"54.36000","9.05473","254.56631","5.8434"
"54.48000","9.07477","254.87268","5.8554"
"54.60000","9.09477","255.28297","5.8672"
"54.72000","9.11479","255.59052","5.8790"
"54.84000","9.13478","256.14401","5.8907"
"54.96000","9.15480","256.72745","5.9025"
"55.08000","9.17476","257.34164","5.9142"
"55.20000","9.19480","257.50925","5.9261"
"55.32000","9.21470","258.07233","5.9376"
"55.44000","9.23478","258.49579","5.9494"
"55.56000","9.25476","259.11765","5.9610"
"55.68000","9.27479","259.77835","5.9730"
"55.80000","9.29480","259.91202","5.9846"
"55.92000","9.31476","260.28955","5.9965"
"56.04000","9.33481","260.92819","6.0081"
"56.16000","9.35479","261.32388","6.0202"
"56.28000","9.37477","261.57690","6.0318"
"56.40000","9.39474","262.42554","6.0436"
"56.52000","9.41483","262.56458","6.0552"
"56.64000","9.43478","263.15045","6.0669"
"56.76000","9.45480","263.39255","6.0785"
"56.88000","9.47479","264.19016","6.0904"
"57.00000","9.49477","264.52136","6.1020"
"57.12000","9.51479","264.91959","6.1139"
"57.24000","9.53473","265.32834","6.1255"
"57.36000","9.55484","265.76434","6.1374"
"57.48000","9.57480","265.98773","6.1492"
"57.60000","9.59481","266.87662","6.1610"
"57.72000","9.61477","267.28265","6.1727"
"57.84000","9.63476","267.56729","6.1844"
"57.96000","9.65474","268.01596","6.1961"
"58.08000","9.67476","268.54834","6.2080"
"58.20000","9.69473","269.06250","6.2196"
"58.32000","9.71476","269.34570","6.2314"
"58.44000","9.73482","270.13199","6.2431"
"58.56000","9.75474","270.19022","6.2548"
"58.68000","9.77481","270.80029","6.2667"
"58.80000","9.79474","271.36035","6.2785"
"58.92000","9.81481","271.90292","6.2901"
"59.04000","9.83477","272.37311","6.3018"
"59.16000","9.85475","272.96698","6.3135"
"59.28000","9.87481","273.34009","6.3253"
"59.40000","9.89480","273.64038","6.3369"
"59.52000","9.91478","274.28119","6.3485"
"59.64000","9.93477","274.58215","6.3602"
"59.76000","9.95479","275.03238","6.3720"
"59.88000","9.97478","275.51154","6.3838"
"60.00000","9.99481","275.78455","6.3958"
"60.12000","10.01473","276.46045","6.4073"
"60.24000","10.03482","277.03049","6.4190"
"60.36000","10.05481","277.39233","6.4306"
"60.48000","10.07477","277.68234","6.4422"
"60.60000","10.09482","278.15027","6.4537"
"60.72000","10.11474","278.82162","6.4655"
"60.84000","10.13480","279.23492","6.4772"
"60.96000","10.15474","279.72095","6.4890"
"61.08000","10.17475","279.89865","6.5006"
"61.20000","10.19477","280.39841","6.5122"
"61.32000","10.21480","281.00897","6.5240"
"61.44000","10.23475","281.34988","6.5355"
"61.56000","10.25477","281.47137","6.5472"
"61.68000","10.27479","282.48663","6.5589"
"61.80000","10.29477","282.92874","6.5705"
"61.92000","10.31484","283.06033","6.5822"
"62.04000","10.33473","283.58408","6.5937"
"62.16000","10.35481","283.94131","6.6053"
"62.28000","10.37477","284.33859","6.6170"
"62.40000","10.39475","284.88596","6.6289"
"62.52000","10.41478","285.48724","6.6405"
"62.64000","10.43479","285.86301","6.6520"
"62.76000","10.45480","286.19781","6.6636"
"62.88000","10.47479","286.76816","6.6755"
"63.00000","10.49479","287.09775","6.6869"
"63.12000","10.51479","287.48602","6.6985"
"63.24000","10.53481","288.00861","6.7101"
"63.36000","10.55471","288.70529","6.7218"
"63.48000","10.57478","289.19385","6.7335"
"63.60000","10.59476","289.52252","6.7451"
"63.72000","10.61477","289.70331","6.7568"
"63.84000","10.63480","290.24399","6.7685"
"63.96000","10.65477","290.69629","6.7802"
"64.08000","10.67478","291.27573","6.7919"
"64.20000","10.69475","291.55530","6.8034"
"64.32000","10.71475","291.96048","6.8149"
"64.44000","10.73473","292.62177","6.8265"
"64.56000","10.75478","293.26389","6.8381"
"64.68000","10.77477","293.46277","6.8497"
"64.80000","10.79478","294.03046","6.8615"
"64.92000","10.81477","294.22531","6.8731"
"65.04000","10.83481","295.10037","6.8847"
"65.16000","10.85483","295.25049","6.8962"
"65.28000","10.87474","295.96790","6.9058"
"65.40000","10.89480","296.40848","6.9143"
"65.52000","10.91478","296.81433","6.9258"
"65.64000","10.93480","297.20871","6.9363"
"65.76000","10.95478","297.59360","6.9466"
"65.88000","10.97477","298.07181","6.9570"
"66.00000","10.99477","298.47287","6.9671"
"66.12000","11.01477","299.07791","6.9762"
"66.24000","11.03479","299.60699","6.9846"
"66.36000","11.05480","300.13275","6.9989"
"66.48000","11.07485","300.61697","7.0097"
"66.60000","11.09476","300.96909","7.0203"
"66.72000","11.11481","301.20337","7.0311"
"66.84000","11.13472","301.56897","7.0416"
"66.96000","11.15477","302.25412","7.0523"
"67.08000","11.17476","302.67801","7.0628"
"67.20000","11.19474","303.63287","7.0735"
"67.32000","11.21478","303.56430","7.0841"
"67.44000","11.23479","304.48959","7.0948"
"67.56000","11.25476","304.69574","7.1052"
"67.68000","11.27477","305.31100","7.1160"
"67.80000","11.29480","305.64117","7.1266"
"67.92000","11.31476","306.00693","7.1373"
"68.04000","11.33481","306.61496","7.1480"
"68.16000","11.35472","307.07465","7.1586"
"68.28000","11.37480","307.67975","7.1693"
"68.40000","11.39480","307.79523","7.1800"
"68.52000","11.41477","308.51071","7.1907"
"68.64000","11.43481","309.14682","7.2013"
"68.76000","11.45476","309.33908","7.2121"
"68.88000","11.47482","310.01520","7.2227"
"69.00000","11.49479","310.05621","7.2334"
"69.12000","11.51477","310.71072","7.2441"
"69.24000","11.53475","311.12103","7.2548"
"69.36000","11.55483","311.61615","7.2653"
"69.48000","11.57476","312.29980","7.2760"
"69.60000","11.59480","312.62238","7.2866"
"69.72000","11.61478","313.23300","7.2972"
"69.84000","11.63475","313.56348","7.3079"
"69.96000","11.65480","314.09979","7.3187"
"70.08000","11.67472","314.39355","7.3294"
"70.20000","11.69481","314.83582","7.3401"
"70.32000","11.71478","315.35791","7.3507"
"70.44000","11.73476","315.80890","7.3612"
"70.56000","11.75474","316.29767","7.3720"
"70.68000","11.77475","316.84598","7.3827"
"70.80000","11.79480","317.21524","7.3934"
"70.92000","11.81479","317.47449","7.4041"
"71.04000","11.83480","318.12302","7.4148"
"71.16000","11.85478","318.64490","7.4257"
"71.28000","11.87482","318.95837","7.4366"
"71.40000","11.89474","319.56555","7.4473"
"71.52000","11.91481","320.08115","7.4584"
"71.64000","11.93477","320.72955","7.4692"
"71.76000","11.95481","320.84644","7.4801"
"71.88000","11.97480","321.44473","7.4909"
"72.00000","11.99475","321.88901","7.5016"
"72.12000","12.01485","322.34750","7.5125"
"72.24000","12.03478","323.08386","7.5232"
"72.36000","12.05477","323.34851","7.5341"
"72.48000","12.07474","323.90842","7.5450"
"72.60000","12.09479","324.26321","7.5560"
"72.72000","12.11477","324.83182","7.5667"
"72.84000","12.13477","324.94489","7.5777"
"72.96000","12.15473","325.64407","7.5885"
"73.08000","12.17475","326.19034","7.5996"
"73.20000","12.19481","326.63065","7.6103"
"73.32000","12.21472","327.22235","7.6211"
"73.44000","12.23480","327.67743","7.6319"
"73.56000","12.25476","327.96863","7.6428"
"73.68000","12.27477","328.64908","7.6535"
"73.80000","12.29477","329.01642","7.6642"
"73.92000","12.31477","329.40494","7.6751"
"74.04000","12.33479","330.01270","7.6855"
"74.16000","12.35482","330.58511","7.6964"
"74.28000","12.37476","330.87653","7.7069"
"74.40000","12.39477","331.10245","7.7175"
"74.52000","12.41484","331.98746","7.7281"
"74.64000","12.43478","332.38736","7.7385"
"74.76000","12.45484","332.78583","7.7490"
"74.88000","12.47474","333.38153","7.7594"
"75.00000","12.49482","334.10526","7.7700"
"75.12000","12.51477","334.28000","7.7803"
"75.24000","12.53476","334.73950","7.7908"
"75.36000","12.55479","335.17532","7.8013"
"75.48000","12.57480","335.75500","7.8117"
"75.60000","12.59483","336.04785","7.8219"
"75.72000","12.61475","336.64963","7.8321"
"75.84000","12.63479","337.18079","7.8421"
"75.96000","12.65473","337.41794","7.8522"
"76.08000","12.67478","338.45645","7.8622"
"76.20000","12.69472","338.61545","7.8721"
"76.32000","12.71476","339.10690","7.8822"
"76.44000","12.73478","339.54733","7.8921"
"76.56000","12.75475","339.95245","7.9022"
"76.68000","12.77481","340.41360","7.9120"
"76.80000","12.79477","341.07056","7.9220"
"76.92000","12.81482","341.43558","7.9317"
"77.04000","12.83477","341.88538","7.9413"
"77.16000","12.85476","342.43286","7.9511"
"77.28000","12.87478","342.60406","7.9608"
"77.40000","12.89479","343.17877","7.9703"
"77.52000","12.91476","343.48111","7.9799"
"77.64000","12.93479","344.18942","7.9891"
"77.76000","12.95478","344.40204","7.9986"
"77.88000","12.97480","344.87961","8.0079"
"78.00000","12.99483","345.44653","8.0172"
"78.12000","13.01474","346.24884","8.0263"
"78.24000","13.03482","346.56238","8.0351"
"78.36000","13.05479","346.99548","8.0442"
"78.48000","13.07477","347.51996","8.0532"
"78.60000","13.09477","347.73129","8.0621"
"78.72000","13.11478","348.54288","8.0709"
"78.84000","13.13476","348.67621","8.0799"
"78.96000","13.15476","349.32132","8.0889"
"79.08000","13.17477","349.74094","8.0971"
"79.20000","13.19477","350.31760","8.1054"
"79.32000","13.21482","350.57556","8.1135"
"79.44000","13.23472","351.66043","8.1212"
"79.56000","13.25477","352.00919","8.1286"
"79.68000","13.27477","352.43030","8.1355"
"79.80000","13.29479","352.48535","8.1420"
"79.92000","13.31481","353.37830","8.1479"
"80.04000","13.33475","353.56262","8.1532"
"80.16000","13.35480","354.33209","8.1581"
"80.28000","13.37477","354.62115","8.1625"
"80.40000","13.39479","355.35080","8.1659"
"80.52000","13.41478","355.89276","8.1686"
"80.64000","13.43482","356.32480","8.1704"
"80.76000","13.45477","357.10248","8.1718"
"80.88000","13.47480","357.23199","8.1725"
"81.00000","13.49474","357.48083","8.1729"
"81.12000","13.51480","357.96558","8.1733"
"81.24000","13.53481","358.84158","8.1736"
"81.36000","13.55475","359.04910","8.1737"
"81.48000","13.57479","359.47034","8.1740"
"81.60000","13.59476","360.32782","8.1743"
"81.72000","13.61480","360.83649","8.1747"
"81.84000","13.63475","361.24475","8.1751"
"81.96000","13.65477","361.85770","8.1756"
"82.08000","13.67476","362.34100","8.1765"
"82.20000","13.69477","362.73386","8.1778"
"82.32000","13.71475","363.22296","8.1801"
"82.44000","13.73474","364.09070","8.1824"
"82.56000","13.75479","364.25769","8.1848"
"82.68000","13.77476","364.85568","8.1876"
"82.80000","13.79481","364.98615","8.1904"
"82.92000","13.81475","366.01535","8.1932"
"83.04000","13.83480","365.94275","8.1960"
"83.16000","13.85479","367.08853","8.1988"
"83.28000","13.87476","367.16501","8.2015"
"83.40000","13.89479","367.82742","8.2039"
"83.52000","13.91478","368.19458","8.2065"
"83.64000","13.93481","368.82526","8.2088"
"83.76000","13.95479","369.02917","8.2113"
"83.88000","13.97480","369.79361","8.2135"
"84.00000","13.99476","370.36777","8.2156"
"84.12000","14.01480","370.66672","8.2176"
"84.24000","14.03474","371.36938","8.2195"
"84.36000","14.05482","371.65610","8.2212"
"84.48000","14.07480","372.12775","8.2230"
"84.60000","14.09478","372.83603","8.2248"
"84.72000","14.11481","373.26581","8.2264"
"84.84000","14.13474","373.78363","8.2281"
"84.96000","14.15479","374.29684","8.2297"
"85.08000","14.17473","374.62296","8.2314"
"85.20000","14.19474","375.48605","8.2329"
"85.32000","14.21474","375.84418","8.2345"
"85.44000","14.23478","376.40381","8.2361"
"85.56000","14.25476","376.63168","8.2377"
"85.68000","14.27480","377.02475","8.2394"
"85.80000","14.29479","377.53839","8.2411"
"85.92000","14.31477","378.04794","8.2427"
"86.04000","14.33480","378.54929","8.2444"
"86.16000","14.35474","379.19495","8.2461"
"86.28000","14.37481","379.75888","8.2480"
"86.40000","14.39477","380.39874","8.2498"
"86.52000","14.41478","380.63211","8.2517"
"86.64000","14.43478","381.37936","8.2536"
"86.76000","14.45476","381.65765","8.2554"
"86.88000","14.47478","382.14557","8.2574"
"87.00000","14.49479","382.68176","8.2593"
"87.12000","14.51480","383.24951","8.2612"
"87.24000","14.53478","383.58826","8.2631"
"87.36000","14.55484","384.24411","8.2649"
"87.48000","14.57475","384.51917","8.2667"
"87.60000","14.59480","385.26630","8.2685"
"87.72000","14.61475","385.87064","8.2705"
"87.84000","14.63475","386.20142","8.2722"
"87.96000","14.65475","387.03192","8.2741"
"88.08000","14.67472","386.98044","8.2759"
"88.20000","14.69480","387.86234","8.2778"
"88.32000","14.71480","388.03745","8.2795"
"88.44000","14.73478","389.08041","8.2812"
"88.56000","14.75473","389.23026","8.2830"
"88.68000","14.77478","389.98370","8.2847"
"88.80000","14.79477","390.07343","8.2861"
"88.92000","14.81481","390.83487","8.2877"
"89.04000","14.83474","391.56586","8.2894"
"89.16000","14.85479","392.00125","8.2910"
"89.28000","14.87483","392.29086","8.2926"
"89.40000","14.89474","392.91690","8.2943"
"89.52000","14.91483","393.29358","8.2961"
"89.64000","14.93476","393.77911","8.2979"
"89.76000","14.95482","394.50311","8.2996"
"89.88000","14.97477","395.10751","8.3014"
"90.00000","14.99478","395.58374","8.3031"
"90.12000","15.01478","396.02759","8.3048"
"90.24000","15.03480","396.40167","8.3066"
"90.36000","15.05476","396.94757","8.3082"
"90.48000","15.07478","397.29327","8.3099"
"90.60000","15.09479","398.16843","8.3115"
"90.72000","15.11477","398.54269","8.3130"
"90.84000","15.13482","398.95200","8.3145"
"90.96000","15.15470","399.62024","8.3159"
"91.08000","15.17478","399.99295","8.3172"
"91.20000","15.19476","400.53647","8.3184"
"91.32000","15.21473","401.02188","8.3196"
"91.44000","15.23478","401.83725","8.3206"
"91.56000","15.25478","402.32108","8.3216"
"91.68000","15.27480","402.59393","8.3224"
"91.80000","15.29478","403.23636","8.3231"
"91.92000","15.31481","403.39236","8.3238"
"92.04000","15.33478","404.43768","8.3244"
"92.16000","15.35482","404.57196","8.3251"
"92.28000","15.37470","405.51642","8.3256"
"92.40000","15.39475","405.84482","8.3263"
"92.52000","15.41479","406.37698","8.3268"
"92.64000","15.43478","406.90842","8.3274"
"92.76000","15.45483","407.37680","8.3281"
"92.88000","15.47475","407.83682","8.3288"
"93.00000","15.49482","408.35007","8.3295"
"93.12000","15.51478","409.11850","8.3303"
"93.24000","15.53477","409.20694","8.3311"
"93.36000","15.55478","410.25314","8.3321"
"93.48000","15.57482","410.54074","8.3334"
"93.60000","15.59479","411.11325","8.3347"
"93.72000","15.61478","411.37985","8.3362"
"93.84000","15.63475","412.09436","8.3378"
"93.96000","15.65477","412.88766","8.3395"
"94.08000","15.67479","412.84021","8.3413"
"94.20000","15.69470","413.55240","8.3428"
"94.32000","15.71480","414.04636","8.3442"
"94.44000","15.73475","414.95300","8.3457"
"94.56000","15.75477","414.99771","8.3470"
"94.68000","15.77478","415.74057","8.3482"
"94.80000","15.79479","416.20227","8.3494"
"94.92000","15.81479","416.48392","8.3503"
"95.04000","15.83480","417.33157","8.3514"
"95.16000","15.85478","417.57111","8.3524"
"95.28000","15.87477","418.33231","8.3533"
"95.40000","15.89483","418.86322","8.3542"
"95.52000","15.91474","419.46136","8.3550"
"95.64000","15.93480","419.85507","8.3558"
"95.76000","15.95474","420.46802","8.3566"
"95.88000","15.97480","420.98431","8.3573"
"96.00000","15.99481","421.41449","8.3580"
"96.12000","16.01477","422.09207","8.3585"
"96.24000","16.03481","422.39795","8.3592"
"96.36000","16.05481","422.73364","8.3598"
"96.48000","16.07478","423.39581","8.3604"
"96.60000","16.09476","423.74918","8.3609"
"96.72000","16.11478","424.34613","8.3615"
"96.84000","16.13473","424.90698","8.3621"
"96.96000","16.15477","425.31238","8.3626"
"97.08000","16.17473","425.99115","8.3631"
"97.20000","16.19479","426.39905","8.3636"
"97.32000","16.21482","427.32855","8.3641"
"97.44000","16.23473","427.58487","8.3647"
"97.56000","16.25480","428.41956","8.3652"
"97.68000","16.27474","428.60992","8.3657"
"97.80000","16.29480","429.45547","8.3660"
"97.92000","16.31478","429.78479","8.3665"
"98.04000","16.33477","430.17053","8.3669"
"98.16000","16.35476","430.90930","8.3672"
"98.28000","16.37481","431.51547","8.3676"
"98.40000","16.39475","431.94763","8.3679"
"98.52000","16.41479","432.38388","8.3682"
"98.64000","16.43480","433.28397","8.3686"
"98.76000","16.45478","433.60028","8.3688"
"98.88000","16.47482","434.14081","8.3691"
"99.00000","16.49475","434.54013","8.3694"
"99.12000","16.51484","435.18063","8.3696"
"99.24000","16.53476","435.89487","8.3699"
"99.36000","16.55475","436.25058","8.3701"
"99.48000","16.57477","436.62103","8.3704"
"99.60000","16.59477","437.37061","8.3706"
"99.72000","16.61482","437.66370","8.3710"
"99.84000","16.63477","438.38449","8.3712"
"99.96000","16.65478","438.92221","8.3715"
"100.08000","16.67473","439.48111","8.3717"
"100.20000","16.69480","439.85574","8.3719"
"100.32000","16.71470","440.42245","8.3721"
"100.44000","16.73477","440.94501","8.3723"
"100.56000","16.75478","441.55066","8.3725"
"100.68000","16.77478","442.15652","8.3728"
"100.80000","16.79479","442.83499","8.3729"
"100.92000","16.81476","443.06308","8.3731"
"101.04000","16.83485","443.85544","8.3733"
"101.16000","16.85479","444.34262","8.3735"
"101.28000","16.87477","444.68835","8.3737"
"101.40000","16.89474","445.37592","8.3739"
"101.52000","16.91482","445.79477","8.3741"
"101.64000","16.93479","446.26010","8.3743"
"101.76000","16.95481","447.07651","8.3745"
"101.88000","16.97477","447.39871","8.3748"
"102.00000","16.99478","447.65286","8.3750"
"102.12000","17.01483","448.41693","8.3752"
"102.24000","17.03474","449.21857","8.3755"
"102.36000","17.05484","449.37106","8.3756"
"102.48000","17.07479","450.33752","8.3758"
"102.60000","17.09480","450.36621","8.3759"
"102.72000","17.11476","451.16846","8.3762"
"102.84000","17.13475","451.57742","8.3762"
"102.96000","17.15475","452.51624","8.3764"
"103.08000","17.17476","452.86188","8.3766"
"103.20000","17.19478","453.34552","8.3767"
"103.32000","17.21474","453.67120","8.3768"
"103.44000","17.23480","454.23669","8.3769"
"103.56000","17.25476","455.08459","8.3771"
"103.68000","17.27481","455.17966","8.3772"
"103.80000","17.29476","456.23309","8.3774"
"103.92000","17.31479","456.57208","8.3774"
"104.04000","17.33479","457.15622","8.3775"
"104.16000","17.35475","457.47208","8.3777"
"104.28000","17.37482","458.21085","8.3777"
"104.40000","17.39477","459.09592","8.3779"
"104.52000","17.41480","459.18021","8.3780"
"104.64000","17.43477","460.09128","8.3781"
"104.76000","17.45481","460.56918","8.3781"
"104.88000","17.47478","461.01624","8.3783"
"105.00000","17.49481","461.13580","8.3783"
"105.12000","17.51474","462.00687","8.3784"
"105.24000","17.53479","462.47058","8.3786"
"105.36000","17.55482","463.01807","8.3787"
"105.48000","17.57475","463.66147","8.3787"
"105.60000","17.59481","464.09042","8.3788"
"105.72000","17.61474","464.82031","8.3789"
"105.84000","17.63479","465.34198","8.3790"
"105.96000","17.65474","465.69635","8.3792"
"106.08000","17.67477","466.28284","8.3793"
"106.20000","17.69476","466.69455","8.3793"
"106.32000","17.71478","467.58459","8.3795"
"106.44000","17.73474","467.83810","8.3795"
"106.56000","17.75477","468.52283","8.3796"
"106.68000","17.77478","469.02341","8.3796"
"106.80000","17.79479","469.68298","8.3797"
"106.92000","17.81483","470.16641","8.3797"
"107.04000","17.83475","470.47339","8.3799"
"107.16000","17.85480","471.27744","8.3799"
"107.28000","17.87479","471.18527","8.3800"
"107.40000","17.89476","472.02750","8.3800"
"107.52000","17.91479","472.66705","8.3801"
"107.64000","17.93479","473.06781","8.3801"
"107.76000","17.95479","473.90033","8.3802"
"107.88000","17.97479","474.02731","8.3802"
"108.00000","17.99478","474.78937","8.3803"
"108.12000","18.01479","475.31506","8.3803"
"108.24000","18.03482","475.86850","8.3804"
"108.36000","18.05473","476.25452","8.3804"
"108.48000","18.07479","476.83478","8.3805"
"108.60000","18.09477","477.67688","8.3805"
"108.72000","18.11479","477.76111","8.3806"
"108.84000","18.13479","478.25760","8.3806"
"108.96000","18.15473","478.59424","8.3806"
"109.08000","18.17477","479.54315","8.3807"
"109.20000","18.19477","479.77377","8.3807"
"109.32000","18.21474","480.41797","8.3808"
"109.44000","18.23474","480.97214","8.3808"
"109.56000","18.25480","481.55319","8.3808"
"109.68000","18.27475","481.97568","8.3809"
"109.80000","18.29480","482.50705","8.3809"
"109.92000","18.31475","483.33859","8.3809"
"110.04000","18.33481","483.66486","8.3811"
"110.16000","18.35484","483.99194","8.3811"
"110.28000","18.37473","484.84180","8.3811"
"110.40000","18.39482","485.29883","8.3810"
"110.52000","18.41477","485.55072","8.3810"
"110.64000","18.43480","486.43597","8.3811"
"110.76000","18.45479","486.81433","8.3810"
"110.88000","18.47479","487.00214","8.3811"
"111.00000","18.49478","487.80408","8.3810"
"111.12000","18.51480","488.67389","8.3811"
"111.24000","18.53479","488.97742","8.3809"
"111.36000","18.55478","489.51843","8.3810"
"111.48000","18.57484","489.75580","8.3809"
"111.60000","18.59476","490.53705","8.3809"
"111.72000","18.61480","491.03433","8.3809"
"111.84000","18.63473","491.58023","8.3808"
"111.96000","18.65477","492.00803","8.3808"
"112.08000","18.67474","492.84552","8.3808"
"112.20000","18.69472","493.26526","8.3807"
"112.32000","18.71478","493.78305","8.3807"
"112.44000","18.73476","494.35565","8.3807"
"112.56000","18.75477","494.60526","8.3807"
"112.68000","18.77477","495.39990","8.3807"
"112.80000","18.79480","495.97836","8.3806"
"112.92000","18.81477","496.30856","8.3805"
"113.04000","18.83480","496.82333","8.3804"
"113.16000","18.85472","497.38571","8.3805"
"113.28000","18.87482","498.03741","8.3805"
"113.40000","18.89477","498.48370","8.3806"
"113.52000","18.91477","498.82544","8.3805"
"113.64000","18.93481","499.39697","8.3806"
"113.76000","18.95479","500.11353","8.3806"
"113.88000","18.97482","500.47305","8.3807"
"114.00000","18.99479","500.94952","8.3806"
"114.12000","19.01476","501.46649","8.3808"
"114.24000","19.03477","501.98416","8.3807"
"114.36000","19.05482","502.61151","8.3807"
"114.48000","19.07477","502.94559","8.3808"
"114.60000","19.09479","503.43597","8.3808"
"114.72000","19.11480","503.69370","8.3808"
"114.84000","19.13475","504.39984","8.3808"
"114.96000","19.15479","504.99438","8.3809"
"115.08000","19.17471","505.66125","8.3810"
"115.20000","19.19480","506.01855","8.3809"
"115.32000","19.21477","506.50787","8.3810"
"115.44000","19.23475","506.83911","8.3811"
"115.56000","19.25476","507.48755","8.3811"
"115.68000","19.27477","508.02728","8.3811"
"115.80000","19.29478","508.44733","8.3811"
"115.92000","19.31478","508.88327","8.3811"
"116.04000","19.33480","509.20364","8.3811"
"116.16000","19.35476","510.12918","8.3811"
"116.28000","19.37483","510.35556","8.3812"
"116.40000","19.39474","510.77930","8.3811"
"116.52000","19.41481","511.46432","8.3812"
"116.64000","19.43478","511.79245","8.3813"
"116.76000","19.45479","512.22839","8.3813"
"116.88000","19.47482","512.93683","8.3813"
"117.00000","19.49476","513.18707","8.3813"
"117.12000","19.51482","513.73810","8.3813"
"117.24000","19.53480","514.45660","8.3814"
"117.36000","19.55477","514.98169","8.3815"
"117.48000","19.57475","515.38257","8.3815"
"117.60000","19.59480","515.80548","8.3816"
"117.72000","19.61476","515.84778","8.3816"
"117.84000","19.63477","516.80164","8.3817"
"117.96000","19.65474","516.93536","8.3817"
"118.08000","19.67477","517.40820","8.3818"
"118.20000","19.69480","518.10828","8.3818"
"118.32000","19.71472","518.41901","8.3818"
"118.44000","19.73479","518.87988","8.3819"
"118.56000","19.75475","519.37592","8.3819"
"118.68000","19.77479","519.94879","8.3819"
"118.80000","19.79475","520.47278","8.3819"
"118.92000","19.81476","520.51392","8.3820"
"119.04000","19.83480","521.16217","8.3820"
"119.16000","19.85481","521.54437","8.3820"
"119.28000","19.87474","522.19049","8.3820"
"119.40000","19.89479","522.40485","8.3821"
"119.52000","19.91481","522.77344","8.3821"
"119.64000","19.93478","523.22797","8.3820"
"119.76000","19.95483","523.76831","8.3821"
"119.88000","19.97474","524.13458","8.3821"
"120.00000","19.99480","524.41052","8.3822"
"120.12000","20.01479","524.67322","8.3822"
"120.24000","20.03475","525.46686","8.3821"
"120.36000","20.05482","525.86798","8.3823"
"120.48000","20.07481","526.05371","8.3822"
"120.60000","20.09483","526.49225","8.3822"
"120.72000","20.11476","527.10895","8.3823"
"120.84000","20.13478","527.30359","8.3823"
"120.96000","20.15475","527.71246","8.3824"
"121.08000","20.17476","527.98352","8.3823"
"121.20000","20.19470","528.60999","8.3823"
"121.32000","20.21476","528.68683","8.3823"
"121.44000","20.23478","529.10645","8.3824"
"121.56000","20.25475","529.75031","8.3824"
"121.68000","20.27481","529.95209","8.3824"
"121.80000","20.29478","530.34131","8.3825"
"121.92000","20.31481","530.63794","8.3824"
"122.04000","20.33479","531.00708","8.3825"
"122.16000","20.35478","531.12244","8.3825"
"122.28000","20.37479","531.38599","8.3825"
"122.40000","20.39480","531.70514","8.3825"
"122.52000","20.41478","532.14001","8.3826"
"122.64000","20.43479","532.34198","8.3827"
"122.76000","20.45478","532.64484","8.3827"
"122.88000","20.47480","532.89917","8.3827"
"123.00000","20.49482","533.01648","8.3827"
"123.12000","20.51474","533.26239","8.3827"
"123.24000","20.53481","533.46686","8.3828"
"123.36000","20.55479","534.06989","8.3828"
"123.48000","20.57477","533.71289","8.3828"
"123.60000","20.59477","534.13800","8.3827"
"123.72000","20.61474","534.16803","8.3828"
"123.84000","20.63477","534.38306","8.3827"
"123.96000","20.65476","534.49664","8.3828"
"124.08000","20.67477","534.53070","8.3827"
"124.20000","20.69477","534.66058","8.3828"
"124.32000","20.71481","534.71442","8.3827"
"124.44000","20.73471","534.75275","8.3827"
"124.56000","20.75476","534.75476","8.3827"
"124.68000","20.77475","534.53790","8.3826"
"124.80000","20.79476","534.22571","8.3825"
"124.92000","20.81481","534.30811","8.3824"
"125.04000","20.83476","533.62604","8.3822"
"125.16000","20.85483","533.38739","8.3821"
"125.28000","20.87479","532.82587","8.3820"
"125.40000","20.89477","532.68622","8.3818"
"125.52000","20.91477","532.19391","8.3815"
"125.64000","20.93480","531.10162","8.3811"
"125.76000","20.95477","530.17596","8.3806"
"125.88000","20.97480","529.45862","8.3801"
"126.00000","20.99476","527.74188","8.3792"
"126.12000","21.01481","526.57233","8.3780"
"126.24000","21.03481","524.12805","8.3763"
"126.36000","21.05473","521.65570","8.3735"
"126.48000","21.07482","517.82990","8.3696"
"126.60000","21.09477","512.33691","8.3630"
"126.72000","21.11480","502.62506","8.3475"
"126.82200","21.13183","290.55151","7.0938"