File: mechanics_and_materials/materials_practical_data/instrondata_machine3_15sep2022_2pm/all_material_instron_data/low_carbon_steel.csv
Time measurement,Displacement,Primary force measurement,Strain 1
(s),(mm),(N),(%)
"0.00000","0.00000","-12.44689","-0.0001"
"0.14000","0.01643","89.97260","0.0055"
"0.28000","0.04135","275.54016","0.0159"
"0.42000","0.06479","404.55136","0.0231"
"0.56000","0.08808","508.07544","0.0290"
"0.70000","0.11149","600.01434","0.0342"
"0.84000","0.13476","686.44879","0.0390"
"0.98000","0.15812","772.83899","0.0439"
"1.12000","0.18145","858.85767","0.0489"
"1.26000","0.20481","946.38495","0.0539"
"1.40000","0.22814","1035.82520","0.0592"
"1.54000","0.25145","1124.20312","0.0645"
"1.68000","0.27481","1214.00757","0.0697"
"1.82000","0.29813","1301.91650","0.0752"
"1.96000","0.32143","1392.02649","0.0810"
"2.10000","0.34481","1481.52344","0.0868"
"2.24000","0.36815","1572.56165","0.0928"
"2.38000","0.39151","1662.44434","0.0989"
"2.52000","0.41475","1752.17090","0.1050"
"2.66000","0.43815","1839.90137","0.1109"
"2.80000","0.46146","1921.67761","0.1166"
"2.94000","0.48481","1994.01416","0.1214"
"3.08000","0.50811","2052.67383","0.1253"
"3.22000","0.53145","2099.72681","0.1287"
"3.36000","0.55480","2141.33105","0.1315"
"3.50000","0.57812","2168.93066","0.1338"
"3.64000","0.60150","2185.58325","0.1353"
"3.78000","0.62478","2202.49365","0.1369"
"3.92000","0.64815","2215.62549","0.1384"
"4.06000","0.67143","2226.02515","0.1396"
"4.20000","0.69484","2232.27100","0.1405"
"4.34000","0.71811","2238.58838","0.1414"
"4.48000","0.74146","2245.29834","0.1422"
"4.62000","0.76481","2254.68188","0.1432"
"4.76000","0.78817","2264.29297","0.1441"
"4.90000","0.81143","2276.47266","0.1451"
"5.04000","0.83481","2289.27393","0.1462"
"5.18000","0.85812","2303.36963","0.1475"
"5.32000","0.88148","2317.76904","0.1488"
"5.46000","0.90480","2330.57178","0.1501"
"5.60000","0.92819","2343.82642","0.1516"
"5.74000","0.95147","2356.19580","0.1530"
"5.88000","0.97481","2362.55591","0.1542"
"6.02000","0.99814","2367.64478","0.1552"
"6.16000","1.02152","2374.60840","0.1563"
"6.30000","1.04478","2384.28711","0.1577"
"6.44000","1.06810","2394.44312","0.1589"
"6.58000","1.09147","2401.77271","0.1601"
"6.72000","1.11478","2404.14160","0.1608"
"6.86000","1.13815","2401.44116","0.1612"
"7.00000","1.16149","2402.46606","0.1616"
"7.14000","1.18481","2400.69189","0.1620"
"7.28000","1.20809","2396.49585","0.1623"
"7.42000","1.23149","2391.22266","0.1624"
"7.56000","1.25478","2387.78638","0.1636"
"7.70000","1.27820","2388.56348","0.1657"
"7.84000","1.30145","2388.08276","0.1682"
"7.98000","1.32484","2387.47949","0.1710"
"8.12000","1.34815","2385.22168","0.1743"
"8.26000","1.37149","2379.67017","0.1771"
"8.40000","1.39478","2377.69849","0.1800"
"8.54000","1.41816","2374.44507","0.1825"
"8.68000","1.44148","2374.44653","0.1850"
"8.82000","1.46480","2368.39526","0.1871"
"8.96000","1.48813","2356.66772","0.1886"
"9.10000","1.51150","2349.52515","0.1902"
"9.24000","1.53480","2343.33618","0.1920"
"9.38000","1.55814","2342.10034","0.1939"
"9.52000","1.58146","2346.16797","0.1963"
"9.66000","1.60480","2351.97778","0.1992"
"9.80000","1.62813","2358.03247","0.2022"
"9.94000","1.65145","2364.39600","0.2059"
"10.08000","1.67484","2367.25562","0.2096"
"10.22000","1.69812","2371.34058","0.2139"
"10.36000","1.72148","2374.00439","0.2189"
"10.50000","1.74476","2375.04858","0.2249"
"10.64000","1.76820","2376.02856","0.2318"
"10.78000","1.79141","2376.15674","0.2396"
"10.92000","1.81484","2377.75488","0.2485"
"11.06000","1.83816","2377.95508","0.2588"
"11.20000","1.86149","2378.59937","0.2705"
"11.34000","1.88481","2379.62915","0.2844"
"11.48000","1.90814","2374.26172","0.3013"
"11.62000","1.93149","2373.52100","0.3214"
"11.76000","1.95480","2372.23901","0.3437"
"11.90000","1.97815","2374.92773","0.3687"
"12.04000","2.00148","2378.37964","0.3938"
"12.18000","2.02480","2384.58472","0.4176"
"12.32000","2.04815","2391.23096","0.4392"
"12.46000","2.07148","2397.82056","0.4586"
"12.60000","2.09482","2405.97852","0.4770"
"12.74000","2.11809","2413.76172","0.4949"
"12.88000","2.14145","2419.70630","0.5130"
"13.02000","2.16478","2425.14990","0.5316"
"13.16000","2.18813","2429.58154","0.5520"
"13.30000","2.21150","2433.54517","0.5743"
"13.44000","2.23479","2435.36597","0.5986"
"13.58000","2.25817","2435.27197","0.6264"
"13.72000","2.28141","2434.43335","0.6590"
"13.86000","2.30484","2433.02441","0.6955"
"14.00000","2.32810","2435.26245","0.7341"
"14.14000","2.35150","2432.51392","0.7749"
"14.28000","2.37477","2425.84155","0.8187"
"14.42000","2.39817","2423.42383","0.8627"
"14.56000","2.42150","2418.34351","0.9085"
"14.70000","2.44481","2409.08301","0.9557"
"14.84000","2.46813","2404.26782","1.0021"
"14.98000","2.49148","2400.43164","1.0501"
"15.12000","2.51479","2396.69116","1.0991"
"15.26000","2.53814","2395.12378","1.1504"
"15.40000","2.56148","2396.67871","1.2031"
"15.54000","2.58483","2398.66382","1.2576"
"15.68000","2.60812","2405.73486","1.3123"
"15.82000","2.63148","2413.92798","1.3667"
"15.96000","2.65479","2420.23242","1.4193"
"16.10000","2.67811","2424.57886","1.4707"
"16.24000","2.70147","2428.04321","1.5220"
"16.38000","2.72481","2431.99609","1.5723"
"16.52000","2.74818","2435.37402","1.6196"
"16.66000","2.77143","2439.84375","1.6623"
"16.80000","2.79483","2442.75171","1.7026"
"16.94000","2.81809","2446.37207","1.7410"
"17.08000","2.84152","2449.07837","1.7786"
"17.22000","2.86476","2454.01001","1.8150"
"17.36000","2.88817","2459.45093","1.8504"
"17.50000","2.91149","2463.66504","1.8854"
"17.64000","2.93480","2464.86768","1.9202"
"17.78000","2.95814","2462.52417","1.9556"
"17.92000","2.98149","2453.56030","1.9891"
"18.06000","3.00479","2450.27759","2.0199"
"18.20000","3.02814","2451.03369","2.0523"
"18.34000","3.05149","2452.31689","2.0880"
"18.48000","3.07482","2453.90820","2.1259"
"18.62000","3.09812","2450.63965","2.1668"
"18.76000","3.12149","2450.09521","2.2093"
"18.90000","3.14481","2451.88257","2.2528"
"19.04000","3.16813","2455.64551","2.2963"
"19.18000","3.19145","2455.61646","2.3399"
"19.32000","3.21480","2459.15430","2.3838"
"19.46000","3.23815","2462.63354","2.4284"
"19.60000","3.26143","2462.42456","2.4734"
"19.74000","3.28485","2451.97314","2.5195"
"19.88000","3.30811","2447.21899","2.5643"
"20.02000","3.33149","2451.57642","2.6059"
"20.16000","3.35477","2459.89453","2.6438"
"20.30000","3.37819","2466.58936","2.6804"
"20.44000","3.40143","2470.94189","2.7179"
"20.58000","3.42481","2474.41016","2.7547"
"20.72000","3.44813","2476.60547","2.7896"
"20.86000","3.47149","2476.31934","2.8213"
"21.00000","3.49484","2473.60718","2.8502"
"21.14000","3.51815","2468.91797","2.8775"
"21.28000","3.54150","2467.26929","2.9048"
"21.42000","3.56478","2469.12842","2.9344"
"21.56000","3.58812","2468.91138","2.9701"
"21.70000","3.61145","2461.35083","3.0144"
"21.84000","3.63483","2456.36206","3.0656"
"21.98000","3.65812","2461.87646","3.1137"
"22.12000","3.68151","2465.53076","3.1562"
"22.26000","3.70481","2466.17041","3.1929"
"22.40000","3.72813","2460.42993","3.2258"
"22.54000","3.75145","2453.71924","3.2583"
"22.68000","3.77480","2449.42651","3.2912"
"22.82000","3.79814","2444.83789","3.3255"
"22.96000","3.82149","2443.85742","3.3622"
"23.10000","3.84479","2448.27637","3.4013"
"23.24000","3.86820","2453.17993","3.4416"
"23.38000","3.89143","2455.79590","3.4864"
"23.52000","3.91485","2462.44458","3.5324"
"23.66000","3.93809","2467.47314","3.5773"
"23.80000","3.96150","2466.53369","3.6230"
"23.94000","3.98476","2464.15088","3.6680"
"24.08000","4.00817","2465.16992","3.7135"
"24.22000","4.03149","2460.09668","3.7650"
"24.36000","4.05481","2441.37134","3.8310"
"24.50000","4.07813","2433.16748","3.9040"
"24.64000","4.10148","2442.48901","3.9675"
"24.78000","4.12482","2447.23828","4.0261"
"24.92000","4.14810","2447.31616","4.0828"
"25.06000","4.17148","2447.78125","4.1388"
"25.20000","4.19482","2447.53540","4.1956"
"25.34000","4.21813","2451.07739","4.2512"
"25.48000","4.24145","2453.82275","4.3045"
"25.62000","4.26478","2448.61548","4.3579"
"25.76000","4.28814","2445.56909","4.4073"
"25.90000","4.31145","2444.06982","4.4521"
"26.04000","4.33480","2446.71118","4.4941"
"26.18000","4.35819","2443.15479","4.5411"
"26.32000","4.38146","2440.76099","4.5925"
"26.46000","4.40483","2439.56421","4.6451"
"26.60000","4.42814","2447.35449","4.6911"
"26.74000","4.45153","2447.45605","4.7341"
"26.88000","4.47476","2434.68164","4.7736"
"27.02000","4.49816","2410.92041","4.8061"
"27.16000","4.52147","2411.09424","4.8343"
"27.30000","4.54483","2417.49561","4.8656"
"27.44000","4.56815","2417.95923","4.9038"
"27.58000","4.59150","2419.60254","4.9479"
"27.72000","4.61482","2423.33740","4.9927"
"27.86000","4.63809","2426.62329","5.0355"
"28.00000","4.66149","2434.50562","5.0820"
"28.14000","4.68480","2441.63818","5.1318"
"28.28000","4.70816","2438.04980","5.1881"
"28.42000","4.73147","2439.94946","5.2454"
"28.56000","4.75483","2436.71875","5.3085"
"28.70000","4.77816","2427.14551","5.3784"
"28.84000","4.80146","2427.60522","5.4472"
"28.98000","4.82481","2432.30908","5.5166"
"29.12000","4.84814","2422.09985","5.5945"
"29.26000","4.87147","2420.73462","5.6792"
"29.40000","4.89480","2414.52466","5.7679"
"29.54000","4.91811","2412.52881","5.8578"
"29.68000","4.94154","2421.59033","5.9439"
"29.82000","4.96478","2422.95068","6.0315"
"29.96000","4.98819","2415.10693","6.1250"
"30.10000","5.01143","2415.17285","6.2176"
"30.24000","5.03484","2441.89624","6.2971"
"30.38000","5.05810","2468.08765","6.3653"
"30.52000","5.08151","2483.70386","6.4270"
"30.66000","5.10485","2494.88379","6.4838"
"30.80000","5.12812","2503.21753","6.5362"
"30.94000","5.15149","2509.90454","6.5856"
"31.08000","5.17477","2514.69922","6.6317"
"31.22000","5.19814","2518.99780","6.6750"
"31.36000","5.22140","2522.53638","6.7156"
"31.50000","5.24483","2525.35352","6.7541"
"31.64000","5.26814","2528.52393","6.7911"
"31.78000","5.29147","2531.20874","6.8268"
"31.92000","5.31479","2533.53931","6.8615"
"32.06000","5.33815","2535.73535","6.8956"
"32.20000","5.36146","2538.54663","6.9292"
"32.34000","5.38480","2540.63989","6.9624"
"32.48000","5.40816","2543.23389","6.9954"
"32.62000","5.43151","2545.12231","7.0279"
"32.76000","5.45477","2547.37988","7.0601"
"32.90000","5.47819","2548.82666","7.0923"
"33.04000","5.50149","2551.43213","7.1242"
"33.18000","5.52486","2553.32300","7.1563"
"33.32000","5.54807","2555.04419","7.1881"
"33.46000","5.57151","2556.99609","7.2201"
"33.60000","5.59480","2559.15283","7.2523"
"33.74000","5.61815","2561.40332","7.2842"
"33.88000","5.64150","2562.86792","7.3162"
"34.02000","5.66482","2565.03564","7.3481"
"34.16000","5.68817","2566.90894","7.3801"
"34.30000","5.71143","2568.45996","7.4117"
"34.44000","5.73485","2570.39941","7.4438"
"34.58000","5.75811","2572.18921","7.4755"
"34.72000","5.78147","2574.01538","7.5077"
"34.86000","5.80479","2576.01367","7.5397"
"35.00000","5.82815","2577.44019","7.5716"
"35.14000","5.85148","2579.38403","7.6037"
"35.28000","5.87482","2580.61621","7.6355"
"35.42000","5.89812","2582.63232","7.6673"
"35.56000","5.92148","2583.85229","7.6990"
"35.70000","5.94476","2586.31812","7.7308"
"35.84000","5.96815","2587.40039","7.7625"
"35.98000","5.99148","2589.54028","7.7943"
"36.12000","6.01484","2591.11255","7.8261"
"36.26000","6.03814","2593.15137","7.8579"
"36.40000","6.06152","2594.76245","7.8897"
"36.54000","6.08476","2595.96802","7.9216"
"36.68000","6.10815","2597.98608","7.9535"
"36.82000","6.13146","2599.08643","7.9856"
"36.96000","6.15484","2601.71851","8.0172"
"37.10000","6.17813","2603.00757","8.0493"
"37.24000","6.20145","2604.81860","8.0817"
"37.38000","6.22484","2606.27588","8.1139"
"37.52000","6.24811","2607.87646","8.1461"
"37.66000","6.27148","2609.64990","8.1786"
"37.80000","6.29475","2610.70068","8.2107"
"37.94000","6.31816","2612.44775","8.2429"
"38.08000","6.34144","2613.90015","8.2752"
"38.22000","6.36482","2615.15674","8.3076"
"38.36000","6.38813","2617.17944","8.3399"
"38.50000","6.41149","2618.42505","8.3723"
"38.64000","6.43476","2620.18848","8.4047"
"38.78000","6.45814","2621.47314","8.4372"
"38.92000","6.48146","2623.46875","8.4699"
"39.06000","6.50481","2624.53589","8.5023"
"39.20000","6.52811","2626.22412","8.5351"
"39.34000","6.55154","2627.62256","8.5675"
"39.48000","6.57482","2629.67041","8.6001"
"39.62000","6.59815","2630.61011","8.6328"
"39.76000","6.62143","2632.01294","8.6654"
"39.90000","6.64482","2633.50049","8.6980"
"40.04000","6.66812","2635.03125","8.7307"
"40.18000","6.69148","2636.44409","8.7632"
"40.32000","6.71484","2637.54980","8.7958"
"40.46000","6.73814","2639.32471","8.8275"
"40.60000","6.76149","2640.35547","8.8582"
"40.74000","6.78477","2641.79688","8.8902"
"40.88000","6.80818","2642.97656","8.9225"
"41.02000","6.83140","2644.78076","8.9547"
"41.16000","6.85482","2645.79565","8.9871"
"41.30000","6.87812","2647.27417","9.0196"
"41.44000","6.90151","2648.47656","9.0518"
"41.58000","6.92480","2649.83521","9.0841"
"41.72000","6.94818","2650.68457","9.1164"
"41.86000","6.97146","2652.27686","9.1486"
"42.00000","6.99478","2653.23413","9.1806"
"42.14000","7.01814","2654.63208","9.2126"
"42.28000","7.04148","2654.95142","9.2443"
"42.42000","7.06481","2657.02271","9.2761"
"42.56000","7.08815","2658.17920","9.3078"
"42.70000","7.11150","2659.53906","9.3397"
"42.84000","7.13484","2660.24438","9.3714"
"42.98000","7.15810","2661.58203","9.4030"
"43.12000","7.18148","2662.46533","9.4346"
"43.26000","7.20479","2663.99512","9.4664"
"43.40000","7.22817","2665.55322","9.4980"
"43.54000","7.25146","2666.39014","9.5298"
"43.68000","7.27481","2667.76929","9.5615"
"43.82000","7.29819","2669.16357","9.5933"
"43.96000","7.32144","2670.06323","9.6251"
"44.10000","7.34483","2671.05225","9.6569"
"44.24000","7.36809","2671.92432","9.6885"
"44.38000","7.39148","2673.40869","9.7204"
"44.52000","7.41476","2674.61938","9.7521"
"44.66000","7.43820","2675.47437","9.7837"
"44.80000","7.46147","2677.21387","9.8155"
"44.94000","7.48480","2678.08838","9.8475"
"45.08000","7.50811","2679.55615","9.8795"
"45.22000","7.53148","2680.25098","9.9117"
"45.36000","7.55481","2681.87451","9.9441"
"45.50000","7.57814","2682.51807","9.9762"
"45.64000","7.60147","2683.70166","10.0083"
"45.78000","7.62484","2684.74487","10.0405"
"45.92000","7.64813","2685.90552","10.0727"
"46.06000","7.67150","2686.76660","10.1049"
"46.20000","7.69478","2687.82886","10.1373"
"46.34000","7.71817","2689.38721","10.1697"
"46.48000","7.74143","2690.01099","10.2019"
"46.62000","7.76483","2691.23462","10.2344"
"46.76000","7.78816","2692.56934","10.2670"
"46.90000","7.81146","2693.43530","10.2994"
"47.04000","7.83486","2694.30444","10.3319"
"47.18000","7.85812","2695.65820","10.3642"
"47.32000","7.88151","2696.74536","10.3970"
"47.46000","7.90473","2697.68750","10.4297"
"47.60000","7.92816","2698.65112","10.4627"
"47.74000","7.95144","2700.11011","10.4955"
"47.88000","7.97481","2700.64819","10.5286"
"48.02000","7.99815","2701.94775","10.5616"
"48.16000","8.02152","2702.61182","10.5947"
"48.30000","8.04479","2704.06714","10.6279"
"48.44000","8.06810","2704.77246","10.6607"
"48.58000","8.09147","2705.95630","10.6940"
"48.72000","8.11482","2706.94458","10.7273"
"48.86000","8.13814","2708.65991","10.7607"
"49.00000","8.16150","2709.31763","10.7943"
"49.14000","8.18483","2710.54517","10.8278"
"49.28000","8.20818","2711.03857","10.8614"
"49.42000","8.23146","2712.16919","10.8947"
"49.56000","8.25483","2712.73242","10.9282"
"49.70000","8.27814","2713.83276","10.9618"
"49.84000","8.30145","2714.86353","10.9952"
"49.98000","8.32479","2715.36841","11.0287"
"50.12000","8.34811","2716.91016","11.0621"
"50.26000","8.37151","2717.72974","11.0959"
"50.40000","8.39477","2718.50757","11.1294"
"50.54000","8.41818","2719.26709","11.1633"
"50.68000","8.44142","2720.05249","11.1966"
"50.82000","8.46481","2720.48315","11.2303"
"50.96000","8.48812","2721.97607","11.2639"
"51.10000","8.51154","2722.60034","11.2972"
"51.24000","8.53479","2723.86230","11.3308"
"51.38000","8.55815","2724.64673","11.3643"
"51.52000","8.58146","2725.69971","11.3978"
"51.66000","8.60480","2726.13696","11.4312"
"51.80000","8.62813","2726.84180","11.4649"
"51.94000","8.65148","2727.27930","11.4980"
"52.08000","8.67482","2728.93213","11.5313"
"52.22000","8.69813","2729.13867","11.5645"
"52.36000","8.72147","2729.96118","11.5976"
"52.50000","8.74483","2730.82617","11.6307"
"52.64000","8.76815","2731.52075","11.6639"
"52.78000","8.79145","2732.71509","11.6973"
"52.92000","8.81479","2733.38135","11.7306"
"53.06000","8.83815","2734.32666","11.7643"
"53.20000","8.86149","2735.11914","11.7979"
"53.34000","8.88478","2736.06396","11.8313"
"53.48000","8.90821","2736.85596","11.8651"
"53.62000","8.93147","2737.90845","11.8987"
"53.76000","8.95480","2738.53418","11.9325"
"53.90000","8.97808","2738.98096","11.9663"
"54.04000","9.00149","2739.80127","12.0003"
"54.18000","9.02477","2740.86987","12.0343"
"54.32000","9.04818","2741.83936","12.0685"
"54.46000","9.07150","2742.36792","12.1025"
"54.60000","9.09483","2743.45728","12.1363"
"54.74000","9.11812","2744.03882","12.1705"
"54.88000","9.14150","2744.64648","12.2043"
"55.02000","9.16483","2745.78125","12.2384"
"55.16000","9.18814","2746.39355","12.2725"
"55.30000","9.21146","2747.14697","12.3067"
"55.44000","9.23480","2747.93848","12.3410"
"55.58000","9.25818","2748.92554","12.3756"
"55.72000","9.28148","2749.34204","12.4097"
"55.86000","9.30482","2749.87500","12.4442"
"56.00000","9.32816","2750.92798","12.4784"
"56.14000","9.35143","2751.31592","12.5125"
"56.28000","9.37480","2752.34888","12.5469"
"56.42000","9.39815","2752.77417","12.5812"
"56.56000","9.42146","2753.92188","12.6155"
"56.70000","9.44483","2754.26147","12.6502"
"56.84000","9.46812","2755.26074","12.6844"
"56.98000","9.49152","2755.61865","12.7191"
"57.12000","9.51473","2756.30029","12.7534"
"57.26000","9.53816","2756.29590","12.7877"
"57.40000","9.56143","2757.40308","12.8221"
"57.54000","9.58484","2758.45508","12.8564"
"57.68000","9.60809","2759.04663","12.8908"
"57.82000","9.63150","2759.53101","12.9254"
"57.96000","9.65481","2760.05444","12.9597"
"58.10000","9.67813","2760.70508","12.9942"
"58.24000","9.70146","2761.29492","13.0289"
"58.38000","9.72477","2761.67041","13.0632"
"58.52000","9.74814","2762.70630","13.0978"
"58.66000","9.77145","2763.15991","13.1321"
"58.80000","9.79484","2763.78833","13.1666"
"58.94000","9.81815","2764.66675","13.2008"
"59.08000","9.84148","2765.32007","13.2354"
"59.22000","9.86479","2766.05591","13.2700"
"59.36000","9.88813","2766.31836","13.3048"
"59.50000","9.91148","2767.10010","13.3394"
"59.64000","9.93480","2767.38550","13.3742"
"59.78000","9.95812","2768.16333","13.4088"
"59.92000","9.98153","2768.46167","13.4432"
"60.06000","10.00478","2769.67261","13.4778"
"60.20000","10.02816","2769.66455","13.5126"
"60.34000","10.05143","2770.77539","13.5471"
"60.48000","10.07485","2770.92358","13.5821"
"60.62000","10.09808","2772.04297","13.6170"
"60.76000","10.12153","2772.60498","13.6520"
"60.90000","10.14479","2773.38696","13.6870"
"61.04000","10.16815","2773.73804","13.7218"
"61.18000","10.19147","2774.09570","13.7568"
"61.32000","10.21482","2774.60229","13.7917"
"61.46000","10.23816","2775.61133","13.8268"
"61.60000","10.26142","2775.70703","13.8618"
"61.74000","10.28483","2776.58374","13.8971"
"61.88000","10.30809","2777.18286","13.9323"
"62.02000","10.33151","2778.28003","13.9678"
"62.16000","10.35481","2778.27368","14.0031"
"62.30000","10.37817","2778.92554","14.0385"
"62.44000","10.40147","2779.44067","14.0739"
"62.58000","10.42475","2779.90747","14.1093"
"62.72000","10.44813","2780.14966","14.1449"
"62.86000","10.47147","2780.70752","14.1803"
"63.00000","10.49477","2781.65723","14.2161"
"63.14000","10.51817","2782.23022","14.2518"
"63.28000","10.54147","2782.42139","14.2874"
"63.42000","10.56486","2782.90186","14.3229"
"63.56000","10.58807","2783.41968","14.3585"
"63.70000","10.61153","2783.94849","14.3944"
"63.84000","10.63477","2784.70459","14.4302"
"63.98000","10.65816","2785.21948","14.4659"
"64.12000","10.68145","2785.64136","14.5018"
"64.26000","10.70484","2786.13892","14.5375"
"64.40000","10.72816","2786.89209","14.5737"
"64.54000","10.75148","2787.41650","14.6095"
"64.68000","10.77483","2787.55640","14.6457"
"64.82000","10.79812","2788.36792","14.6816"
"64.96000","10.82145","2788.91382","14.7176"
"65.10000","10.84480","2788.99609","14.7533"
"65.24000","10.86817","2789.57617","14.7892"
"65.38000","10.89149","2790.10132","14.8252"
"65.52000","10.91479","2790.67456","14.8612"
"65.66000","10.93814","2791.34961","14.8975"
"65.80000","10.96146","2791.27759","14.9335"
"65.94000","10.98480","2792.13013","14.9698"
"66.08000","11.00814","2792.03589","15.0061"
"66.22000","11.03145","2793.23926","15.0422"
"66.36000","11.05484","2793.04590","15.0784"
"66.50000","11.07808","2793.90601","15.1142"
"66.64000","11.10152","2793.71948","15.1505"
"66.78000","11.12475","2794.58179","15.1868"
"66.92000","11.14814","2795.22729","15.2231"
"67.06000","11.17144","2795.43677","15.2595"
"67.20000","11.19485","2795.87354","15.2958"
"67.34000","11.21814","2796.55396","15.3323"
"67.48000","11.24148","2796.71289","15.3683"
"67.62000","11.26483","2797.25439","15.4048"
"67.76000","11.28815","2797.81787","15.4409"
"67.90000","11.31144","2798.46558","15.4774"
"68.04000","11.33477","2798.70361","15.5137"
"68.18000","11.35816","2798.88208","15.5501"
"68.32000","11.38144","2799.32495","15.5865"
"68.46000","11.40483","2799.70996","15.6227"
"68.60000","11.42815","2800.25293","15.6590"
"68.74000","11.45149","2800.59546","15.6946"
"68.88000","11.47479","2800.84229","15.7302"
"69.02000","11.49814","2800.91040","15.7655"
"69.16000","11.52148","2801.92383","15.8010"
"69.30000","11.54481","2801.67041","15.8361"
"69.44000","11.56808","2802.49561","15.8711"
"69.58000","11.59151","2802.62354","15.9057"
"69.72000","11.61480","2803.42383","15.9402"
"69.86000","11.63818","2803.12769","15.9733"
"70.00000","11.66148","2804.05688","16.0065"
"70.14000","11.68485","2803.96851","16.0395"
"70.28000","11.70809","2804.77856","16.0717"
"70.42000","11.73150","2805.00928","16.1035"
"70.56000","11.75477","2805.46997","16.1353"
"70.70000","11.77816","2805.82056","16.1670"
"70.84000","11.80147","2806.57324","16.1996"
"70.98000","11.82483","2806.60327","16.2309"
"71.12000","11.84817","2806.90186","16.2624"
"71.26000","11.87142","2806.95410","16.2935"
"71.40000","11.89482","2807.46313","16.3236"
"71.54000","11.91809","2807.96973","16.3534"
"71.68000","11.94152","2808.34326","16.3832"
"71.82000","11.96476","2808.71558","16.4122"
"71.96000","11.98816","2808.98999","16.4411"
"72.10000","12.01146","2809.44043","16.4709"
"72.24000","12.03481","2809.77515","16.4992"
"72.38000","12.05812","2810.08008","16.5267"
"72.52000","12.08148","2809.86401","16.5538"
"72.66000","12.10477","2810.91504","16.5797"
"72.80000","12.12814","2810.77710","16.6052"
"72.94000","12.15146","2811.63184","16.6292"
"73.08000","12.17486","2811.58911","16.6515"
"73.22000","12.19811","2812.08984","16.6457"
"73.36000","12.22150","2812.03735","16.6390"
"73.50000","12.24478","2812.37988","16.6362"
"73.64000","12.26819","2812.94727","16.6343"
"73.78000","12.29146","2812.63232","16.6354"
"73.92000","12.31484","2812.99756","16.6376"
"74.06000","12.33816","2813.19019","16.6378"
"74.20000","12.36146","2813.75464","16.6390"
"74.34000","12.38481","2814.11279","16.6406"
"74.48000","12.40809","2814.23267","16.6429"
"74.62000","12.43149","2814.56714","16.6444"
"74.76000","12.45475","2814.71606","16.6445"
"74.90000","12.47819","2815.18042","16.6445"
"75.04000","12.50146","2815.31689","16.6445"
"75.18000","12.52482","2815.50708","16.6450"
"75.32000","12.54813","2815.46997","16.6438"
"75.46000","12.57149","2815.38477","16.6420"
"75.60000","12.59481","2816.32275","16.6425"
"75.74000","12.61812","2815.97681","16.6418"
"75.88000","12.64144","2816.44458","16.6413"
"76.02000","12.66483","2816.83081","16.6429"
"76.16000","12.68814","2817.15674","16.6447"
"76.30000","12.71152","2817.43408","16.6462"
"76.44000","12.73479","2817.79761","16.6449"
"76.58000","12.75817","2817.73706","16.6460"
"76.72000","12.78141","2817.93872","16.6450"
"76.86000","12.80484","2817.85303","16.6447"
"77.00000","12.82813","2818.68945","16.6447"
"77.14000","12.85148","2818.65991","16.6457"
"77.28000","12.87481","2819.14624","16.6467"
"77.42000","12.89813","2819.38428","16.6463"
"77.56000","12.92149","2819.49390","16.6461"
"77.70000","12.94475","2819.66333","16.6472"
"77.84000","12.96818","2819.84766","16.6474"
"77.98000","12.99141","2819.68311","16.6491"
"78.12000","13.01481","2820.01001","16.6501"
"78.26000","13.03810","2820.51343","16.6510"
"78.40000","13.06151","2820.43677","16.6514"
"78.54000","13.08481","2820.87598","16.6522"
"78.68000","13.10814","2821.11035","16.6533"
"78.82000","13.13147","2821.41187","16.6533"
"78.96000","13.15481","2821.30640","16.6548"
"79.10000","13.17810","2821.99316","16.6567"
"79.24000","13.20148","2821.43994","16.6564"
"79.38000","13.22481","2822.23584","16.6560"
"79.52000","13.24819","2821.95630","16.6558"
"79.66000","13.27145","2822.76562","16.6579"
"79.80000","13.29484","2822.47144","16.6599"
"79.94000","13.31811","2822.95166","16.6618"
"80.08000","13.34149","2823.13745","16.6637"
"80.22000","13.36479","2822.90967","16.6269"
"80.36000","13.38814","2822.96265","16.6319"
"80.50000","13.41148","2823.52148","16.6338"
"80.64000","13.43477","2823.69360","16.6335"
"80.78000","13.45818","2823.72485","16.6335"
"80.92000","13.48143","2823.73755","16.6317"
"81.06000","13.50482","2823.62012","16.6317"
"81.20000","13.52808","2824.02319","16.6326"
"81.34000","13.55153","2824.38525","16.6337"
"81.48000","13.57476","2824.46997","16.6345"
"81.62000","13.59814","2824.55664","16.6355"
"81.76000","13.62147","2824.83911","16.6354"
"81.90000","13.64486","2824.95459","16.6361"
"82.04000","13.66809","2824.83765","16.6363"
"82.18000","13.69145","2825.07593","16.6367"
"82.32000","13.71478","2825.52515","16.6376"
"82.46000","13.73816","2825.71753","16.6382"
"82.60000","13.76147","2826.13916","16.6392"
"82.74000","13.78487","2825.90698","16.6380"
"82.88000","13.80812","2826.23218","16.6371"
"83.02000","13.83149","2826.39258","16.6373"
"83.16000","13.85478","2826.40430","16.6382"
"83.30000","13.87817","2826.29077","16.6393"
"83.44000","13.90146","2826.79883","16.6404"
"83.58000","13.92478","2826.98730","16.6404"
"83.72000","13.94813","2827.00659","16.6405"
"83.86000","13.97145","2827.06982","16.6423"
"84.00000","13.99484","2827.14307","16.6452"
"84.14000","14.01813","2827.33618","16.6459"
"84.28000","14.04151","2827.55005","16.6418"
"84.42000","14.06475","2827.43530","16.6360"
"84.56000","14.08815","2827.29370","16.6364"
"84.70000","14.11143","2827.44312","16.6377"
"84.84000","14.13484","2827.99683","16.6390"
"84.98000","14.15813","2828.18164","16.6413"
"85.12000","14.18149","2827.94507","16.6424"
"85.26000","14.20479","2828.40088","16.6416"
"85.40000","14.22816","2828.50610","16.6441"
"85.54000","14.25145","2828.33545","16.6458"
"85.68000","14.27482","2828.43628","16.6465"
"85.82000","14.29816","2828.71436","16.6468"
"85.96000","14.32148","2828.87305","16.6474"
"86.10000","14.34479","2829.10474","16.6483"
"86.24000","14.36817","2829.10254","16.6483"
"86.38000","14.39146","2828.94580","16.6472"
"86.52000","14.41480","2829.40894","16.6481"
"86.66000","14.43813","2829.36426","16.6499"
"86.80000","14.46146","2829.39404","16.6499"
"86.94000","14.48479","2829.35156","16.6491"
"87.08000","14.50812","2829.52344","16.6487"
"87.22000","14.53152","2829.34277","16.6480"
"87.36000","14.55477","2829.64941","16.6449"
"87.50000","14.57814","2829.61255","16.6433"
"87.64000","14.60142","2829.82520","16.6442"
"87.78000","14.62487","2829.56787","16.6444"
"87.92000","14.64810","2829.84961","16.6428"
"88.06000","14.67151","2829.80420","16.6440"
"88.20000","14.69483","2830.21826","16.6451"
"88.34000","14.71816","2830.13916","16.6453"
"88.48000","14.74147","2830.24268","16.6455"
"88.62000","14.76480","2829.94556","16.6459"
"88.76000","14.78813","2830.19897","16.6456"
"88.90000","14.81145","2830.06567","16.6457"
"89.04000","14.83484","2830.52563","16.6450"
"89.18000","14.85816","2830.88208","16.6434"
"89.32000","14.88149","2830.59131","16.6434"
"89.46000","14.90481","2830.30688","16.6450"
"89.60000","14.92815","2830.38672","16.6450"
"89.74000","14.95149","2830.59204","16.6439"
"89.88000","14.97476","2830.77002","16.6431"
"90.02000","14.99810","2830.95386","16.6444"
"90.16000","15.02148","2830.94824","16.6445"
"90.30000","15.04481","2830.96655","16.6456"
"90.44000","15.06818","2831.04980","16.6474"
"90.58000","15.09146","2831.09546","16.6475"
"90.72000","15.11483","2830.57227","16.6474"
"90.86000","15.13806","2830.64160","16.6475"
"91.00000","15.16151","2830.65747","16.6439"
"91.14000","15.18476","2830.72705","16.6413"
"91.28000","15.20817","2830.86011","16.6430"
"91.42000","15.23143","2831.14282","16.6438"
"91.56000","15.25484","2830.95825","16.6440"
"91.70000","15.27815","2831.28882","16.6426"
"91.84000","15.30146","2830.85034","16.6417"
"91.98000","15.32479","2830.70996","16.6418"
"92.12000","15.34813","2830.76294","16.6428"
"92.26000","15.37148","2831.07227","16.6414"
"92.40000","15.39480","2831.14331","16.6418"
"92.54000","15.41814","2831.44287","16.6423"
"92.68000","15.44150","2831.18481","16.6421"
"92.82000","15.46478","2831.13281","16.6404"
"92.96000","15.48816","2831.23608","16.6421"
"93.10000","15.51144","2831.06274","16.6438"
"93.24000","15.53480","2831.20215","16.6433"
"93.38000","15.55813","2830.80078","16.6437"
"93.52000","15.58149","2831.24121","16.6439"
"93.66000","15.60484","2830.68262","16.6443"
"93.80000","15.62811","2831.20728","16.6440"
"93.94000","15.65150","2831.21753","16.6440"
"94.08000","15.67478","2831.29443","16.6447"
"94.22000","15.69818","2831.10767","16.6455"
"94.36000","15.72143","2831.09937","16.6445"
"94.50000","15.74484","2830.88599","16.6449"
"94.64000","15.76815","2831.42188","16.6454"
"94.78000","15.79147","2831.19971","16.6434"
"94.92000","15.81479","2830.80640","16.6379"
"95.06000","15.83813","2831.02759","16.6393"
"95.20000","15.86148","2831.30273","16.6412"
"95.34000","15.88478","2831.04785","16.6413"
"95.48000","15.90816","2831.23560","16.6423"
"95.62000","15.93148","2830.96313","16.6437"
"95.76000","15.95478","2831.10620","16.6428"
"95.90000","15.97817","2831.08838","16.6432"
"96.04000","16.00149","2830.82080","16.6426"
"96.18000","16.02481","2830.90381","16.6426"
"96.32000","16.04811","2830.51050","16.6417"
"96.46000","16.07146","2830.64209","16.6409"
"96.60000","16.09480","2830.51758","16.6400"
"96.74000","16.11810","2831.05396","16.6397"
"96.88000","16.14151","2830.51489","16.6408"
"97.02000","16.16477","2830.75757","16.6411"
"97.16000","16.18816","2830.15210","16.6383"
"97.30000","16.21142","2830.04199","16.6373"
"97.44000","16.23485","2830.28149","16.6383"
"97.58000","16.25811","2830.45801","16.6405"
"97.72000","16.28147","2830.25977","16.6434"
"97.86000","16.30481","2830.31055","16.6469"
"98.00000","16.32817","2829.81958","16.6466"
"98.14000","16.35151","2830.03564","16.6456"
"98.28000","16.37481","2829.88818","16.6465"
"98.42000","16.39816","2830.04150","16.6490"
"98.56000","16.42146","2829.67700","16.6517"
"98.70000","16.44479","2829.92896","16.6532"
"98.84000","16.46814","2829.87720","16.6541"
"98.98000","16.49147","2829.62158","16.6545"
"99.12000","16.51481","2829.75610","16.6520"
"99.26000","16.53815","2829.61938","16.6506"
"99.40000","16.56146","2829.62817","16.6514"
"99.54000","16.58477","2829.14185","16.6502"
"99.68000","16.60811","2829.00757","16.6483"
"99.82000","16.63146","2828.95386","16.6488"
"99.96000","16.65482","2829.31055","16.6492"
"100.10000","16.67815","2828.96606","16.6471"
"100.24000","16.70144","2828.88013","16.6453"
"100.38000","16.72485","2828.68750","16.6444"
"100.52000","16.74811","2828.80737","16.6450"
"100.66000","16.77151","2828.37939","16.6439"
"100.80000","16.79476","2828.57715","16.6437"
"100.94000","16.81816","2828.36865","16.6421"
"101.08000","16.84143","2828.13257","16.6368"
"101.22000","16.86484","2827.91968","16.6376"
"101.36000","16.88816","2828.46802","16.6393"
"101.50000","16.91149","2827.90137","16.6388"
"101.64000","16.93480","2828.14917","16.6398"
"101.78000","16.95812","2827.52637","16.6393"
"101.92000","16.98147","2827.79980","16.6416"
"102.06000","17.00479","2827.42725","16.6415"
"102.20000","17.02814","2827.42505","16.6412"
"102.34000","17.05148","2827.37622","16.6416"
"102.48000","17.07480","2827.11450","16.6405"
"102.62000","17.09812","2827.10156","16.6406"
"102.76000","17.12144","2826.86279","16.6422"
"102.90000","17.14479","2827.38037","16.6428"
"103.04000","17.16814","2826.77881","16.6446"
"103.18000","17.19146","2826.90649","16.6445"
"103.32000","17.21485","2826.25366","16.6460"
"103.46000","17.23815","2826.49658","16.6467"
"103.60000","17.26150","2825.93652","16.6458"
"103.74000","17.28480","2825.86255","16.6413"
"103.88000","17.30820","2825.84009","16.6413"
"104.02000","17.33142","2826.06323","16.6425"
"104.16000","17.35482","2825.89331","16.6437"
"104.30000","17.37813","2825.83813","16.6452"
"104.44000","17.40149","2825.77295","16.6468"
"104.58000","17.42481","2825.16528","16.6442"
"104.72000","17.44818","2825.13086","16.6432"
"104.86000","17.47148","2825.09302","16.6419"
"105.00000","17.49475","2824.60986","16.6424"
"105.14000","17.51814","2824.71704","16.6426"
"105.28000","17.54147","2824.49341","16.6423"
"105.42000","17.56483","2824.49341","16.6427"
"105.56000","17.58811","2824.78174","16.6422"
"105.70000","17.61149","2824.44214","16.6426"
"105.84000","17.63481","2824.29565","16.6419"
"105.98000","17.65813","2823.71777","16.6402"
"106.12000","17.68146","2823.65845","16.6392"
"106.26000","17.70481","2822.88965","16.6375"
"106.40000","17.72813","2823.46362","16.6361"
"106.54000","17.75148","2823.14771","16.6339"
"106.68000","17.77478","2823.16406","16.6343"
"106.82000","17.79820","2822.87085","16.6359"
"106.96000","17.82144","2822.87549","16.6373"
"107.10000","17.84486","2822.40332","16.6386"
"107.24000","17.86810","2822.79395","16.6380"
"107.38000","17.89151","2822.34619","16.6390"
"107.52000","17.91477","2822.04517","16.6401"
"107.66000","17.93819","2822.03564","16.6402"
"107.80000","17.96148","2822.02393","16.6391"
"107.94000","17.98477","2821.82568","16.6383"
"108.08000","18.00816","2821.69556","16.6361"
"108.22000","18.03144","2821.56201","16.6344"
"108.36000","18.05482","2821.22949","16.6342"
"108.50000","18.07809","2820.93335","16.6347"
"108.64000","18.10150","2820.52026","16.6341"
"108.78000","18.12480","2820.70850","16.6344"
"108.92000","18.14814","2820.35205","16.6351"
"109.06000","18.17144","2820.08081","16.6368"
"109.20000","18.19480","2820.01953","16.6387"
"109.34000","18.21812","2819.88281","16.6394"
"109.48000","18.24145","2819.31177","16.6382"
"109.62000","18.26482","2819.71313","16.6379"
"109.76000","18.28818","2818.92700","16.6388"
"109.90000","18.31142","2819.12524","16.6393"
"110.04000","18.33487","2818.70410","16.6384"
"110.18000","18.35814","2819.02979","16.6384"
"110.32000","18.38153","2818.32300","16.6368"
"110.46000","18.40473","2818.11279","16.6381"
"110.60000","18.42815","2818.14917","16.6388"
"110.74000","18.45146","2817.93799","16.6391"
"110.88000","18.47482","2817.91772","16.6396"
"111.02000","18.49819","2817.70850","16.6416"
"111.16000","18.52149","2817.30566","16.6434"
"111.30000","18.54483","2817.11157","16.6437"
"111.44000","18.56809","2816.68188","16.6429"
"111.58000","18.59151","2816.75732","16.6429"
"111.72000","18.61477","2816.45435","16.6432"
"111.86000","18.63813","2816.56689","16.6438"
"112.00000","18.66146","2816.57080","16.6460"
"112.14000","18.68482","2815.96680","16.6469"
"112.28000","18.70814","2815.76709","16.6477"
"112.42000","18.73146","2815.32642","16.6483"
"112.56000","18.75480","2815.43604","16.6488"
"112.70000","18.77814","2814.93579","16.6500"
"112.84000","18.80143","2815.15381","16.6486"
"112.98000","18.82482","2814.34473","16.6494"
"113.12000","18.84815","2814.65381","16.6490"
"113.26000","18.87152","2814.01660","16.6503"
"113.40000","18.89479","2814.06299","16.6493"
"113.54000","18.91818","2813.75024","16.6495"
"113.68000","18.94143","2813.37939","16.6481"
"113.82000","18.96480","2813.02441","16.6466"
"113.96000","18.98814","2812.77661","16.6468"
"114.10000","19.01152","2812.83618","16.6474"
"114.24000","19.03480","2812.91016","16.6479"
"114.38000","19.05811","2812.21802","16.6465"
"114.52000","19.08150","2812.06958","16.6434"
"114.66000","19.10477","2811.47412","16.6439"
"114.80000","19.12815","2811.32544","16.6451"
"114.94000","19.15145","2810.98071","16.6441"
"115.08000","19.17481","2810.65894","16.6444"
"115.22000","19.19811","2810.72681","16.6455"
"115.36000","19.22149","2810.19800","16.6443"
"115.50000","19.24480","2809.79248","16.6424"
"115.64000","19.26815","2809.56152","16.6430"
"115.78000","19.29145","2809.89160","16.6446"
"115.92000","19.31480","2808.85547","16.6450"
"116.06000","19.33814","2808.80542","16.6440"
"116.20000","19.36148","2808.08057","16.6432"
"116.34000","19.38478","2808.23389","16.6432"
"116.48000","19.40820","2807.64844","16.6438"
"116.62000","19.43149","2807.43555","16.6437"
"116.76000","19.45480","2807.15967","16.6436"
"116.90000","19.47812","2806.76514","16.6426"
"117.04000","19.50150","2806.56250","16.6420"
"117.18000","19.52479","2806.16357","16.6419"
"117.32000","19.54815","2806.11011","16.6436"
"117.46000","19.57150","2805.73877","16.6455"
"117.60000","19.59481","2805.64258","16.6466"
"117.74000","19.61815","2805.08984","16.6487"
"117.88000","19.64145","2804.88477","16.6481"
"118.02000","19.66483","2804.35767","16.6494"
"118.16000","19.68808","2804.14893","16.6499"
"118.30000","19.71146","2803.63086","16.6511"
"118.44000","19.73479","2803.67163","16.6519"
"118.58000","19.75818","2803.26782","16.6515"
"118.72000","19.78147","2803.15234","16.6492"
"118.86000","19.80486","2802.20972","16.6482"
"119.00000","19.82813","2802.33081","16.6476"
"119.14000","19.85144","2801.26514","16.6485"
"119.28000","19.87479","2801.39087","16.6481"
"119.42000","19.89817","2800.75977","16.6480"
"119.56000","19.92149","2800.89355","16.6491"
"119.70000","19.94483","2800.23267","16.6464"
"119.84000","19.96815","2800.36621","16.6474"
"119.98000","19.99152","2799.50024","16.6469"
"120.12000","20.01476","2798.88184","16.6479"
"120.26000","20.03815","2798.47803","16.6486"
"120.40000","20.06145","2798.08521","16.6491"
"120.54000","20.08484","2797.97021","16.6471"
"120.68000","20.10815","2797.55737","16.6457"
"120.82000","20.13148","2797.19043","16.6439"
"120.96000","20.15483","2796.56006","16.6401"
"121.10000","20.17811","2796.20557","16.6393"
"121.24000","20.20150","2795.33447","16.6412"
"121.38000","20.22475","2795.23169","16.6424"
"121.52000","20.24816","2795.21362","16.6434"
"121.66000","20.27141","2794.48413","16.6449"
"121.80000","20.29486","2793.85156","16.6439"
"121.94000","20.31814","2793.66748","16.6429"
"122.08000","20.34147","2793.04785","16.6437"
"122.22000","20.36477","2792.88379","16.6431"
"122.36000","20.38815","2791.80444","16.6442"
"122.50000","20.41147","2791.84033","16.6437"
"122.64000","20.43480","2791.24048","16.6427"
"122.78000","20.45815","2790.85889","16.6432"
"122.92000","20.48151","2790.35181","16.6456"
"123.06000","20.50478","2790.29004","16.6477"
"123.20000","20.52814","2789.34937","16.6490"
"123.34000","20.55144","2789.17017","16.6470"
"123.48000","20.57482","2788.51416","16.6470"
"123.62000","20.59810","2788.29126","16.6476"
"123.76000","20.62148","2787.58228","16.6469"
"123.90000","20.64482","2787.10693","16.6459"
"124.04000","20.66811","2786.62964","16.6441"
"124.18000","20.69152","2786.28979","16.6441"
"124.32000","20.71478","2785.32886","16.6417"
"124.46000","20.73820","2785.12354","16.6375"
"124.60000","20.76138","2784.44653","16.6382"
"124.74000","20.78482","2783.82446","16.6387"
"124.88000","20.80811","2783.73608","16.6398"
"125.02000","20.83149","2782.84424","16.6398"
"125.16000","20.85482","2782.44727","16.6388"
"125.30000","20.87819","2781.67310","16.6397"
"125.44000","20.90147","2781.21143","16.6404"
"125.58000","20.92476","2780.57910","16.6411"
"125.72000","20.94815","2779.94629","16.6408"
"125.86000","20.97148","2779.36694","16.6408"
"126.00000","20.99478","2779.13501","16.6405"
"126.14000","21.01816","2778.22681","16.6407"
"126.28000","21.04150","2778.09717","16.6422"
"126.42000","21.06485","2777.42578","16.6437"
"126.56000","21.08811","2776.30029","16.6445"
"126.70000","21.11149","2775.96216","16.6449"
"126.84000","21.13478","2774.96533","16.6442"
"126.98000","21.15810","2774.75073","16.6444"
"127.12000","21.18148","2773.83374","16.6459"
"127.26000","21.20479","2773.60645","16.6467"
"127.40000","21.22820","2772.42090","16.6478"
"127.54000","21.25142","2771.88940","16.6466"
"127.68000","21.27483","2771.00317","16.6448"
"127.82000","21.29807","2770.18970","16.6449"
"127.96000","21.32150","2769.22925","16.6448"
"128.10000","21.34478","2768.83618","16.6438"
"128.24000","21.36822","2767.67212","16.6435"
"128.38000","21.39147","2767.35034","16.6444"
"128.52000","21.41481","2766.31445","16.6447"
"128.66000","21.43813","2765.72339","16.6446"
"128.80000","21.46148","2764.96655","16.6437"
"128.94000","21.48479","2764.14575","16.6439"
"129.08000","21.50814","2762.56396","16.6433"
"129.22000","21.53149","2762.38062","16.6428"
"129.36000","21.55482","2761.00439","16.6433"
"129.50000","21.57812","2760.60596","16.6431"
"129.64000","21.60149","2759.06250","16.6424"
"129.78000","21.62480","2758.41357","16.6425"
"129.92000","21.64813","2757.56519","16.6434"
"130.06000","21.67145","2756.27246","16.6444"
"130.20000","21.69483","2755.44775","16.6449"
"130.34000","21.71814","2754.40405","16.6450"
"130.48000","21.74145","2753.37891","16.6444"
"130.62000","21.76487","2751.66211","16.6441"
"130.76000","21.78813","2750.87964","16.6439"
"130.90000","21.81148","2749.27466","16.6433"
"131.04000","21.83473","2748.10107","16.6425"
"131.18000","21.85817","2746.84595","16.6422"
"131.32000","21.88144","2745.63794","16.6420"
"131.46000","21.90484","2743.97607","16.6420"
"131.60000","21.92817","2742.88013","16.6418"
"131.74000","21.95149","2741.19458","16.6414"
"131.88000","21.97478","2739.72534","16.6410"
"132.02000","21.99815","2737.72681","16.6407"
"132.16000","22.02149","2736.52515","16.6406"
"132.30000","22.04482","2734.44165","16.6408"
"132.44000","22.06812","2733.46558","16.6410"
"132.58000","22.09148","2731.48853","16.6413"
"132.72000","22.11484","2729.80054","16.6415"
"132.86000","22.13814","2727.76343","16.6415"
"133.00000","22.16148","2725.74927","16.6417"
"133.14000","22.18480","2723.91309","16.6418"
"133.28000","22.20811","2721.47827","16.6416"
"133.42000","22.23143","2719.59033","16.6415"
"133.56000","22.25481","2717.46997","16.6413"
"133.70000","22.27811","2715.23901","16.6411"
"133.84000","22.30149","2713.19141","16.6409"
"133.98000","22.32479","2710.80542","16.6408"
"134.12000","22.34818","2708.08936","16.6407"
"134.26000","22.37141","2705.61182","16.6406"
"134.40000","22.39482","2702.71704","16.6406"
"134.54000","22.41812","2700.21484","16.6405"
"134.68000","22.44151","2697.25562","16.6404"
"134.82000","22.46478","2694.67480","16.6402"
"134.96000","22.48817","2691.14819","16.6401"
"135.10000","22.51148","2688.38330","16.6399"
"135.24000","22.53482","2685.53687","16.6397"
"135.38000","22.55813","2682.24609","16.6396"
"135.52000","22.58146","2678.18823","16.6393"
"135.66000","22.60480","2675.03491","16.6391"
"135.80000","22.62811","2671.48364","16.6389"
"135.94000","22.65151","2667.91333","16.6387"
"136.08000","22.67482","2663.45728","16.6384"
"136.22000","22.69814","2659.52563","16.6382"
"136.36000","22.72146","2655.41138","16.6379"
"136.50000","22.74481","2650.35010","16.6378"
"136.64000","22.76814","2645.81372","16.6375"
"136.78000","22.79147","2640.42334","16.6372"
"136.92000","22.81479","2635.16870","16.6370"
"137.06000","22.83818","2629.27124","16.6366"
"137.20000","22.86146","2623.54370","16.6363"
"137.34000","22.88482","2616.50488","16.6360"
"137.48000","22.90809","2609.69019","16.6357"
"137.62000","22.93150","2601.65039","16.6353"
"137.76000","22.95474","2592.73413","16.6350"
"137.90000","22.97819","2582.23193","16.6344"
"138.04000","23.00148","2571.43164","16.6339"
"138.18000","23.02481","2557.44946","16.6333"
"138.32000","23.04815","2541.55444","16.6325"
"138.46000","23.07149","2522.62622","16.6315"
"138.60000","23.09484","2500.58423","16.6302"
"138.74000","23.11808","2470.41406","16.6288"
"138.88000","23.14150","2434.79980","16.6271"
"139.02000","23.16478","2395.41211","16.6250"
"139.16000","23.18816","2351.65405","16.6228"
"139.30000","23.21149","2298.73999","16.6203"
"139.44000","23.23483","2243.69873","16.6177"
"139.58000","23.25815","2178.66748","16.6148"
"139.72000","23.28143","2106.08105","16.6121"
"139.86000","23.30483","2021.17139","16.6207"
"140.00000","23.32816","1919.05103","16.6193"
"140.14000","23.35147","1779.22412","16.6126"
"140.26600","23.37259","1367.53772","16.5734"
"140.27400","23.37403","991.07001","16.5297"